Workbook
Name aaa: #REF!
Name aaa: #REF!
Name aaaaaaa: #REF!
Name aaaaaaa: #REF!
Name ad: #REF!
Name ad: #REF!
Name adb: #REF!
Name adb: #REF!
Name adsf: #REF!
Name adsf: #REF!
Name ae: #REF!
Name ae: #REF!
Name aef: #REF!
Name aef: #REF!
Name afdasfas: #REF!
Name afdasfas: #REF!
Name AH: #REF!
Name AH: #REF!
Name asfd: #REF!
Name asfd: #REF!
Name ASI_REDE: '[1]Calc Eng'!$H$26
Name Atendentes_Instr_Campo_QT: '[1]Calc Eng'!$B$52
Name Atendentes_Senior_QT: '[1]Calc Eng'!$B$50
Name Atendentes_Sistema_Processo_QT: '[1]Calc Eng'!$B$51
Name Atendentes_Total: '[1]Calc Eng'!$B$27
Name BR: #REF!
Name BR: #REF!
Name BRN: #REF!
Name BRN: #REF!
Name C_ADM_Geral: 0.1
Name CFTV_TI_meta: '[1]Pareto Metas'!$R$85
Name CFTV_TI_real: [1]Metas!$U$127
Name CFTV_Total: [1]Retorno!$B$6
Name Cidade: '[1]Calc Eng'!$H$78
Name CNPJ: '[1]Calc Eng'!$K$77
Name Conteiner_Aluguel_Mes: '[1]Calc Eng'!$B$43
Name CSLL: [1]Impostos!$H$28
Name CTNER: '[1]Calc Eng'!$H$20
Name Custo_Impostos_Credito__Débito: [1]Retorno!$J$23
Name data_abertura_OS: '[1]O.S.'!$M$5
Name descrição_da_venda: '[1]O.S.'!$E$16
Name Diária_Casa_Atendente: '[2]Calc Eng'!$B$2
Name Diária_Casa_Custo_Atendente: '[1]Calc Eng'!$B$2
Name Diária_Completa_Sem_Transporte: '[1]Calc Eng'!$B$41
Name Diária_Hotel_Avulsos: '[2]Calc Eng'!$B$4
Name Diária_Hotel_Negociado: '[2]Calc Eng'!$B$5
Name Diárias_Hotel_Avulsas_Custo: '[1]Calc Eng'!$B$4
Name Diárias_Hotel_Negociada_Custo: '[1]Calc Eng'!$B$5
Name Dias_Campo: '[1]Calc Eng'!$B$32
Name Distância_Base_PLANTA: '[1]Calc Eng'!$B$37
Name Distância_STZ_BASE: '[1]Calc Eng'!$B$36
Name Domingo_H: '[1]Calc Eng'!$B$60
Name Duração_Comissionamento__Startup: '[1]Calc Eng'!$B$42
Name Duração_Obra_Mês: '[1]Calc Eng'!$B$31
Name EA_E_PA: '[1]Calc Eng'!$H$23
Name ED_SD: '[1]Calc Eng'!$H$25
Name Embalagem: '[1]Calc Eng'!$B$18
Name Embalagem_meta: '[1]Pareto Metas'!$R$80
Name Equipe_Numero: '[1]Calc Eng'!$B$33
Name Estado: '[1]Calc Eng'!$J$78

Sheet Lista de Cargas
A1: Área | B1: Painel | C1: TAG | D1: Descrição | E1: Ex | F1: Status | G1: Partida | H1: Partida Pesada | I1: Resitência Aquecimento | J1: Resistor Frenagem | K1: Ventilação Forçada | L1: Termistor | M1: RTD | N1: Observação | O1: Acionamento | P1: Potência (cv) | Q1: Potência (KW) | R1: Nº Pólos | S1: FP | T1: Rend. | U1: Tipo Circuito | V1: Tensão (V) | W1: Corrente (A) | X1: Potência (KVA) | Y1: Corrente Partida (A) | Z1: Cabo / Barramento | AA1: Borne | AB1: Parcial 1 (m) | AC1: Parcial 2 (m) | AD1: Parcial 3 (m) | AE1: Parcial 4 (m) | AF1: Parcial 5 (m) | AG1: Distância Total (m) | AH1: Nº Cabos Fase | AI1: Cabo Fases | AJ1: Total Cabos Fase (m) | AK1: Nº Cabos Neutro (N) | AL1: Cabo Neutro (N) | AM1: Total Cabos Neutro (m) | AN1: Nº Cabos Terra PE/PEN | AO1: Cabos Terra (PE/PEN) | AP1: Total Cabos Terra (m) | AQ1: Carcaça Motor | AR1: Caixa de ligação Motor | AS1: QTDE | AT1: Fusível | AU1: Tamanho Fusível | AV1: Inversor | AW1: Frame Inversor / Soft | AX1: Frenagem | AY1: Softstarter | AZ1: Acessórios Inversor/Soft | BA1: Disjuntor Motor | BB1: Contator | BC1: Relé Inteligente | BD1: Acessórios para Relé Inteligente | BE1: Disjuntor | BF1: Potência Reativa Necessária | BG1: Fator de Potência Desejado | BH1: 0.92 | BI1: Margem Cabos | BJ1: 0
A2: SE-02 | B2: QGBT-1 | C2: CUB02 | D2: Alimentação Geral | O2: Disjuntor C.A. | P2: 9249.3298 | Q2: =P2*0.746 -> 6900 | S2: =IF(O2="","",IF(O2="NA","",IF(O2="Mini disjuntor + DR",0.92,IF(O2="Mini disjuntor",0.92,IF(O2="Disjuntor Motor",0.92,IF(O2="Disjuntor C.M.",0.92,IF(O2="Disjuntor C.A.",0.92,IFERROR(VLOOKUP('Lista de Cargas'!P2,Motores!$B$9:$T$48,19,FALSE),"Erro")))))))) -> 0.92 | T2: =IF(O2="","",IF(O2="NA","",IF(O2="Mini disjuntor + DR",100%,IF(O2="Mini disjuntor",100%,IF(O2="Disjuntor Motor",0.92,IF(O2="Disjuntor C.M.",100%,IF(O2="Disjuntor C.A.",100%,IFERROR(VLOOKUP('Lista de Cargas'!P2,Motores!$B$9:$T$48,16,FALSE)/100,"Erro")))))))) -> 1 | U2: Trifásico | V2: 13800 | W2: =IFERROR(IF(U2=$U$344,(P2*746)/(SQRT(3)*S2*T2*V2),(P2*746)/(S2*T2*V2)),0) -> 313.77732 | X2: =IFERROR(Q2/S2,0) -> 7500 | Y2: =IFERROR(IF(O2=$O$344,6*W2,IF(O2=$O$345,6*W2,IF(O2=$O$346,3*W2,IF(O2=$O$347,1.5*W2,W2)))),0) -> 313.77732 | AB2: 600 | AG2: =SUM(AB2:AF2) -> 600 | AH2: 6 | AI2: 70 mm² - 15/25KV - EPR 105°C | AJ2: =$AG2*AH2*(1+$BJ$1) -> 3600 | AK2: 0 | AL2: NA | AN2: 4 | AO2: 240mm² - 0,6/1kV - VD - EPR - 90ºC - Cobre | AP2: =$AG2*AN2*(1+$BJ$1) -> 2400 | AQ2: NA | AS2: 1
A3: SE-02 | B3: QGBT-1 | C3: TRF1 | D3: Aliemntação Transformador 1 | O3: Disjuntor C.A. | P3: 3083.1099 | Q3: =P3*0.746 -> 2300 | S3: =IF(O3="","",IF(O3="NA","",IF(O3="Mini disjuntor + DR",0.92,IF(O3="Mini disjuntor",0.92,IF(O3="Disjuntor Motor",0.92,IF(O3="Disjuntor C.M.",0.92,IF(O3="Disjuntor C.A.",0.92,IFERROR(VLOOKUP('Lista de Cargas'!P3,Motores!$B$9:$T$48,19,FALSE),"Erro")))))))) -> 0.92 | T3: =IF(O3="","",IF(O3="NA","",IF(O3="Mini disjuntor + DR",100%,IF(O3="Mini disjuntor",100%,IF(O3="Disjuntor Motor",0.92,IF(O3="Disjuntor C.M.",100%,IF(O3="Disjuntor C.A.",100%,IFERROR(VLOOKUP('Lista de Cargas'!P3,Motores!$B$9:$T$48,16,FALSE)/100,"Erro")))))))) -> 1 | U3: Trifásico | V3: 13800 | W3: =IFERROR(IF(U3=$U$344,(P3*746)/(SQRT(3)*S3*T3*V3),(P3*746)/(S3*T3*V3)),0) -> 104.59244 | X3: =IFERROR(Q3/S3,0) -> 2500 | Y3: =IFERROR(IF(O3=$O$344,6*W3,IF(O3=$O$345,6*W3,IF(O3=$O$346,3*W3,IF(O3=$O$347,1.5*W3,W3)))),0) -> 104.59244 | AB3: 20 | AG3: =SUM(AB3:AF3) -> 20 | AH3: 3 | AI3: 70 mm² - 15/25KV - EPR 105°C | AJ3: =$AG3*AH3*(1+$BJ$1) -> 60 | AP3: =$AG3*AN3*(1+$BJ$1) -> 0 | AQ3: NA | AS3: 1
A4: SE-02 | B4: QGBT-1 | C4: TRF2 | D4: Aliemntação Transformador 2 | O4: Disjuntor C.A. | P4: 3083.1099 | Q4: =P4*0.746 -> 2300 | S4: =IF(O4="","",IF(O4="NA","",IF(O4="Mini disjuntor + DR",0.92,IF(O4="Mini disjuntor",0.92,IF(O4="Disjuntor Motor",0.92,IF(O4="Disjuntor C.M.",0.92,IF(O4="Disjuntor C.A.",0.92,IFERROR(VLOOKUP('Lista de Cargas'!P4,Motores!$B$9:$T$48,19,FALSE),"Erro")))))))) -> 0.92 | T4: =IF(O4="","",IF(O4="NA","",IF(O4="Mini disjuntor + DR",100%,IF(O4="Mini disjuntor",100%,IF(O4="Disjuntor Motor",0.92,IF(O4="Disjuntor C.M.",100%,IF(O4="Disjuntor C.A.",100%,IFERROR(VLOOKUP('Lista de Cargas'!P4,Motores!$B$9:$T$48,16,FALSE)/100,"Erro")))))))) -> 1 | U4: Trifásico | V4: 13800 | W4: =IFERROR(IF(U4=$U$344,(P4*746)/(SQRT(3)*S4*T4*V4),(P4*746)/(S4*T4*V4)),0) -> 104.59244 | X4: =IFERROR(Q4/S4,0) -> 2500 | Y4: =IFERROR(IF(O4=$O$344,6*W4,IF(O4=$O$345,6*W4,IF(O4=$O$346,3*W4,IF(O4=$O$347,1.5*W4,W4)))),0) -> 104.59244 | AB4: 20 | AG4: =SUM(AB4:AF4) -> 20 | AH4: 3 | AI4: 70 mm² - 15/25KV - EPR 105°C | AJ4: =$AG4*AH4*(1+$BJ$1) -> 60 | AK4: 0 | AL4: NA | AN4: 1 | AO4: 120mm² - 0,6/1kV - VD - EPR - 90ºC - Cobre | AP4: =$AG4*AN4*(1+$BJ$1) -> 20 | AQ4: NA | AS4: 1
A5: SE-02 | B5: QGBT-1 | C5: TRF3 | D5: Aliemntação Transformador 3 | O5: Disjuntor C.A. | P5: 3083.1099 | Q5: =P5*0.746 -> 2300 | S5: =IF(O5="","",IF(O5="NA","",IF(O5="Mini disjuntor + DR",0.92,IF(O5="Mini disjuntor",0.92,IF(O5="Disjuntor Motor",0.92,IF(O5="Disjuntor C.M.",0.92,IF(O5="Disjuntor C.A.",0.92,IFERROR(VLOOKUP('Lista de Cargas'!P5,Motores!$B$9:$T$48,19,FALSE),"Erro")))))))) -> 0.92 | T5: =IF(O5="","",IF(O5="NA","",IF(O5="Mini disjuntor + DR",100%,IF(O5="Mini disjuntor",100%,IF(O5="Disjuntor Motor",0.92,IF(O5="Disjuntor C.M.",100%,IF(O5="Disjuntor C.A.",100%,IFERROR(VLOOKUP('Lista de Cargas'!P5,Motores!$B$9:$T$48,16,FALSE)/100,"Erro")))))))) -> 1 | U5: Trifásico | V5: 13800 | W5: =IFERROR(IF(U5=$U$344,(P5*746)/(SQRT(3)*S5*T5*V5),(P5*746)/(S5*T5*V5)),0) -> 104.59244 | X5: =IFERROR(Q5/S5,0) -> 2500 | Y5: =IFERROR(IF(O5=$O$344,6*W5,IF(O5=$O$345,6*W5,IF(O5=$O$346,3*W5,IF(O5=$O$347,1.5*W5,W5)))),0) -> 104.59244 | AB5: 20 | AG5: =SUM(AB5:AF5) -> 20 | AH5: 3 | AI5: 70 mm² - 15/25KV - EPR 105°C | AJ5: =$AG5*AH5*(1+$BJ$1) -> 60 | AK5: 0 | AL5: NA | AN5: 1 | AO5: 120mm² - 0,6/1kV - VD - EPR - 90ºC - Cobre | AP5: =$AG5*AN5*(1+$BJ$1) -> 20 | AQ5: NA | AS5: 1
A6: SE-03 | B6: QGBT-1 | C6: CUB02 | D6: Alimentação Geral | O6: Disjuntor C.A. | P6: 6166.2198 | Q6: =P6*0.746 -> 4600 | S6: =IF(O6="","",IF(O6="NA","",IF(O6="Mini disjuntor + DR",0.92,IF(O6="Mini disjuntor",0.92,IF(O6="Disjuntor Motor",0.92,IF(O6="Disjuntor C.M.",0.92,IF(O6="Disjuntor C.A.",0.92,IFERROR(VLOOKUP('Lista de Cargas'!P6,Motores!$B$9:$T$48,19,FALSE),"Erro")))))))) -> 0.92 | T6: =IF(O6="","",IF(O6="NA","",IF(O6="Mini disjuntor + DR",100%,IF(O6="Mini disjuntor",100%,IF(O6="Disjuntor Motor",0.92,IF(O6="Disjuntor C.M.",100%,IF(O6="Disjuntor C.A.",100%,IFERROR(VLOOKUP('Lista de Cargas'!P6,Motores!$B$9:$T$48,16,FALSE)/100,"Erro")))))))) -> 1 | U6: Trifásico | V6: 13800 | W6: =IFERROR(IF(U6=$U$344,(P6*746)/(SQRT(3)*S6*T6*V6),(P6*746)/(S6*T6*V6)),0) -> 209.18488 | X6: =IFERROR(Q6/S6,0) -> 5000 | Y6: =IFERROR(IF(O6=$O$344,6*W6,IF(O6=$O$345,6*W6,IF(O6=$O$346,3*W6,IF(O6=$O$347,1.5*W6,W6)))),0) -> 209.18488 | AB6: 400 | AG6: =SUM(AB6:AF6) -> 400 | AH6: 3 | AI6: 70 mm² - 15/25KV - EPR 105°C | AJ6: =$AG6*AH6*(1+$BJ$1) -> 1200 | AK6: 0 | AL6: NA | AN6: 1 | AO6: 120mm² - 0,6/1kV - VD - EPR - 90ºC - Cobre | AP6: =$AG6*AN6*(1+$BJ$1) -> 400 | AQ6: NA | AS6: 1
A7: SE-03 | B7: QGBT-1 | C7: TRF1 | D7: Aliemntação Transformador 1 | O7: Disjuntor C.A. | P7: 3083.1099 | Q7: =P7*0.746 -> 2300 | S7: =IF(O7="","",IF(O7="NA","",IF(O7="Mini disjuntor + DR",0.92,IF(O7="Mini disjuntor",0.92,IF(O7="Disjuntor Motor",0.92,IF(O7="Disjuntor C.M.",0.92,IF(O7="Disjuntor C.A.",0.92,IFERROR(VLOOKUP('Lista de Cargas'!P7,Motores!$B$9:$T$48,19,FALSE),"Erro")))))))) -> 0.92 | T7: =IF(O7="","",IF(O7="NA","",IF(O7="Mini disjuntor + DR",100%,IF(O7="Mini disjuntor",100%,IF(O7="Disjuntor Motor",0.92,IF(O7="Disjuntor C.M.",100%,IF(O7="Disjuntor C.A.",100%,IFERROR(VLOOKUP('Lista de Cargas'!P7,Motores!$B$9:$T$48,16,FALSE)/100,"Erro")))))))) -> 1 | U7: Trifásico | V7: 13800 | W7: =IFERROR(IF(U7=$U$344,(P7*746)/(SQRT(3)*S7*T7*V7),(P7*746)/(S7*T7*V7)),0) -> 104.59244 | X7: =IFERROR(Q7/S7,0) -> 2500 | Y7: =IFERROR(IF(O7=$O$344,6*W7,IF(O7=$O$345,6*W7,IF(O7=$O$346,3*W7,IF(O7=$O$347,1.5*W7,W7)))),0) -> 104.59244 | AB7: 20 | AG7: =SUM(AB7:AF7) -> 20 | AH7: 3 | AI7: 70 mm² - 15/25KV - EPR 105°C | AJ7: =$AG7*AH7*(1+$BJ$1) -> 60 | AK7: 0 | AL7: NA | AN7: 1 | AO7: 240mm² - 0,6/1kV - VD - EPR - 90ºC - Cobre | AP7: =$AG7*AN7*(1+$BJ$1) -> 20 | AQ7: NA | AS7: 1
A8: SE-03 | B8: QGBT-1 | C8: TRF2 | D8: Aliemntação Transformador 2 | O8: Disjuntor C.A. | P8: 3083.1099 | Q8: =P8*0.746 -> 2300 | S8: =IF(O8="","",IF(O8="NA","",IF(O8="Mini disjuntor + DR",0.92,IF(O8="Mini disjuntor",0.92,IF(O8="Disjuntor Motor",0.92,IF(O8="Disjuntor C.M.",0.92,IF(O8="Disjuntor C.A.",0.92,IFERROR(VLOOKUP('Lista de Cargas'!P8,Motores!$B$9:$T$48,19,FALSE),"Erro")))))))) -> 0.92 | T8: =IF(O8="","",IF(O8="NA","",IF(O8="Mini disjuntor + DR",100%,IF(O8="Mini disjuntor",100%,IF(O8="Disjuntor Motor",0.92,IF(O8="Disjuntor C.M.",100%,IF(O8="Disjuntor C.A.",100%,IFERROR(VLOOKUP('Lista de Cargas'!P8,Motores!$B$9:$T$48,16,FALSE)/100,"Erro")))))))) -> 1 | U8: Trifásico | V8: 13800 | W8: =IFERROR(IF(U8=$U$344,(P8*746)/(SQRT(3)*S8*T8*V8),(P8*746)/(S8*T8*V8)),0) -> 104.59244 | X8: =IFERROR(Q8/S8,0) -> 2500 | Y8: =IFERROR(IF(O8=$O$344,6*W8,IF(O8=$O$345,6*W8,IF(O8=$O$346,3*W8,IF(O8=$O$347,1.5*W8,W8)))),0) -> 104.59244 | AB8: 20 | AG8: =SUM(AB8:AF8) -> 20 | AH8: 3 | AI8: 70 mm² - 15/25KV - EPR 105°C | AJ8: =$AG8*AH8*(1+$BJ$1) -> 60 | AK8: 0 | AL8: NA | AN8: 1 | AO8: 240mm² - 0,6/1kV - VD - EPR - 90ºC - Cobre | AP8: =$AG8*AN8*(1+$BJ$1) -> 20 | AQ8: NA | AS8: 1
A9: Geral | B9: QGBT-1 | C9: G Diesel | D9: Alimentação Gerador Diesel | O9: Disjuntor C.A. | P9: 3083.1099 | Q9: =P9*0.746 -> 2300 | S9: =IF(O9="","",IF(O9="NA","",IF(O9="Mini disjuntor + DR",0.92,IF(O9="Mini disjuntor",0.92,IF(O9="Disjuntor Motor",0.92,IF(O9="Disjuntor C.M.",0.92,IF(O9="Disjuntor C.A.",0.92,IFERROR(VLOOKUP('Lista de Cargas'!P9,Motores!$B$9:$T$48,19,FALSE),"Erro")))))))) -> 0.92 | T9: =IF(O9="","",IF(O9="NA","",IF(O9="Mini disjuntor + DR",100%,IF(O9="Mini disjuntor",100%,IF(O9="Disjuntor Motor",0.92,IF(O9="Disjuntor C.M.",100%,IF(O9="Disjuntor C.A.",100%,IFERROR(VLOOKUP('Lista de Cargas'!P9,Motores!$B$9:$T$48,16,FALSE)/100,"Erro")))))))) -> 1 | U9: Trifásico | V9: 13800 | W9: =IFERROR(IF(U9=$U$344,(P9*746)/(SQRT(3)*S9*T9*V9),(P9*746)/(S9*T9*V9)),0) -> 104.59244 | X9: =IFERROR(Q9/S9,0) -> 2500 | Y9: =IFERROR(IF(O9=$O$344,6*W9,IF(O9=$O$345,6*W9,IF(O9=$O$346,3*W9,IF(O9=$O$347,1.5*W9,W9)))),0) -> 104.59244 | AB9: 50 | AG9: =SUM(AB9:AF9) -> 50 | AH9: 3 | AI9: 70 mm² - 15/25KV - EPR 105°C | AJ9: =$AG9*AH9*(1+$BJ$1) -> 150 | AK9: 0 | AL9: NA | AN9: 1 | AO9: 120mm² - 0,6/1kV - VD - EPR - 90ºC - Cobre | AP9: =$AG9*AN9*(1+$BJ$1) -> 50 | AQ9: NA | AS9: 1
A10: SE-02 | B10: QGBT-1 | C10: Q0 | D10: DISJUNTOR DE ENTRADA | O10: Disjuntor C.A. | P10: 3007.546 | Q10: =P10*0.746 -> 2243.6293 | S10: =IF(O10="","",IF(O10="NA","",IF(O10="Mini disjuntor + DR",0.92,IF(O10="Mini disjuntor",0.92,IF(O10="Disjuntor Motor",0.92,IF(O10="Disjuntor C.M.",0.92,IF(O10="Disjuntor C.A.",0.92,IFERROR(VLOOKUP('Lista de Cargas'!P10,Motores!$B$9:$T$48,19,FALSE),"Erro")))))))) -> 0.92 | T10: =IF(O10="","",IF(O10="NA","",IF(O10="Mini disjuntor + DR",100%,IF(O10="Mini disjuntor",100%,IF(O10="Disjuntor Motor",0.92,IF(O10="Disjuntor C.M.",100%,IF(O10="Disjuntor C.A.",100%,IFERROR(VLOOKUP('Lista de Cargas'!P10,Motores!$B$9:$T$48,16,FALSE)/100,"Erro")))))))) -> 1 | U10: Trifásico | V10: 440 | W10: =IFERROR(IF(U10=$U$344,(P10*746)/(SQRT(3)*S10*T10*V10),(P10*746)/(S10*T10*V10)),0) -> 3200 | X10: =IFERROR(Q10/S10,0) -> 2438.7275 | Y10: =IFERROR(IF(O10=$O$344,6*W10,IF(O10=$O$345,6*W10,IF(O10=$O$346,3*W10,IF(O10=$O$347,1.5*W10,W10)))),0) -> 3200 | AB10: 20 | AG10: =SUM(AB10:AF10) -> 20 | AH10: 21 | AI10: 240mm² - 0,6/1kV - PT - EPR - 90ºC - Cobre | AJ10: =$AG10*AH10*(1+$BJ$1) -> 420 | AK10: 0 | AL10: NA | AN10: 4 | AO10: 240mm² - 0,6/1kV - VD - EPR - 90ºC - Cobre | AP10: =$AG10*AN10*(1+$BJ$1) -> 80 | AQ10: NA | AS10: 1
A11: SE-02 | B11: QGBT-1 | C11: MO1-100-01 | D11: MOINHO (FASE 2) | O11: Disjuntor C.M. | P11: 499.72257 | Q11: =P11*0.746 -> 372.79304 | S11: =IF(O11="","",IF(O11="NA","",IF(O11="Mini disjuntor + DR",0.92,IF(O11="Mini disjuntor",0.92,IF(O11="Disjuntor Motor",0.92,IF(O11="Disjuntor C.M.",0.92,IF(O11="Disjuntor C.A.",0.92,IFERROR(VLOOKUP('Lista de Cargas'!P11,Motores!$B$9:$T$48,19,FALSE),"Erro")))))))) -> 0.92 | T11: =IF(O11="","",IF(O11="NA","",IF(O11="Mini disjuntor + DR",100%,IF(O11="Mini disjuntor",100%,IF(O11="Disjuntor Motor",0.92,IF(O11="Disjuntor C.M.",100%,IF(O11="Disjuntor C.A.",100%,IFERROR(VLOOKUP('Lista de Cargas'!P11,Motores!$B$9:$T$48,16,FALSE)/100,"Erro")))))))) -> 1 | U11: Trifásico | V11: 440 | W11: =IFERROR(IF(U11=$U$344,(P11*746)/(SQRT(3)*S11*T11*V11),(P11*746)/(S11*T11*V11)),0) -> 531.7 | X11: =IFERROR(Q11/S11,0) -> 405.20982 | Y11: =IFERROR(IF(O11=$O$344,6*W11,IF(O11=$O$345,6*W11,IF(O11=$O$346,3*W11,IF(O11=$O$347,1.5*W11,W11)))),0) -> 531.7 | AB11: 0 | AG11: =SUM(AB11:AF11) -> 0 | AJ11: =$AG11*AH11*(1+$BJ$1) -> 0 | AP11: =$AG11*AN11*(1+$BJ$1) -> 0 | AQ11: NA | AS11: 1
A12: SE-02 | B12: QGBT-1 | C12: SCD-401 - (PRT001-09) | D12: SECADOR N°1 - ÁREA 400 | O12: Disjuntor C.M. | P12: 555.8321 | Q12: =P12*0.746 -> 414.65075 | S12: =IF(O12="","",IF(O12="NA","",IF(O12="Mini disjuntor + DR",0.92,IF(O12="Mini disjuntor",0.92,IF(O12="Disjuntor Motor",0.92,IF(O12="Disjuntor C.M.",0.92,IF(O12="Disjuntor C.A.",0.92,IFERROR(VLOOKUP('Lista de Cargas'!P12,Motores!$B$9:$T$48,19,FALSE),"Erro")))))))) -> 0.92 | T12: =IF(O12="","",IF(O12="NA","",IF(O12="Mini disjuntor + DR",100%,IF(O12="Mini disjuntor",100%,IF(O12="Disjuntor Motor",0.92,IF(O12="Disjuntor C.M.",100%,IF(O12="Disjuntor C.A.",100%,IFERROR(VLOOKUP('Lista de Cargas'!P12,Motores!$B$9:$T$48,16,FALSE)/100,"Erro")))))))) -> 1 | U12: Trifásico | V12: 440 | W12: =IFERROR(IF(U12=$U$344,(P12*746)/(SQRT(3)*S12*T12*V12),(P12*746)/(S12*T12*V12)),0) -> 591.4 | X12: =IFERROR(Q12/S12,0) -> 450.70733 | Y12: =IFERROR(IF(O12=$O$344,6*W12,IF(O12=$O$345,6*W12,IF(O12=$O$346,3*W12,IF(O12=$O$347,1.5*W12,W12)))),0) -> 591.4 | AB12: 20 | AG12: =SUM(AB12:AF12) -> 20 | AH12: 3 | AI12: 240mm² - 0,6/1kV - PT - EPR - 90ºC - Cobre | AJ12: =$AG12*AH12*(1+$BJ$1) -> 60 | AK12: 0 | AL12: NA | AN12: 1 | AO12: 120mm² - 0,6/1kV - VD - EPR - 90ºC - Cobre | AP12: =$AG12*AN12*(1+$BJ$1) -> 20 | AQ12: NA | AS12: 1
A13: SE-02 | B13: QGBT-1 | C13: SCD-402 - (PRT001-09) | D13: SECADOR N°2 - ÁREA 401 | O13: Disjuntor C.M. | P13: 555.8321 | Q13: =P13*0.746 -> 414.65075 | S13: =IF(O13="","",IF(O13="NA","",IF(O13="Mini disjuntor + DR",0.92,IF(O13="Mini disjuntor",0.92,IF(O13="Disjuntor Motor",0.92,IF(O13="Disjuntor C.M.",0.92,IF(O13="Disjuntor C.A.",0.92,IFERROR(VLOOKUP('Lista de Cargas'!P13,Motores!$B$9:$T$48,19,FALSE),"Erro")))))))) -> 0.92 | T13: =IF(O13="","",IF(O13="NA","",IF(O13="Mini disjuntor + DR",100%,IF(O13="Mini disjuntor",100%,IF(O13="Disjuntor Motor",0.92,IF(O13="Disjuntor C.M.",100%,IF(O13="Disjuntor C.A.",100%,IFERROR(VLOOKUP('Lista de Cargas'!P13,Motores!$B$9:$T$48,16,FALSE)/100,"Erro")))))))) -> 1 | U13: Trifásico | V13: 440 | W13: =IFERROR(IF(U13=$U$344,(P13*746)/(SQRT(3)*S13*T13*V13),(P13*746)/(S13*T13*V13)),0) -> 591.4 | X13: =IFERROR(Q13/S13,0) -> 450.70733 | Y13: =IFERROR(IF(O13=$O$344,6*W13,IF(O13=$O$345,6*W13,IF(O13=$O$346,3*W13,IF(O13=$O$347,1.5*W13,W13)))),0) -> 591.4 | AB13: 20 | AG13: =SUM(AB13:AF13) -> 20 | AH13: 3 | AI13: 240mm² - 0,6/1kV - PT - EPR - 90ºC - Cobre | AJ13: =$AG13*AH13*(1+$BJ$1) -> 60 | AK13: 0 | AL13: NA | AN13: 1 | AO13: 120mm² - 0,6/1kV - VD - EPR - 90ºC - Cobre | AP13: =$AG13*AN13*(1+$BJ$1) -> 20 | AQ13: NA | AS13: 1
A14: SE-02 | B14: QGBT-1 | C14: SCD-403 - (PRT001-09) | D14: SECADOR N°3 - ÁREA 402 | O14: Disjuntor C.M. | P14: 555.8321 | Q14: =P14*0.746 -> 414.65075 | S14: =IF(O14="","",IF(O14="NA","",IF(O14="Mini disjuntor + DR",0.92,IF(O14="Mini disjuntor",0.92,IF(O14="Disjuntor Motor",0.92,IF(O14="Disjuntor C.M.",0.92,IF(O14="Disjuntor C.A.",0.92,IFERROR(VLOOKUP('Lista de Cargas'!P14,Motores!$B$9:$T$48,19,FALSE),"Erro")))))))) -> 0.92 | T14: =IF(O14="","",IF(O14="NA","",IF(O14="Mini disjuntor + DR",100%,IF(O14="Mini disjuntor",100%,IF(O14="Disjuntor Motor",0.92,IF(O14="Disjuntor C.M.",100%,IF(O14="Disjuntor C.A.",100%,IFERROR(VLOOKUP('Lista de Cargas'!P14,Motores!$B$9:$T$48,16,FALSE)/100,"Erro")))))))) -> 1 | U14: Trifásico | V14: 440 | W14: =IFERROR(IF(U14=$U$344,(P14*746)/(SQRT(3)*S14*T14*V14),(P14*746)/(S14*T14*V14)),0) -> 591.4 | X14: =IFERROR(Q14/S14,0) -> 450.70733 | Y14: =IFERROR(IF(O14=$O$344,6*W14,IF(O14=$O$345,6*W14,IF(O14=$O$346,3*W14,IF(O14=$O$347,1.5*W14,W14)))),0) -> 591.4 | AB14: 20 | AG14: =SUM(AB14:AF14) -> 20 | AH14: 3 | AI14: 240mm² - 0,6/1kV - PT - EPR - 90ºC - Cobre | AJ14: =$AG14*AH14*(1+$BJ$1) -> 60 | AK14: 0 | AL14: NA | AN14: 1 | AO14: 120mm² - 0,6/1kV - VD - EPR - 90ºC - Cobre | AP14: =$AG14*AN14*(1+$BJ$1) -> 20 | AQ14: NA | AS14: 1
A15: SE-02 | B15: QGBT-1 | C15: PRT001-04 | D15: BANCO DE CAPACITORES QGBT-1 - TRANSFORMADOR N°1 | O15: Disjuntor C.M. | P15: 925.94823 | Q15: =P15*0.746 -> 690.75738 | S15: =IF(O15="","",IF(O15="NA","",IF(O15="Mini disjuntor + DR",0.92,IF(O15="Mini disjuntor",0.92,IF(O15="Disjuntor Motor",0.92,IF(O15="Disjuntor C.M.",0.92,IF(O15="Disjuntor C.A.",0.92,IFERROR(VLOOKUP('Lista de Cargas'!P15,Motores!$B$9:$T$48,19,FALSE),"Erro")))))))) -> 0.92 | T15: =IF(O15="","",IF(O15="NA","",IF(O15="Mini disjuntor + DR",100%,IF(O15="Mini disjuntor",100%,IF(O15="Disjuntor Motor",0.92,IF(O15="Disjuntor C.M.",100%,IF(O15="Disjuntor C.A.",100%,IFERROR(VLOOKUP('Lista de Cargas'!P15,Motores!$B$9:$T$48,16,FALSE)/100,"Erro")))))))) -> 1 | U15: Trifásico | V15: 440 | W15: =IFERROR(IF(U15=$U$344,(P15*746)/(SQRT(3)*S15*T15*V15),(P15*746)/(S15*T15*V15)),0) -> 985.2 | X15: =IFERROR(Q15/S15,0) -> 750.82324 | Y15: =IFERROR(IF(O15=$O$344,6*W15,IF(O15=$O$345,6*W15,IF(O15=$O$346,3*W15,IF(O15=$O$347,1.5*W15,W15)))),0) -> 985.2 | AB15: 20 | AG15: =SUM(AB15:AF15) -> 20 | AH15: 6 | AI15: 240mm² - 0,6/1kV - PT - EPR - 90ºC - Cobre | AJ15: =$AG15*AH15*(1+$BJ$1) -> 120 | AK15: 0 | AL15: NA | AN15: 1 | AO15: 240mm² - 0,6/1kV - VD - EPR - 90ºC - Cobre | AP15: =$AG15*AN15*(1+$BJ$1) -> 20 | AQ15: NA | AS15: 1
A16: SE-02 | B16: QGBT-2 | C16: Q0 | D16: DISJUNTOR DE ENTRADA | O16: Disjuntor C.A. | P16: 3007.546 | Q16: =P16*0.746 -> 2243.6293 | S16: =IF(O16="","",IF(O16="NA","",IF(O16="Mini disjuntor + DR",0.92,IF(O16="Mini disjuntor",0.92,IF(O16="Disjuntor Motor",0.92,IF(O16="Disjuntor C.M.",0.92,IF(O16="Disjuntor C.A.",0.92,IFERROR(VLOOKUP('Lista de Cargas'!P16,Motores!$B$9:$T$48,19,FALSE),"Erro")))))))) -> 0.92 | T16: =IF(O16="","",IF(O16="NA","",IF(O16="Mini disjuntor + DR",100%,IF(O16="Mini disjuntor",100%,IF(O16="Disjuntor Motor",0.92,IF(O16="Disjuntor C.M.",100%,IF(O16="Disjuntor C.A.",100%,IFERROR(VLOOKUP('Lista de Cargas'!P16,Motores!$B$9:$T$48,16,FALSE)/100,"Erro")))))))) -> 1 | U16: Trifásico | V16: 440 | W16: =IFERROR(IF(U16=$U$344,(P16*746)/(SQRT(3)*S16*T16*V16),(P16*746)/(S16*T16*V16)),0) -> 3200 | X16: =IFERROR(Q16/S16,0) -> 2438.7275 | Y16: =IFERROR(IF(O16=$O$344,6*W16,IF(O16=$O$345,6*W16,IF(O16=$O$346,3*W16,IF(O16=$O$347,1.5*W16,W16)))),0) -> 3200 | AB16: 20 | AG16: =SUM(AB16:AF16) -> 20 | AH16: 21 | AI16: 240mm² - 0,6/1kV - PT - EPR - 90ºC - Cobre | AJ16: =$AG16*AH16*(1+$BJ$1) -> 420 | AK16: 0 | AL16: NA | AN16: 4 | AO16: 240mm² - 0,6/1kV - VD - EPR - 90ºC - Cobre | AP16: =$AG16*AN16*(1+$BJ$1) -> 80 | AQ16: NA | AS16: 1
A17: SE-02 | B17: QGBT-2 | C17: MO1-100-00 | D17: MOINHO (FASE 1) | O17: Disjuntor C.M. | P17: 850.0077 | Q17: =P17*0.746 -> 634.10574 | S17: =IF(O17="","",IF(O17="NA","",IF(O17="Mini disjuntor + DR",0.92,IF(O17="Mini disjuntor",0.92,IF(O17="Disjuntor Motor",0.92,IF(O17="Disjuntor C.M.",0.92,IF(O17="Disjuntor C.A.",0.92,IFERROR(VLOOKUP('Lista de Cargas'!P17,Motores!$B$9:$T$48,19,FALSE),"Erro")))))))) -> 0.92 | T17: =IF(O17="","",IF(O17="NA","",IF(O17="Mini disjuntor + DR",100%,IF(O17="Mini disjuntor",100%,IF(O17="Disjuntor Motor",0.92,IF(O17="Disjuntor C.M.",100%,IF(O17="Disjuntor C.A.",100%,IFERROR(VLOOKUP('Lista de Cargas'!P17,Motores!$B$9:$T$48,16,FALSE)/100,"Erro")))))))) -> 1 | U17: Trifásico | V17: 440 | W17: =IFERROR(IF(U17=$U$344,(P17*746)/(SQRT(3)*S17*T17*V17),(P17*746)/(S17*T17*V17)),0) -> 904.4 | X17: =IFERROR(Q17/S17,0) -> 689.24537 | Y17: =IFERROR(IF(O17=$O$344,6*W17,IF(O17=$O$345,6*W17,IF(O17=$O$346,3*W17,IF(O17=$O$347,1.5*W17,W17)))),0) -> 904.4 | AB17: 20 | AG17: =SUM(AB17:AF17) -> 20 | AH17: 6 | AI17: 185mm² - 0,6/1kV - PT - EPR - 90ºC - Cobre | AJ17: =$AG17*AH17*(1+$BJ$1) -> 120 | AK17: 0 | AL17: NA | AN17: 1 | AO17: 185mm² - 0,6/1kV - VD - EPR - 90ºC - Cobre | AP17: =$AG17*AN17*(1+$BJ$1) -> 20 | AQ17: NA | AS17: 1
A18: SE-02 | B18: QGBT-2 | C18: PRT001-12 | D18: CCM 2.1 - ÁREA 400 | O18: Disjuntor C.M. | P18: 2349.6453 | Q18: =P18*0.746 -> 1752.8354 | S18: =IF(O18="","",IF(O18="NA","",IF(O18="Mini disjuntor + DR",0.92,IF(O18="Mini disjuntor",0.92,IF(O18="Disjuntor Motor",0.92,IF(O18="Disjuntor C.M.",0.92,IF(O18="Disjuntor C.A.",0.92,IFERROR(VLOOKUP('Lista de Cargas'!P18,Motores!$B$9:$T$48,19,FALSE),"Erro")))))))) -> 0.92 | T18: =IF(O18="","",IF(O18="NA","",IF(O18="Mini disjuntor + DR",100%,IF(O18="Mini disjuntor",100%,IF(O18="Disjuntor Motor",0.92,IF(O18="Disjuntor C.M.",100%,IF(O18="Disjuntor C.A.",100%,IFERROR(VLOOKUP('Lista de Cargas'!P18,Motores!$B$9:$T$48,16,FALSE)/100,"Erro")))))))) -> 1 | U18: Trifásico | V18: 440 | W18: =IFERROR(IF(U18=$U$344,(P18*746)/(SQRT(3)*S18*T18*V18),(P18*746)/(S18*T18*V18)),0) -> 2500 | X18: =IFERROR(Q18/S18,0) -> 1905.2559 | Y18: =IFERROR(IF(O18=$O$344,6*W18,IF(O18=$O$345,6*W18,IF(O18=$O$346,3*W18,IF(O18=$O$347,1.5*W18,W18)))),0) -> 2500 | AB18: 20 | AG18: =SUM(AB18:AF18) -> 20 | AH18: 15 | AI18: 240mm² - 0,6/1kV - PT - EPR - 90ºC - Cobre | AJ18: =$AG18*AH18*(1+$BJ$1) -> 300 | AK18: 0 | AL18: NA | AN18: 4 | AO18: 150mm² - 0,6/1kV - VD - EPR - 90ºC - Cobre | AP18: =$AG18*AN18*(1+$BJ$1) -> 80 | AQ18: NA | AS18: 1
A19: SE-02 | B19: QGBT-2 | C19: PRT001-05 | D19: BANCO DE CAPACITORES QGBT-2 - TRANSFORMADOR N°2 | O19: Disjuntor C.M. | P19: 925.94823 | Q19: =P19*0.746 -> 690.75738 | S19: =IF(O19="","",IF(O19="NA","",IF(O19="Mini disjuntor + DR",0.92,IF(O19="Mini disjuntor",0.92,IF(O19="Disjuntor Motor",0.92,IF(O19="Disjuntor C.M.",0.92,IF(O19="Disjuntor C.A.",0.92,IFERROR(VLOOKUP('Lista de Cargas'!P19,Motores!$B$9:$T$48,19,FALSE),"Erro")))))))) -> 0.92 | T19: =IF(O19="","",IF(O19="NA","",IF(O19="Mini disjuntor + DR",100%,IF(O19="Mini disjuntor",100%,IF(O19="Disjuntor Motor",0.92,IF(O19="Disjuntor C.M.",100%,IF(O19="Disjuntor C.A.",100%,IFERROR(VLOOKUP('Lista de Cargas'!P19,Motores!$B$9:$T$48,16,FALSE)/100,"Erro")))))))) -> 1 | U19: Trifásico | V19: 440 | W19: =IFERROR(IF(U19=$U$344,(P19*746)/(SQRT(3)*S19*T19*V19),(P19*746)/(S19*T19*V19)),0) -> 985.2 | X19: =IFERROR(Q19/S19,0) -> 750.82324 | Y19: =IFERROR(IF(O19=$O$344,6*W19,IF(O19=$O$345,6*W19,IF(O19=$O$346,3*W19,IF(O19=$O$347,1.5*W19,W19)))),0) -> 985.2 | AB19: 20 | AG19: =SUM(AB19:AF19) -> 20 | AH19: 6 | AI19: 240mm² - 0,6/1kV - PT - EPR - 90ºC - Cobre | AJ19: =$AG19*AH19*(1+$BJ$1) -> 120 | AK19: 0 | AL19: NA | AN19: 1 | AO19: 240mm² - 0,6/1kV - VD - EPR - 90ºC - Cobre | AP19: =$AG19*AN19*(1+$BJ$1) -> 20 | AQ19: NA | AS19: 1
A20: SE-02 | B20: QGBT-3 | C20: Q0 | D20: DISJUNTOR DE ENTRADA | O20: Disjuntor C.M. | P20: 3007.546 | Q20: =P20*0.746 -> 2243.6293 | S20: =IF(O20="","",IF(O20="NA","",IF(O20="Mini disjuntor + DR",0.92,IF(O20="Mini disjuntor",0.92,IF(O20="Disjuntor Motor",0.92,IF(O20="Disjuntor C.M.",0.92,IF(O20="Disjuntor C.A.",0.92,IFERROR(VLOOKUP('Lista de Cargas'!P20,Motores!$B$9:$T$48,19,FALSE),"Erro")))))))) -> 0.92 | T20: =IF(O20="","",IF(O20="NA","",IF(O20="Mini disjuntor + DR",100%,IF(O20="Mini disjuntor",100%,IF(O20="Disjuntor Motor",0.92,IF(O20="Disjuntor C.M.",100%,IF(O20="Disjuntor C.A.",100%,IFERROR(VLOOKUP('Lista de Cargas'!P20,Motores!$B$9:$T$48,16,FALSE)/100,"Erro")))))))) -> 1 | U20: Trifásico | V20: 440 | W20: =IFERROR(IF(U20=$U$344,(P20*746)/(SQRT(3)*S20*T20*V20),(P20*746)/(S20*T20*V20)),0) -> 3200 | X20: =IFERROR(Q20/S20,0) -> 2438.7275 | Y20: =IFERROR(IF(O20=$O$344,6*W20,IF(O20=$O$345,6*W20,IF(O20=$O$346,3*W20,IF(O20=$O$347,1.5*W20,W20)))),0) -> 3200 | AB20: 20 | AG20: =SUM(AB20:AF20) -> 20 | AH20: 21 | AI20: 240mm² - 0,6/1kV - PT - EPR - 90ºC - Cobre | AJ20: =$AG20*AH20*(1+$BJ$1) -> 420 | AK20: 0 | AL20: NA | AN20: 4 | AO20: 240mm² - 0,6/1kV - VD - EPR - 90ºC - Cobre | AP20: =$AG20*AN20*(1+$BJ$1) -> 80 | AQ20: NA | AS20: 1
A21: SE-02 | B21: QGBT-3 | C21: DCT-401 | D21: DECANTER N°1 (FASE 1) | O21: Disjuntor C.M. | P21: 234.96453 | Q21: =P21*0.746 -> 175.28354 | S21: =IF(O21="","",IF(O21="NA","",IF(O21="Mini disjuntor + DR",0.92,IF(O21="Mini disjuntor",0.92,IF(O21="Disjuntor Motor",0.92,IF(O21="Disjuntor C.M.",0.92,IF(O21="Disjuntor C.A.",0.92,IFERROR(VLOOKUP('Lista de Cargas'!P21,Motores!$B$9:$T$48,19,FALSE),"Erro")))))))) -> 0.92 | T21: =IF(O21="","",IF(O21="NA","",IF(O21="Mini disjuntor + DR",100%,IF(O21="Mini disjuntor",100%,IF(O21="Disjuntor Motor",0.92,IF(O21="Disjuntor C.M.",100%,IF(O21="Disjuntor C.A.",100%,IFERROR(VLOOKUP('Lista de Cargas'!P21,Motores!$B$9:$T$48,16,FALSE)/100,"Erro")))))))) -> 1 | U21: Trifásico | V21: 440 | W21: =IFERROR(IF(U21=$U$344,(P21*746)/(SQRT(3)*S21*T21*V21),(P21*746)/(S21*T21*V21)),0) -> 250 | X21: =IFERROR(Q21/S21,0) -> 190.52559 | Y21: =IFERROR(IF(O21=$O$344,6*W21,IF(O21=$O$345,6*W21,IF(O21=$O$346,3*W21,IF(O21=$O$347,1.5*W21,W21)))),0) -> 250 | AB21: 20 | AG21: =SUM(AB21:AF21) -> 20 | AH21: 3 | AI21: 70mm² - 0,6/1kV - PT - EPR - 90ºC - Cobre | AJ21: =$AG21*AH21*(1+$BJ$1) -> 60 | AK21: 0 | AL21: NA | AN21: 1 | AO21: 35mm² - 0,6/1kV - VD - EPR - 90ºC - Cobre | AP21: =$AG21*AN21*(1+$BJ$1) -> 20 | AQ21: NA | AS21: 1
A22: SE-02 | B22: QGBT-3 | C22: DCT-402 | D22: DECANTER N°2 (FASE 1) | O22: Disjuntor C.M. | P22: 234.96453 | Q22: =P22*0.746 -> 175.28354 | S22: =IF(O22="","",IF(O22="NA","",IF(O22="Mini disjuntor + DR",0.92,IF(O22="Mini disjuntor",0.92,IF(O22="Disjuntor Motor",0.92,IF(O22="Disjuntor C.M.",0.92,IF(O22="Disjuntor C.A.",0.92,IFERROR(VLOOKUP('Lista de Cargas'!P22,Motores!$B$9:$T$48,19,FALSE),"Erro")))))))) -> 0.92 | T22: =IF(O22="","",IF(O22="NA","",IF(O22="Mini disjuntor + DR",100%,IF(O22="Mini disjuntor",100%,IF(O22="Disjuntor Motor",0.92,IF(O22="Disjuntor C.M.",100%,IF(O22="Disjuntor C.A.",100%,IFERROR(VLOOKUP('Lista de Cargas'!P22,Motores!$B$9:$T$48,16,FALSE)/100,"Erro")))))))) -> 1 | U22: Trifásico | V22: 440 | W22: =IFERROR(IF(U22=$U$344,(P22*746)/(SQRT(3)*S22*T22*V22),(P22*746)/(S22*T22*V22)),0) -> 250 | X22: =IFERROR(Q22/S22,0) -> 190.52559 | Y22: =IFERROR(IF(O22=$O$344,6*W22,IF(O22=$O$345,6*W22,IF(O22=$O$346,3*W22,IF(O22=$O$347,1.5*W22,W22)))),0) -> 250 | AB22: 20 | AG22: =SUM(AB22:AF22) -> 20 | AH22: 3 | AI22: 70mm² - 0,6/1kV - PT - EPR - 90ºC - Cobre | AJ22: =$AG22*AH22*(1+$BJ$1) -> 60 | AK22: 0 | AL22: NA | AN22: 1 | AO22: 35mm² - 0,6/1kV - VD - EPR - 90ºC - Cobre | AP22: =$AG22*AN22*(1+$BJ$1) -> 20 | AQ22: NA | AS22: 1
A23: SE-02 | B23: QGBT-3 | C23: DCT-403 | D23: DECANTER N°3 (FASE 1) | O23: Disjuntor C.M. | P23: 234.96453 | Q23: =P23*0.746 -> 175.28354 | S23: =IF(O23="","",IF(O23="NA","",IF(O23="Mini disjuntor + DR",0.92,IF(O23="Mini disjuntor",0.92,IF(O23="Disjuntor Motor",0.92,IF(O23="Disjuntor C.M.",0.92,IF(O23="Disjuntor C.A.",0.92,IFERROR(VLOOKUP('Lista de Cargas'!P23,Motores!$B$9:$T$48,19,FALSE),"Erro")))))))) -> 0.92 | T23: =IF(O23="","",IF(O23="NA","",IF(O23="Mini disjuntor + DR",100%,IF(O23="Mini disjuntor",100%,IF(O23="Disjuntor Motor",0.92,IF(O23="Disjuntor C.M.",100%,IF(O23="Disjuntor C.A.",100%,IFERROR(VLOOKUP('Lista de Cargas'!P23,Motores!$B$9:$T$48,16,FALSE)/100,"Erro")))))))) -> 1 | U23: Trifásico | V23: 440 | W23: =IFERROR(IF(U23=$U$344,(P23*746)/(SQRT(3)*S23*T23*V23),(P23*746)/(S23*T23*V23)),0) -> 250 | X23: =IFERROR(Q23/S23,0) -> 190.52559 | Y23: =IFERROR(IF(O23=$O$344,6*W23,IF(O23=$O$345,6*W23,IF(O23=$O$346,3*W23,IF(O23=$O$347,1.5*W23,W23)))),0) -> 250 | AB23: 20 | AG23: =SUM(AB23:AF23) -> 20 | AH23: 3 | AI23: 70mm² - 0,6/1kV - PT - EPR - 90ºC - Cobre | AJ23: =$AG23*AH23*(1+$BJ$1) -> 60 | AK23: 0 | AL23: NA | AN23: 1 | AO23: 35mm² - 0,6/1kV - VD - EPR - 90ºC - Cobre | AP23: =$AG23*AN23*(1+$BJ$1) -> 20 | AQ23: NA | AS23: 1
A24: SE-02 | B24: QGBT-3 | C24: DCT-401 | D24: DECANTER N°4 (FASE 1) | O24: Disjuntor C.M. | P24: 234.96453 | Q24: =P24*0.746 -> 175.28354 | S24: =IF(O24="","",IF(O24="NA","",IF(O24="Mini disjuntor + DR",0.92,IF(O24="Mini disjuntor",0.92,IF(O24="Disjuntor Motor",0.92,IF(O24="Disjuntor C.M.",0.92,IF(O24="Disjuntor C.A.",0.92,IFERROR(VLOOKUP('Lista de Cargas'!P24,Motores!$B$9:$T$48,19,FALSE),"Erro")))))))) -> 0.92 | T24: =IF(O24="","",IF(O24="NA","",IF(O24="Mini disjuntor + DR",100%,IF(O24="Mini disjuntor",100%,IF(O24="Disjuntor Motor",0.92,IF(O24="Disjuntor C.M.",100%,IF(O24="Disjuntor C.A.",100%,IFERROR(VLOOKUP('Lista de Cargas'!P24,Motores!$B$9:$T$48,16,FALSE)/100,"Erro")))))))) -> 1 | U24: Trifásico | V24: 440 | W24: =IFERROR(IF(U24=$U$344,(P24*746)/(SQRT(3)*S24*T24*V24),(P24*746)/(S24*T24*V24)),0) -> 250 | X24: =IFERROR(Q24/S24,0) -> 190.52559 | Y24: =IFERROR(IF(O24=$O$344,6*W24,IF(O24=$O$345,6*W24,IF(O24=$O$346,3*W24,IF(O24=$O$347,1.5*W24,W24)))),0) -> 250 | AB24: 20 | AG24: =SUM(AB24:AF24) -> 20 | AH24: 3 | AI24: 70mm² - 0,6/1kV - PT - EPR - 90ºC - Cobre | AJ24: =$AG24*AH24*(1+$BJ$1) -> 60 | AK24: 0 | AL24: NA | AN24: 1 | AO24: 35mm² - 0,6/1kV - VD - EPR - 90ºC - Cobre | AP24: =$AG24*AN24*(1+$BJ$1) -> 20 | AQ24: NA | AS24: 1
A25: SE-02 | B25: QGBT-3 | C25: CHL-401 | D25: CHILLER N°1 (FASE 1) | O25: Disjuntor C.M. | P25: 25.470155 | Q25: =P25*0.746 -> 19.000736 | S25: =IF(O25="","",IF(O25="NA","",IF(O25="Mini disjuntor + DR",0.92,IF(O25="Mini disjuntor",0.92,IF(O25="Disjuntor Motor",0.92,IF(O25="Disjuntor C.M.",0.92,IF(O25="Disjuntor C.A.",0.92,IFERROR(VLOOKUP('Lista de Cargas'!P25,Motores!$B$9:$T$48,19,FALSE),"Erro")))))))) -> 0.92 | T25: =IF(O25="","",IF(O25="NA","",IF(O25="Mini disjuntor + DR",100%,IF(O25="Mini disjuntor",100%,IF(O25="Disjuntor Motor",0.92,IF(O25="Disjuntor C.M.",100%,IF(O25="Disjuntor C.A.",100%,IFERROR(VLOOKUP('Lista de Cargas'!P25,Motores!$B$9:$T$48,16,FALSE)/100,"Erro")))))))) -> 1 | U25: Trifásico | V25: 440 | W25: =IFERROR(IF(U25=$U$344,(P25*746)/(SQRT(3)*S25*T25*V25),(P25*746)/(S25*T25*V25)),0) -> 27.1 | X25: =IFERROR(Q25/S25,0) -> 20.652974 | Y25: =IFERROR(IF(O25=$O$344,6*W25,IF(O25=$O$345,6*W25,IF(O25=$O$346,3*W25,IF(O25=$O$347,1.5*W25,W25)))),0) -> 27.1 | AB25: 20 | AG25: =SUM(AB25:AF25) -> 20 | AH25: 1 | AI25: PP 4 x 2,5mm² - 0,6/1kV - EPR - 90ºC - Cobre | AJ25: =$AG25*AH25*(1+$BJ$1) -> 20 | AK25: 0 | AL25: NA | AN25: 0 | AP25: =$AG25*AN25*(1+$BJ$1) -> 0 | AQ25: NA | AS25: 1
A26: SE-02 | B26: QGBT-3 | C26: CHL-402 | D26: CHILLER N°2 (FASE 1) | O26: Disjuntor C.M. | P26: 25.470155 | Q26: =P26*0.746 -> 19.000736 | S26: =IF(O26="","",IF(O26="NA","",IF(O26="Mini disjuntor + DR",0.92,IF(O26="Mini disjuntor",0.92,IF(O26="Disjuntor Motor",0.92,IF(O26="Disjuntor C.M.",0.92,IF(O26="Disjuntor C.A.",0.92,IFERROR(VLOOKUP('Lista de Cargas'!P26,Motores!$B$9:$T$48,19,FALSE),"Erro")))))))) -> 0.92 | T26: =IF(O26="","",IF(O26="NA","",IF(O26="Mini disjuntor + DR",100%,IF(O26="Mini disjuntor",100%,IF(O26="Disjuntor Motor",0.92,IF(O26="Disjuntor C.M.",100%,IF(O26="Disjuntor C.A.",100%,IFERROR(VLOOKUP('Lista de Cargas'!P26,Motores!$B$9:$T$48,16,FALSE)/100,"Erro")))))))) -> 1 | U26: Trifásico | V26: 440 | W26: =IFERROR(IF(U26=$U$344,(P26*746)/(SQRT(3)*S26*T26*V26),(P26*746)/(S26*T26*V26)),0) -> 27.1 | X26: =IFERROR(Q26/S26,0) -> 20.652974 | Y26: =IFERROR(IF(O26=$O$344,6*W26,IF(O26=$O$345,6*W26,IF(O26=$O$346,3*W26,IF(O26=$O$347,1.5*W26,W26)))),0) -> 27.1 | AB26: 20 | AG26: =SUM(AB26:AF26) -> 20 | AH26: 1 | AI26: PP 4 x 2,5mm² - 0,6/1kV - EPR - 90ºC - Cobre | AJ26: =$AG26*AH26*(1+$BJ$1) -> 20 | AK26: 0 | AL26: NA | AN26: 0 | AO26: NA | AP26: =$AG26*AN26*(1+$BJ$1) -> 0 | AQ26: NA | AS26: 1
A27: SE-02 | B27: QGBT-3 | C27: CHL-403 | D27: CHILLER N°3 (FASE 1) | O27: Disjuntor C.M. | P27: 25.470155 | Q27: =P27*0.746 -> 19.000736 | S27: =IF(O27="","",IF(O27="NA","",IF(O27="Mini disjuntor + DR",0.92,IF(O27="Mini disjuntor",0.92,IF(O27="Disjuntor Motor",0.92,IF(O27="Disjuntor C.M.",0.92,IF(O27="Disjuntor C.A.",0.92,IFERROR(VLOOKUP('Lista de Cargas'!P27,Motores!$B$9:$T$48,19,FALSE),"Erro")))))))) -> 0.92 | T27: =IF(O27="","",IF(O27="NA","",IF(O27="Mini disjuntor + DR",100%,IF(O27="Mini disjuntor",100%,IF(O27="Disjuntor Motor",0.92,IF(O27="Disjuntor C.M.",100%,IF(O27="Disjuntor C.A.",100%,IFERROR(VLOOKUP('Lista de Cargas'!P27,Motores!$B$9:$T$48,16,FALSE)/100,"Erro")))))))) -> 1 | U27: Trifásico | V27: 440 | W27: =IFERROR(IF(U27=$U$344,(P27*746)/(SQRT(3)*S27*T27*V27),(P27*746)/(S27*T27*V27)),0) -> 27.1 | X27: =IFERROR(Q27/S27,0) -> 20.652974 | Y27: =IFERROR(IF(O27=$O$344,6*W27,IF(O27=$O$345,6*W27,IF(O27=$O$346,3*W27,IF(O27=$O$347,1.5*W27,W27)))),0) -> 27.1 | AB27: 20 | AG27: =SUM(AB27:AF27) -> 20 | AH27: 1 | AI27: PP 4 x 2,5mm² - 0,6/1kV - EPR - 90ºC - Cobre | AJ27: =$AG27*AH27*(1+$BJ$1) -> 20 | AK27: 0 | AL27: NA | AN27: 0 | AO27: NA | AP27: =$AG27*AN27*(1+$BJ$1) -> 0 | AQ27: NA | AS27: 1
A28: SE-02 | B28: QGBT-3 | C28: RFD-401 | D28: RESFRIADOR DDGS (FASE1) | O28: Disjuntor C.M. | P28: 301.69446 | Q28: =P28*0.746 -> 225.06407 | S28: =IF(O28="","",IF(O28="NA","",IF(O28="Mini disjuntor + DR",0.92,IF(O28="Mini disjuntor",0.92,IF(O28="Disjuntor Motor",0.92,IF(O28="Disjuntor C.M.",0.92,IF(O28="Disjuntor C.A.",0.92,IFERROR(VLOOKUP('Lista de Cargas'!P28,Motores!$B$9:$T$48,19,FALSE),"Erro")))))))) -> 0.92 | T28: =IF(O28="","",IF(O28="NA","",IF(O28="Mini disjuntor + DR",100%,IF(O28="Mini disjuntor",100%,IF(O28="Disjuntor Motor",0.92,IF(O28="Disjuntor C.M.",100%,IF(O28="Disjuntor C.A.",100%,IFERROR(VLOOKUP('Lista de Cargas'!P28,Motores!$B$9:$T$48,16,FALSE)/100,"Erro")))))))) -> 1 | U28: Trifásico | V28: 440 | W28: =IFERROR(IF(U28=$U$344,(P28*746)/(SQRT(3)*S28*T28*V28),(P28*746)/(S28*T28*V28)),0) -> 321 | X28: =IFERROR(Q28/S28,0) -> 244.63486 | Y28: =IFERROR(IF(O28=$O$344,6*W28,IF(O28=$O$345,6*W28,IF(O28=$O$346,3*W28,IF(O28=$O$347,1.5*W28,W28)))),0) -> 321 | AB28: 20 | AG28: =SUM(AB28:AF28) -> 20 | AH28: 3 | AI28: 95mm² - 0,6/1kV - PT - EPR - 90ºC - Cobre | AJ28: =$AG28*AH28*(1+$BJ$1) -> 60 | AK28: 0 | AL28: NA | AN28: 1 | AO28: 50mm² - 0,6/1kV - VD - EPR - 90ºC - Cobre | AP28: =$AG28*AN28*(1+$BJ$1) -> 20 | AQ28: NA | AS28: 1
A29: SE-02 | B29: QGBT-3 | C29: PRO-4001, 4002, 4003 | D29: PONTE ROLANTE | O29: Disjuntor C.M. | P29: 34.304822 | Q29: =P29*0.746 -> 25.591397 | S29: =IF(O29="","",IF(O29="NA","",IF(O29="Mini disjuntor + DR",0.92,IF(O29="Mini disjuntor",0.92,IF(O29="Disjuntor Motor",0.92,IF(O29="Disjuntor C.M.",0.92,IF(O29="Disjuntor C.A.",0.92,IFERROR(VLOOKUP('Lista de Cargas'!P29,Motores!$B$9:$T$48,19,FALSE),"Erro")))))))) -> 0.92 | T29: =IF(O29="","",IF(O29="NA","",IF(O29="Mini disjuntor + DR",100%,IF(O29="Mini disjuntor",100%,IF(O29="Disjuntor Motor",0.92,IF(O29="Disjuntor C.M.",100%,IF(O29="Disjuntor C.A.",100%,IFERROR(VLOOKUP('Lista de Cargas'!P29,Motores!$B$9:$T$48,16,FALSE)/100,"Erro")))))))) -> 1 | U29: Trifásico | V29: 440 | W29: =IFERROR(IF(U29=$U$344,(P29*746)/(SQRT(3)*S29*T29*V29),(P29*746)/(S29*T29*V29)),0) -> 36.5 | X29: =IFERROR(Q29/S29,0) -> 27.816736 | Y29: =IFERROR(IF(O29=$O$344,6*W29,IF(O29=$O$345,6*W29,IF(O29=$O$346,3*W29,IF(O29=$O$347,1.5*W29,W29)))),0) -> 36.5 | AB29: 100 | AG29: =SUM(AB29:AF29) -> 100 | AH29: 1 | AI29: PP 4 x 10mm² - 0,6/1kV - EPR - 90ºC - Cobre | AJ29: =$AG29*AH29*(1+$BJ$1) -> 100 | AK29: 0 | AL29: NA | AN29: 0 | AO29: NA | AP29: =$AG29*AN29*(1+$BJ$1) -> 0 | AQ29: NA | AS29: 1
A30: SE-02 | B30: QGBT-3 | C30: TRF-001 | D30: TRANSFORMADOR DE 150 kVA | O30: Disjuntor C.M. | P30: 185.19905 | Q30: =P30*0.746 -> 138.15849 | S30: =IF(O30="","",IF(O30="NA","",IF(O30="Mini disjuntor + DR",0.92,IF(O30="Mini disjuntor",0.92,IF(O30="Disjuntor Motor",0.92,IF(O30="Disjuntor C.M.",0.92,IF(O30="Disjuntor C.A.",0.92,IFERROR(VLOOKUP('Lista de Cargas'!P30,Motores!$B$9:$T$48,19,FALSE),"Erro")))))))) -> 0.92 | T30: =IF(O30="","",IF(O30="NA","",IF(O30="Mini disjuntor + DR",100%,IF(O30="Mini disjuntor",100%,IF(O30="Disjuntor Motor",0.92,IF(O30="Disjuntor C.M.",100%,IF(O30="Disjuntor C.A.",100%,IFERROR(VLOOKUP('Lista de Cargas'!P30,Motores!$B$9:$T$48,16,FALSE)/100,"Erro")))))))) -> 1 | U30: Trifásico | V30: 440 | W30: =IFERROR(IF(U30=$U$344,(P30*746)/(SQRT(3)*S30*T30*V30),(P30*746)/(S30*T30*V30)),0) -> 197.05 | X30: =IFERROR(Q30/S30,0) -> 150.17227 | Y30: =IFERROR(IF(O30=$O$344,6*W30,IF(O30=$O$345,6*W30,IF(O30=$O$346,3*W30,IF(O30=$O$347,1.5*W30,W30)))),0) -> 197.05 | AB30: 20 | AG30: =SUM(AB30:AF30) -> 20 | AH30: 3 | AI30: 50mm² - 0,6/1kV - PT - EPR - 90ºC - Cobre | AJ30: =$AG30*AH30*(1+$BJ$1) -> 60 | AK30: 0 | AL30: NA | AN30: 1 | AO30: 25mm² - 0,6/1kV - VD - EPR - 90ºC - Cobre | AP30: =$AG30*AN30*(1+$BJ$1) -> 20 | AQ30: NA | AS30: 1
A31: SE-02 | B31: QGBT-3 | C31: PRT001-06 | D31: BANCO DE CAPACITORES QGBT-3 - TRANSFORMADOR N°3 | O31: Disjuntor C.M. | P31: 925.94823 | Q31: =P31*0.746 -> 690.75738 | S31: =IF(O31="","",IF(O31="NA","",IF(O31="Mini disjuntor + DR",0.92,IF(O31="Mini disjuntor",0.92,IF(O31="Disjuntor Motor",0.92,IF(O31="Disjuntor C.M.",0.92,IF(O31="Disjuntor C.A.",0.92,IFERROR(VLOOKUP('Lista de Cargas'!P31,Motores!$B$9:$T$48,19,FALSE),"Erro")))))))) -> 0.92 | T31: =IF(O31="","",IF(O31="NA","",IF(O31="Mini disjuntor + DR",100%,IF(O31="Mini disjuntor",100%,IF(O31="Disjuntor Motor",0.92,IF(O31="Disjuntor C.M.",100%,IF(O31="Disjuntor C.A.",100%,IFERROR(VLOOKUP('Lista de Cargas'!P31,Motores!$B$9:$T$48,16,FALSE)/100,"Erro")))))))) -> 1 | U31: Trifásico | V31: 440 | W31: =IFERROR(IF(U31=$U$344,(P31*746)/(SQRT(3)*S31*T31*V31),(P31*746)/(S31*T31*V31)),0) -> 985.2 | X31: =IFERROR(Q31/S31,0) -> 750.82324 | Y31: =IFERROR(IF(O31=$O$344,6*W31,IF(O31=$O$345,6*W31,IF(O31=$O$346,3*W31,IF(O31=$O$347,1.5*W31,W31)))),0) -> 985.2 | AB31: 20 | AG31: =SUM(AB31:AF31) -> 20 | AH31: 6 | AI31: 240mm² - 0,6/1kV - PT - EPR - 90ºC - Cobre | AJ31: =$AG31*AH31*(1+$BJ$1) -> 120 | AK31: 0 | AL31: NA | AN31: 1 | AO31: 240mm² - 0,6/1kV - VD - EPR - 90ºC - Cobre | AP31: =$AG31*AN31*(1+$BJ$1) -> 20 | AQ31: NA | AS31: 1
A32: SE-03 | B32: QGBT-4 | C32: Q0 | D32: DISJUNTOR DE ENTRADA | O32: Disjuntor C.A. | P32: 3007.546 | Q32: =P32*0.746 -> 2243.6293 | S32: =IF(O32="","",IF(O32="NA","",IF(O32="Mini disjuntor + DR",0.92,IF(O32="Mini disjuntor",0.92,IF(O32="Disjuntor Motor",0.92,IF(O32="Disjuntor C.M.",0.92,IF(O32="Disjuntor C.A.",0.92,IFERROR(VLOOKUP('Lista de Cargas'!P32,Motores!$B$9:$T$48,19,FALSE),"Erro")))))))) -> 0.92 | T32: =IF(O32="","",IF(O32="NA","",IF(O32="Mini disjuntor + DR",100%,IF(O32="Mini disjuntor",100%,IF(O32="Disjuntor Motor",0.92,IF(O32="Disjuntor C.M.",100%,IF(O32="Disjuntor C.A.",100%,IFERROR(VLOOKUP('Lista de Cargas'!P32,Motores!$B$9:$T$48,16,FALSE)/100,"Erro")))))))) -> 1 | U32: Trifásico | V32: 440 | W32: =IFERROR(IF(U32=$U$344,(P32*746)/(SQRT(3)*S32*T32*V32),(P32*746)/(S32*T32*V32)),0) -> 3200 | X32: =IFERROR(Q32/S32,0) -> 2438.7275 | Y32: =IFERROR(IF(O32=$O$344,6*W32,IF(O32=$O$345,6*W32,IF(O32=$O$346,3*W32,IF(O32=$O$347,1.5*W32,W32)))),0) -> 3200 | AB32: 20 | AG32: =SUM(AB32:AF32) -> 20 | AH32: 21 | AI32: 240mm² - 0,6/1kV - PT - EPR - 90ºC - Cobre | AJ32: =$AG32*AH32*(1+$BJ$1) -> 420 | AK32: 0 | AL32: NA | AN32: 4 | AO32: 240mm² - 0,6/1kV - VD - EPR - 90ºC - Cobre | AP32: =$AG32*AN32*(1+$BJ$1) -> 80 | AQ32: NA | AS32: 1
A33: SE-03 | B33: QGBT-4 | C33: PRM-201 | D33: PRÉ-MASHER | O33: Disjuntor C.M. | P33: 141.16669 | Q33: =P33*0.746 -> 105.31035 | S33: =IF(O33="","",IF(O33="NA","",IF(O33="Mini disjuntor + DR",0.92,IF(O33="Mini disjuntor",0.92,IF(O33="Disjuntor Motor",0.92,IF(O33="Disjuntor C.M.",0.92,IF(O33="Disjuntor C.A.",0.92,IFERROR(VLOOKUP('Lista de Cargas'!P33,Motores!$B$9:$T$48,19,FALSE),"Erro")))))))) -> 0.92 | T33: =IF(O33="","",IF(O33="NA","",IF(O33="Mini disjuntor + DR",100%,IF(O33="Mini disjuntor",100%,IF(O33="Disjuntor Motor",0.92,IF(O33="Disjuntor C.M.",100%,IF(O33="Disjuntor C.A.",100%,IFERROR(VLOOKUP('Lista de Cargas'!P33,Motores!$B$9:$T$48,16,FALSE)/100,"Erro")))))))) -> 1 | U33: Trifásico | V33: 440 | W33: =IFERROR(IF(U33=$U$344,(P33*746)/(SQRT(3)*S33*T33*V33),(P33*746)/(S33*T33*V33)),0) -> 150.2 | X33: =IFERROR(Q33/S33,0) -> 114.46777 | Y33: =IFERROR(IF(O33=$O$344,6*W33,IF(O33=$O$345,6*W33,IF(O33=$O$346,3*W33,IF(O33=$O$347,1.5*W33,W33)))),0) -> 150.2 | AB33: 20 | AG33: =SUM(AB33:AF33) -> 20 | AH33: 3 | AI33: 35mm² - 0,6/1kV - PT - EPR - 90ºC - Cobre | AJ33: =$AG33*AH33*(1+$BJ$1) -> 60 | AK33: 0 | AL33: NA | AN33: 1 | AO33: 25mm² - 0,6/1kV - VD - EPR - 90ºC - Cobre | AP33: =$AG33*AN33*(1+$BJ$1) -> 20 | AQ33: NA | AS33: 1
A34: SE-03 | B34: QGBT-4 | C34: PRT001-13 | D34: CCM 3.1 - ÁREA 200 | O34: Disjuntor C.M. | P34: 273.02879 | Q34: =P34*0.746 -> 203.67948 | S34: =IF(O34="","",IF(O34="NA","",IF(O34="Mini disjuntor + DR",0.92,IF(O34="Mini disjuntor",0.92,IF(O34="Disjuntor Motor",0.92,IF(O34="Disjuntor C.M.",0.92,IF(O34="Disjuntor C.A.",0.92,IFERROR(VLOOKUP('Lista de Cargas'!P34,Motores!$B$9:$T$48,19,FALSE),"Erro")))))))) -> 0.92 | T34: =IF(O34="","",IF(O34="NA","",IF(O34="Mini disjuntor + DR",100%,IF(O34="Mini disjuntor",100%,IF(O34="Disjuntor Motor",0.92,IF(O34="Disjuntor C.M.",100%,IF(O34="Disjuntor C.A.",100%,IFERROR(VLOOKUP('Lista de Cargas'!P34,Motores!$B$9:$T$48,16,FALSE)/100,"Erro")))))))) -> 1 | U34: Trifásico | V34: 440 | W34: =IFERROR(IF(U34=$U$344,(P34*746)/(SQRT(3)*S34*T34*V34),(P34*746)/(S34*T34*V34)),0) -> 290.5 | X34: =IFERROR(Q34/S34,0) -> 221.39073 | Y34: =IFERROR(IF(O34=$O$344,6*W34,IF(O34=$O$345,6*W34,IF(O34=$O$346,3*W34,IF(O34=$O$347,1.5*W34,W34)))),0) -> 290.5 | AB34: 20 | AG34: =SUM(AB34:AF34) -> 20 | AH34: 3 | AI34: 95mm² - 0,6/1kV - PT - EPR - 90ºC - Cobre | AJ34: =$AG34*AH34*(1+$BJ$1) -> 60 | AK34: 0 | AL34: NA | AN34: 1 | AO34: 50mm² - 0,6/1kV - VD - EPR - 90ºC - Cobre | AP34: =$AG34*AN34*(1+$BJ$1) -> 20 | AQ34: NA | AS34: 1
A35: SE-03 | B35: QGBT-4 | C35: PRT001-14 | D35: CCM 3.2 - ÁREA 300 | O35: Disjuntor C.M. | P35: 1748.2301 | Q35: =P35*0.746 -> 1304.1797 | S35: =IF(O35="","",IF(O35="NA","",IF(O35="Mini disjuntor + DR",0.92,IF(O35="Mini disjuntor",0.92,IF(O35="Disjuntor Motor",0.92,IF(O35="Disjuntor C.M.",0.92,IF(O35="Disjuntor C.A.",0.92,IFERROR(VLOOKUP('Lista de Cargas'!P35,Motores!$B$9:$T$48,19,FALSE),"Erro")))))))) -> 0.92 | T35: =IF(O35="","",IF(O35="NA","",IF(O35="Mini disjuntor + DR",100%,IF(O35="Mini disjuntor",100%,IF(O35="Disjuntor Motor",0.92,IF(O35="Disjuntor C.M.",100%,IF(O35="Disjuntor C.A.",100%,IFERROR(VLOOKUP('Lista de Cargas'!P35,Motores!$B$9:$T$48,16,FALSE)/100,"Erro")))))))) -> 1 | U35: Trifásico | V35: 440 | W35: =IFERROR(IF(U35=$U$344,(P35*746)/(SQRT(3)*S35*T35*V35),(P35*746)/(S35*T35*V35)),0) -> 1860.1 | X35: =IFERROR(Q35/S35,0) -> 1417.5866 | Y35: =IFERROR(IF(O35=$O$344,6*W35,IF(O35=$O$345,6*W35,IF(O35=$O$346,3*W35,IF(O35=$O$347,1.5*W35,W35)))),0) -> 1860.1 | AB35: 20 | AG35: =SUM(AB35:AF35) -> 20 | AH35: 12 | AI35: 240mm² - 0,6/1kV - PT - EPR - 90ºC - Cobre | AJ35: =$AG35*AH35*(1+$BJ$1) -> 240 | AK35: 0 | AL35: NA | AN35: 2 | AO35: 240mm² - 0,6/1kV - VD - EPR - 90ºC - Cobre | AP35: =$AG35*AN35*(1+$BJ$1) -> 40 | AQ35: NA | AS35: 1
A36: SE-03 | B36: QGBT-4 | C36: PRT001-15 | D36: CCM 3.3 - ÁREA 700 | O36: Disjuntor C.M. | P36: 127.16281 | Q36: =P36*0.746 -> 94.863453 | S36: =IF(O36="","",IF(O36="NA","",IF(O36="Mini disjuntor + DR",0.92,IF(O36="Mini disjuntor",0.92,IF(O36="Disjuntor Motor",0.92,IF(O36="Disjuntor C.M.",0.92,IF(O36="Disjuntor C.A.",0.92,IFERROR(VLOOKUP('Lista de Cargas'!P36,Motores!$B$9:$T$48,19,FALSE),"Erro")))))))) -> 0.92 | T36: =IF(O36="","",IF(O36="NA","",IF(O36="Mini disjuntor + DR",100%,IF(O36="Mini disjuntor",100%,IF(O36="Disjuntor Motor",0.92,IF(O36="Disjuntor C.M.",100%,IF(O36="Disjuntor C.A.",100%,IFERROR(VLOOKUP('Lista de Cargas'!P36,Motores!$B$9:$T$48,16,FALSE)/100,"Erro")))))))) -> 1 | U36: Trifásico | V36: 440 | W36: =IFERROR(IF(U36=$U$344,(P36*746)/(SQRT(3)*S36*T36*V36),(P36*746)/(S36*T36*V36)),0) -> 135.3 | X36: =IFERROR(Q36/S36,0) -> 103.11245 | Y36: =IFERROR(IF(O36=$O$344,6*W36,IF(O36=$O$345,6*W36,IF(O36=$O$346,3*W36,IF(O36=$O$347,1.5*W36,W36)))),0) -> 135.3 | AB36: 20 | AG36: =SUM(AB36:AF36) -> 20 | AH36: 1 | AI36: PP 4 x 25mm² - 0,6/1kV - EPR - 90ºC - Cobre | AJ36: =$AG36*AH36*(1+$BJ$1) -> 20 | AK36: 0 | AL36: NA | AN36: 0 | AO36: NA | AP36: =$AG36*AN36*(1+$BJ$1) -> 0 | AQ36: NA | AS36: 1
A37: SE-03 | B37: QGBT-4 | C37: PRO-3001, 3002, 3003 | D37: PONTE ROLANTE | O37: Disjuntor C.M. | P37: 34.304822 | Q37: =P37*0.746 -> 25.591397 | S37: =IF(O37="","",IF(O37="NA","",IF(O37="Mini disjuntor + DR",0.92,IF(O37="Mini disjuntor",0.92,IF(O37="Disjuntor Motor",0.92,IF(O37="Disjuntor C.M.",0.92,IF(O37="Disjuntor C.A.",0.92,IFERROR(VLOOKUP('Lista de Cargas'!P37,Motores!$B$9:$T$48,19,FALSE),"Erro")))))))) -> 0.92 | T37: =IF(O37="","",IF(O37="NA","",IF(O37="Mini disjuntor + DR",100%,IF(O37="Mini disjuntor",100%,IF(O37="Disjuntor Motor",0.92,IF(O37="Disjuntor C.M.",100%,IF(O37="Disjuntor C.A.",100%,IFERROR(VLOOKUP('Lista de Cargas'!P37,Motores!$B$9:$T$48,16,FALSE)/100,"Erro")))))))) -> 1 | U37: Trifásico | V37: 440 | W37: =IFERROR(IF(U37=$U$344,(P37*746)/(SQRT(3)*S37*T37*V37),(P37*746)/(S37*T37*V37)),0) -> 36.5 | X37: =IFERROR(Q37/S37,0) -> 27.816736 | Y37: =IFERROR(IF(O37=$O$344,6*W37,IF(O37=$O$345,6*W37,IF(O37=$O$346,3*W37,IF(O37=$O$347,1.5*W37,W37)))),0) -> 36.5 | AB37: 100 | AG37: =SUM(AB37:AF37) -> 100 | AH37: 1 | AI37: PP 4 x 10mm² - 0,6/1kV - EPR - 90ºC - Cobre | AJ37: =$AG37*AH37*(1+$BJ$1) -> 100 | AK37: 0 | AL37: NA | AN37: 0 | AO37: NA | AP37: =$AG37*AN37*(1+$BJ$1) -> 0 | AQ37: NA | AS37: 1
... A47: SE-03 | B47: QGBT-5 | C47: PRT001-08 | D47: BANCO DE CAPACITORES QGBT-5 - TRANSFORMADOR N°5 | O47: Disjuntor C.M. | P47: 925.94823 | Q47: =P47*0.746 -> 690.75738 | S47: =IF(O47="","",IF(O47="NA","",IF(O47="Mini disjuntor + DR",0.92,IF(O47="Mini disjuntor",0.92,IF(O47="Disjuntor Motor",0.92,IF(O47="Disjuntor C.M.",0.92,IF(O47="Disjuntor C.A.",0.92,IFERROR(VLOOKUP('Lista de Cargas'!P47,Motores!$B$9:$T$48,19,FALSE),"Erro")))))))) -> 0.92 | T47: =IF(O47="","",IF(O47="NA","",IF(O47="Mini disjuntor + DR",100%,IF(O47="Mini disjuntor",100%,IF(O47="Disjuntor Motor",0.92,IF(O47="Disjuntor C.M.",100%,IF(O47="Disjuntor C.A.",100%,IFERROR(VLOOKUP('Lista de Cargas'!P47,Motores!$B$9:$T$48,16,FALSE)/100,"Erro")))))))) -> 1 | U47: Trifásico | V47: 440 | W47: =IFERROR(IF(U47=$U$344,(P47*746)/(SQRT(3)*S47*T47*V47),(P47*746)/(S47*T47*V47)),0) -> 985.2 | X47: =IFERROR(Q47/S47,0) -> 750.82324 | Y47: =IFERROR(IF(O47=$O$344,6*W47,IF(O47=$O$345,6*W47,IF(O47=$O$346,3*W47,IF(O47=$O$347,1.5*W47,W47)))),0) -> 985.2 | AB47: 20 | AG47: =SUM(AB47:AF47) -> 20 | AH47: 6 | AI47: 240mm² - 0,6/1kV - PT - EPR - 90ºC - Cobre | AJ47: =$AG47*AH47*(1+$BJ$1) -> 120 | AK47: 0 | AL47: NA | AN47: 1 | AO47: 240mm² - 0,6/1kV - VD - EPR - 90ºC - Cobre | AP47: =$AG47*AN47*(1+$BJ$1) -> 20 | AQ47: NA | AS47: 1
A48: 100 | B48: Moagem | C48: ECA-101 | D48: 084692 - ELEVADOR DE CANECA 16 POL 20 HP 22.500 MM ACO CARBONO | O48: Soft | P48: 20 | Q48: =P48*0.746 -> 14.92 | S48: =IF(O48="","",IF(O48="NA","",IF(O48="Mini disjuntor + DR",0.92,IF(O48="Mini disjuntor",0.92,IF(O48="Disjuntor Motor",0.92,IF(O48="Disjuntor C.M.",0.92,IF(O48="Disjuntor C.A.",0.92,IFERROR(VLOOKUP('Lista de Cargas'!P48,Motores!$B$9:$T$48,19,FALSE),"Erro")))))))) -> 0.81 | T48: =IF(O48="","",IF(O48="NA","",IF(O48="Mini disjuntor + DR",100%,IF(O48="Mini disjuntor",100%,IF(O48="Disjuntor Motor",0.92,IF(O48="Disjuntor C.M.",100%,IF(O48="Disjuntor C.A.",100%,IFERROR(VLOOKUP('Lista de Cargas'!P48,Motores!$B$9:$T$48,16,FALSE)/100,"Erro")))))))) -> 0.924 | U48: Trifásico | V48: 440 | W48: =IFERROR(IF(U48=$U$344,(P48*746)/(SQRT(3)*S48*T48*V48),(P48*746)/(S48*T48*V48)),0) -> 26.157638 | X48: =IFERROR(Q48/S48,0) -> 18.419753 | Y48: =IFERROR(IF(O48=$O$344,6*W48,IF(O48=$O$345,6*W48,IF(O48=$O$346,3*W48,IF(O48=$O$347,1.5*W48,W48)))),0) -> 78.472915 | AB48: 90 | AG48: =SUM(AB48:AF48) -> 90 | AH48: 1 | AI48: PP 4 x 6mm² - 0,6/1kV - EPR - 90ºC - Cobre | AJ48: =$AG48*AH48*(1+$BJ$1) -> 90 | AK48: 0 | AL48: NA | AM48: =$AG48*AK48*(1+$BJ$1) -> 0 | AN48: 0 | AO48: NA | AP48: =$AG48*AN48*(1+$BJ$1) -> 0 | AQ48: 132M/L | AR48: =IFERROR(VLOOKUP(AQ48,$O$368:$P$412,2,1),"NA") -> 1" | AS48: 1 | BF48: =IFERROR(IF(F48=$O$358,0,IF(S48>$BH$1,0,IF(O48=$O$347,0,SQRT((X48^2)-(Q48^2))-(SQRT(((Q48/$BH$1)^2)-(Q48^2)))))),0) -> 4.4460001
A49: 100 | B49: Moagem | C49: FCL-101 | D49: 036740 - FEED CLEANER 2.000MM C/ ACIONAMENTO POR REDUTOR | O49: Soft | P49: 15 | Q49: =P49*0.746 -> 11.19 | S49: =IF(O49="","",IF(O49="NA","",IF(O49="Mini disjuntor + DR",0.92,IF(O49="Mini disjuntor",0.92,IF(O49="Disjuntor Motor",0.92,IF(O49="Disjuntor C.M.",0.92,IF(O49="Disjuntor C.A.",0.92,IFERROR(VLOOKUP('Lista de Cargas'!P49,Motores!$B$9:$T$48,19,FALSE),"Erro")))))))) -> 0.85 | T49: =IF(O49="","",IF(O49="NA","",IF(O49="Mini disjuntor + DR",100%,IF(O49="Mini disjuntor",100%,IF(O49="Disjuntor Motor",0.92,IF(O49="Disjuntor C.M.",100%,IF(O49="Disjuntor C.A.",100%,IFERROR(VLOOKUP('Lista de Cargas'!P49,Motores!$B$9:$T$48,16,FALSE)/100,"Erro")))))))) -> 0.917 | U49: Trifásico | V49: 440 | W49: =IFERROR(IF(U49=$U$344,(P49*746)/(SQRT(3)*S49*T49*V49),(P49*746)/(S49*T49*V49)),0) -> 18.837728 | X49: =IFERROR(Q49/S49,0) -> 13.164706 | Y49: =IFERROR(IF(O49=$O$344,6*W49,IF(O49=$O$345,6*W49,IF(O49=$O$346,3*W49,IF(O49=$O$347,1.5*W49,W49)))),0) -> 56.513184 | AB49: 90 | AG49: =SUM(AB49:AF49) -> 90 | AH49: 1 | AI49: PP 4 x 4mm² - 0,6/1kV - EPR - 90ºC - Cobre | AJ49: =$AG49*AH49*(1+$BJ$1) -> 90 | AK49: 0 | AL49: NA | AM49: =$AG49*AK49*(1+$BJ$1) -> 0 | AN49: 0 | AO49: NA | AP49: =$AG49*AN49*(1+$BJ$1) -> 0 | AQ49: 100L | AR49: =IFERROR(VLOOKUP(AQ49,$O$368:$P$412,2,1),"NA") -> 3/4" | AS49: 1 | BF49: =IFERROR(IF(F49=$O$358,0,IF(S49>$BH$1,0,IF(O49=$O$347,0,SQRT((X49^2)-(Q49^2))-(SQRT(((Q49/$BH$1)^2)-(Q49^2)))))),0) -> 2.1680191
...

Sheet Motores
A1: dep
I2: Tempo máximo | R2: 220 V
E3: Corrente | L3: Nível médio
B4: Potência | D4: Conjugado | E4: com Rotor | F4: Conjugado | G4: Conjugado | H4: Momento de | I4: com rotor | K4: Massa | L4: de pressão | M4: Fator de | R4: % de Carga | U4: Corrente
C5: Carcaça | D5: Nominal | E5: Bloqueado | F5: de Partida | G5: Máximo | H5: Inércia J | I5: bloqueado (s) | K5: (kg) | L5: sonora | M5: Serviço | N5: RPM | P5: Rendimento | S5: Fator de Potência | U5: Nominal
D6: (kgfm) | F6: Cp/Cn | G6: Cmáx/Cn | H6: (kgm2)
A7: kW | B7: HP | E7: Ip/In | I7: Quente | J7: Frio | L7: dB(A) | O7: 50 | P7: 75 | Q7: 100 | R7: 50 | S7: 75 | T7: 100 | U7: In (A)
B8: IV polos - 1800 rpm - 60 Hz
A9: 0.12 | B9: 0.16 | C9: 63 | D9: 0.068 | E9: 4.6 | F9: 2.5 | G9: 3.2 | H9: 0.0004 | I9: 37 | J9: 81 | K9: 6.2 | L9: 48 | M9: 1.15 | N9: 1715 | O9: 50 | P9: 57 | Q9: 61 | R9: 0.44 | S9: 0.55 | T9: 0.64 | U9: 0.805
A10: 0.18 | B10: 0.25 | C10: 63 | D10: 0.103 | E10: 4.7 | F10: 2.4 | G10: 2.9 | H10: 0.0006 | I10: 29 | J10: 64 | K10: 7.2 | L10: 48 | M10: 1.15 | N10: 1705 | O10: 57 | P10: 64 | Q10: 67 | R10: 0.47 | S10: 0.59 | T10: 0.68 | U10: 1.03
A11: 0.25 | B11: 0.33 | C11: 63 | D11: 0.143 | E11: 5 | F11: 2.55 | G11: 2.95 | H11: 0.0007 | I11: 26 | J11: 57 | K11: 8.2 | L11: 48 | M11: 1.15 | N11: 1705 | O11: 62 | P11: 68 | Q11: 70 | R11: 0.47 | S11: 0.6 | T11: 0.69 | U11: 1.35
A12: 0.37 | B12: 0.5 | C12: 71 | D12: 0.213 | E12: 5 | F12: 2.2 | G12: 2.3 | H12: 0.0007 | I12: 20 | J12: 44 | K12: 8 | L12: 47 | M12: 1.15 | N12: 1690 | O12: 63 | P12: 68 | Q12: 70 | R12: 0.45 | S12: 0.59 | T12: 0.69 | U12: 2
A13: 0.55 | B13: 0.75 | C13: 71 | D13: 0.317 | E13: 5.3 | F13: 2.5 | G13: 2.5 | H13: 0.0008 | I13: 14 | J13: 31 | K13: 11.5 | L13: 47 | M13: 1.15 | N13: 1690 | O13: 67 | P13: 71 | Q13: 72 | R13: 0.44 | S13: 0.56 | T13: 0.66 | U13: 2.95
A14: 0.75 | B14: 1 | C14: 80 | D14: 0.422 | E14: 6.6 | F14: 2.4 | G14: 2.8 | H14: 0.0032 | I14: 8 | J14: 18 | K14: 12.5 | L14: 48 | M14: 1.15 | N14: 1730 | O14: 75.5 | P14: 79 | Q14: 80.5 | R14: 0.57 | S14: 0.71 | T14: 0.81 | U14: 3.02
A15: 1.1 | B15: 1.5 | C15: 80 | D15: 0.625 | E15: 6.8 | F15: 3.15 | G15: 3 | H15: 0.0032 | I15: 11 | J15: 24 | K15: 14.5 | L15: 48 | M15: 1.15 | N15: 1715 | O15: 78 | P15: 81 | Q15: 81.6 | R15: 0.58 | S15: 0.71 | T15: 0.79 | U15: 4.48
A16: 1.5 | B16: 2 | C16: 90S | D16: 0.835 | E16: 7.1 | F16: 2.2 | G16: 3 | H16: 0.0049 | I16: 11 | J16: 24 | K16: 18.5 | L16: 51 | M16: 1.15 | N16: 1750 | O16: 81 | P16: 83.5 | Q16: 84.2 | R16: 0.57 | S16: 0.7 | T16: 0.78 | U16: 5.98
A17: 2.2 | B17: 3 | C17: 90L | D17: 1.24 | E17: 6.5 | F17: 1.95 | G17: 2.5 | H17: 0.0063 | I17: 10 | J17: 22 | K17: 23 | L17: 51 | M17: 1.15 | N17: 1735 | O17: 83.8 | P17: 84.8 | Q17: 85.1 | R17: 0.64 | S17: 0.76 | T17: 0.83 | U17: 8.18
A18: 3 | B18: 4 | C18: 100L | D18: 1.7 | E18: 6.4 | F18: 2.7 | G18: 2.9 | H18: 0.0105 | I18: 8 | J18: 18 | K18: 30 | L18: 54 | M18: 1.15 | N18: 1715 | O18: 85.6 | P18: 86.3 | Q18: 86.5 | R18: 0.63 | S18: 0.75 | T18: 0.82 | U18: 11.1
A19: 3.7 | B19: 5 | C19: 100L | D19: 2.08 | E19: 8 | F19: 3 | G19: 3.6 | H19: 0.0097 | I19: 11 | J19: 24 | K19: 34 | L19: 54 | M19: 1.15 | N19: 1735 | O19: 85 | P19: 87 | Q19: 88 | R19: 0.59 | S19: 0.72 | T19: 0.8 | U19: 13.7
A20: 4.5 | B20: 6 | C20: 112M | D20: 2.52 | E20: 6.2 | F20: 2.1 | G20: 2.75 | H20: 0.018 | I20: 18 | J20: 40 | K20: 42 | L20: 56 | M20: 1.15 | N20: 1740 | O20: 88 | P20: 88.5 | Q20: 88.5 | R20: 0.62 | S20: 0.74 | T20: 0.81 | U20: 16.6
A21: 5.5 | B21: 7.5 | C21: 112M | D21: 3.08 | E21: 6.3 | F21: 2.1 | G21: 2.7 | H21: 0.018 | I21: 16 | J21: 35 | K21: 44 | L21: 56 | M21: 1.15 | N21: 1740 | O21: 88.4 | P21: 89.1 | Q21: 90 | R21: 0.59 | S21: 0.72 | T21: 0.79 | U21: 20.2
A22: 7.5 | B22: 10 | C22: 132S | D22: 4.15 | E22: 7.9 | F22: 2 | G22: 3.2 | H22: 0.0489 | I22: 12 | J22: 26 | K22: 68 | L22: 58 | M22: 1.15 | N22: 1760 | O22: 90 | P22: 90.8 | Q22: 91 | R22: 0.66 | S22: 0.78 | T22: 0.84 | U22: 25.8
A23: 9.2 | B23: 12.5 | C23: 132M | D23: 5.09 | E23: 8 | F23: 2.05 | G23: 3.1 | H23: 0.0563 | I23: 10 | J23: 22 | K23: 75 | L23: 58 | M23: 1.15 | N23: 1760 | O23: 90 | P23: 90.8 | Q23: 91 | R23: 0.67 | S23: 0.79 | T23: 0.84 | U23: 31.4
A24: 11 | B24: 15 | C24: 132M/L | D24: 6.09 | E24: 8.2 | F24: 2.15 | G24: 3.2 | H24: 0.0638 | I24: 8 | J24: 18 | K24: 78 | L24: 58 | M24: 1.15 | N24: 1760 | O24: 90.5 | P24: 91.2 | Q24: 91.7 | R24: 0.67 | S24: 0.79 | T24: 0.85 | U24: 37.2
A25: 15 | B25: 20 | C25: 160M | D25: 8.23 | E25: 6.8 | F25: 2.7 | G25: 3 | H25: 0.1188 | I25: 11 | J25: 24 | K25: 120 | L25: 64 | M25: 1.15 | N25: 1775 | O25: 91 | P25: 92.4 | Q25: 92.4 | R25: 0.64 | S25: 0.75 | T25: 0.81 | U25: 52.6
A26: 18.5 | B26: 25 | C26: 160L | D26: 10.2 | E26: 6.8 | F26: 2.7 | G26: 3 | H26: 0.1397 | I26: 10 | J26: 22 | K26: 135 | L26: 64 | M26: 1.15 | N26: 1765 | O26: 92 | P26: 92.8 | Q26: 92.8 | R26: 0.64 | S26: 0.75 | T26: 0.81 | U26: 64.6
A27: 22 | B27: 30 | C27: 180M | D27: 12.1 | E27: 6.4 | F27: 2.3 | G27: 2.7 | H27: 0.1657 | I27: 19 | J27: 42 | K27: 168 | L27: 64 | M27: 1.15 | N27: 1765 | O27: 92.5 | P27: 92.8 | Q27: 93 | R27: 0.71 | S27: 0.81 | T27: 0.84 | U27: 74
... A48: 550 | B48: 750 | C48: 355A/B | D48: 299 | E48: 7.6 | F48: 2.7 | G48: 2.7 | H48: 14.6 | I48: 22 | J48: 48 | K48: 2246 | L48: 81 | M48: 1 | N48: 1790 | O48: 96.3 | P48: 96.6 | Q48: 96.7 | R48: 0.7 | S48: 0.8 | T48: 0.85 | U48: 1760

Sheet Cabos
J1: ELETROD,CONECTOR E SEAL TUBO | M1: TERMINAIS FASE | R1: TERMINAIS TERRA | W1: TERMINAIS TOTAL
A2: Rótulos de Linha | B2: Soma de Total Cabos Fase (m) | D2: Rótulos de Linha | E2: Soma de Total Cabos Neutro (m) | G2: Rótulos de Linha | H2: Soma de Total Cabos Terra (m) | J2: Rótulos de Linha | K2: Soma de QTDE | M2: Rótulos de Linha | N2: Soma de Nº Cabos Fase | O2: BITOLA | P2: TOTAL | R2: Rótulos de Linha | S2: Soma de Nº Cabos Terra PE/PEN | T2: BITOLA | U2: TOTAL | W2: Rótulos de Linha | X2: Soma de TOTAL
A3: (vazio) | B3: 0 | D3: (vazio) | E3: 0 | G3: (vazio) | H3: 0 | J3: 1" | K3: 68 | M3: 120mm² - 0,6/1kV - PT - EPR - 90ºC - Cobre | N3: 27 | O3: 120mm² | P3: =N3*2 -> 54 | R3: 120mm² - 0,6/1kV - VD - EPR - 90ºC - Cobre | S3: 8 | T3: 120mm² | U3: =$S$3*2 -> 16 | W3: 10mm² | X3: 304
A4: 240mm² - 0,6/1kV - PT - EPR - 90ºC - Cobre | B4: 3420 | D4: NA | E4: 0 | G4: 240mm² - 0,6/1kV - VD - EPR - 90ºC - Cobre | H4: 2980 | J4: 1.1/2" | K4: 41 | M4: 150mm² - 0,6/1kV - PT - EPR - 90ºC - Cobre | N4: 6 | O4: 150mm² | P4: =N4*2 -> 12 | R4: 150mm² - 0,6/1kV - VD - EPR - 90ºC - Cobre | S4: 6 | T4: 150mm² | U4: =$S$4*2 -> 12 | W4: 120mm² | X4: 70
A5: 185mm² - 0,6/1kV - PT - EPR - 90ºC - Cobre | B5: 300 | D5: Total Geral | E5: 0 | G5: 120mm² - 0,6/1kV - VD - EPR - 90ºC - Cobre | H5: 570 | J5: 2 x 3" | K5: 9 | M5: 185mm² - 0,6/1kV - PT - EPR - 90ºC - Cobre | N5: 15 | O5: 185mm² | P5: =N5*2 -> 30 | R5: 185mm² - 0,6/1kV - VD - EPR - 90ºC - Cobre | S5: 1 | T5: 185mm² | U5: =$S$5*2 -> 2 | W5: 150mm² | X5: 24
A6: 70mm² - 0,6/1kV - PT - EPR - 90ºC - Cobre | B6: 5520 | G6: 185mm² - 0,6/1kV - VD - EPR - 90ºC - Cobre | H6: 20 | J6: 2" | K6: 36 | M6: 240mm² - 0,6/1kV - PT - EPR - 90ºC - Cobre | N6: 171 | O6: 240mm² | P6: =N6*2 -> 342 | R6: 240mm² - 0,6/1kV - VD - EPR - 90ºC - Cobre | S6: 33 | T6: 240mm² | U6: =$S$6*2 -> 66 | W6: 16mm² | X6: 248
A7: PP 4 x 2,5mm² - 0,6/1kV - EPR - 90ºC - Cobre | B7: 8080 | G7: 150mm² - 0,6/1kV - VD - EPR - 90ºC - Cobre | H7: 120 | J7: 3/4" | K7: 128 | M7: 35mm² - 0,6/1kV - PT - EPR - 90ºC - Cobre | N7: 15 | O7: 35mm² | P7: =N7*2 -> 30 | R7: 25mm² - 0,6/1kV - VD - EPR - 90ºC - Cobre | S7: 12 | T7: 25mm² | U7: =$S$7*2 -> 24 | W7: 185mm² | X7: 32
A8: 95mm² - 0,6/1kV - PT - EPR - 90ºC - Cobre | B8: 120 | G8: 35mm² - 0,6/1kV - VD - EPR - 90ºC - Cobre | H8: 1840 | J8: NA | K8: 5 | M8: 50mm² - 0,6/1kV - PT - EPR - 90ºC - Cobre | N8: 21 | O8: 50mm² | P8: =N8*2 -> 42 | R8: 35mm² - 0,6/1kV - VD - EPR - 90ºC - Cobre | S8: 20 | T8: 35mm² | U8: =$S$8*2 -> 40 | W8: 2,5-4mm² | X8: 916
A9: PP 4 x 10mm² - 0,6/1kV - EPR - 90ºC - Cobre | B9: 4180 | G9: NA | H9: 0 | J9: (vazio) | K9: 46 | M9: 70 mm² - 15/25KV - EPR 105°C | N9: 27 | O9: 70mm² | P9: =N9*2 -> 54 | R9: 50mm² - 0,6/1kV - VD - EPR - 90ºC - Cobre | S9: 2 | T9: 50mm² | U9: =$S$9*2 -> 4 | W9: 240mm² | X9: 408
