Workbook
Name ASI_REDE: '[3]Calc Eng'!$H$27
Name Atendentes_Instr_Campo_QT: '[3]Calc Eng'!$B$53
Name Atendentes_Senior_QT: '[3]Calc Eng'!$B$51
Name Atendentes_Sistema_Processo_QT: '[3]Calc Eng'!$B$52
Name Atendentes_Total: '[3]Calc Eng'!$B$28
Name ATK_LOG: '[3]Resumo_Custos ATK '!$B$10
Name ATK_MOA: '[3]Resumo_Custos ATK '!$B$3
Name ATK_MOB: '[3]Resumo_Custos ATK '!$B$9
Name ATK_MOD: '[3]Resumo_Custos ATK '!$B$5
Name ATK_MOI: '[3]Resumo_Custos ATK '!$B$4
Name ATK_SSMA: '[3]Resumo_Custos ATK '!$B$8
Name ATK_ST: '[3]Resumo_Custos ATK '!$B$6
Name ATK_TURNOVER: '[3]Resumo_Custos ATK '!$B$7
Name C_ADM_Geral: 0.1
Name Cidade: '[3]Calc Eng'!$H$79
Name Conteiner_Aluguel_Mes: '[3]Calc Eng'!$B$44
Name CSLL: [3]Impostos_Taxas!$H$28
Name CTNER: '[3]Calc Eng'!$H$21
Name Custo_Impostos_Credito__Débito: [3]Retorno!$K$31
Name Custo_Total: [3]Retorno!$C$43
Name Diária_Casa_Custo_Atendente: '[3]Calc Eng'!$B$3
Name Diária_Casa_Geral: '[3]Calc Eng'!$B$4
Name Diária_Completa_Sem_Transporte: '[3]Calc Eng'!$B$42
Name Diárias_Hotel_Avulsas_Custo: '[3]Calc Eng'!$B$5
Name Diárias_Hotel_Negociada_Custo: '[3]Calc Eng'!$B$6
Name Dias_Campo: '[3]Calc Eng'!$B$33
Name Distância_Base_PLANTA: '[3]Calc Eng'!$B$38
Name Distância_STZ_BASE: '[3]Calc Eng'!$B$37
Name Domingo_H: '[3]Calc Eng'!$B$61
Name Duração_Comissionamento__Startup: '[3]Calc Eng'!$B$43
Name Duração_da_Obra_Efetiva_Em_Meses: '[3]Calc Eng'!$I$101
Name Duração_Obra_Mês: '[3]Calc Eng'!$B$32
Name EA_E_PA: '[3]Calc Eng'!$H$24
Name ED_SD: '[3]Calc Eng'!$H$26
Name Equipe_Numero: '[3]Calc Eng'!$B$34
Name Estado: '[3]Calc Eng'!$J$79
Name Fator_Venda: [3]Retorno!$C$34
Name Frete_KM: '[3]Calc Eng'!$B$18
Name HH_Extra_DIA: '[3]Calc Eng'!$B$63
Name HH_Total_Eng_Interna: '[3]Calc Eng'!$O$56
Name HH_Total_Startup: '[3]Calc Eng'!$M$61
Name Horas_Comissionamento_Startup: '[3]Calc Eng'!$B$48
Name Horas_extras: '[3]Calc Eng'!$L$90
Name Horas_Instr_Startup: '[3]Calc Eng'!$B$50
Name Horas_Normais_Mês: '[3]Calc Eng'!$B$62
Name Horas_Preposto: '[3]Calc Eng'!$L$52
Name Horas_Senior_Startup: '[3]Calc Eng'!$B$49
Name Horas_Sistema_Proj_Startup: '[3]Calc Eng'!$B$54
Name Horas_Trabalho_Média: '[3]Calc Eng'!$B$29
Name IHM: '[3]Calc Eng'!$H$31
Name IRPJ: [3]Impostos_Taxas!$H$27
Name JBs_Total: '[3]Calc Eng'!$B$25
Name KM: '[3]Calc Eng'!$B$8
Name KM_HH_D_REF: '[3]Calc Eng'!$B$9
Name LOG: '[3]Calc Eng'!$H$9
Name LOG_HH_Médio_Obra: '[3]Calc Eng'!$DA$128
Name Log_In_MOI_Custo_HH: '[3]Custos de HH_LOG'!$K$20
Name LOG_Mão_Obra_Indireta: '[3]Calc Eng'!$Q$44
Name lOG_MOB_COFINS_LP: [3]Impostos_Taxas!$K$25
Name lOG_MOB_ISSQN_LR_LP: [3]Impostos_Taxas!$H$26

Sheet Custo_MI_Device
H1: MI Total | I1: =Insumos_Device!O1+Custo_MI_Infra!L1 -> 248547.71
A2: ISA | B2: TIPO | C2: CUSTO UNITARIO | D2: QUANT | E2: CUSTO TOTAL | F2: =SUBTOTAL(9,E:E) -> 249760.61
A3: AIT | B3: AIT Hart - 2 Fios - Tanque | C3: =SUMIFS(Insumos_Device!K:K,Insumos_Device!B:B,A3,Insumos_Device!C:C,B3) -> 284.933 | E3: =Custo_MI_Device!$C3*Custo_MI_Device!$D3 -> 0
A4: AIT | B4: AIT Hart - 2 Fios - Tubul. | C4: =SUMIFS(Insumos_Device!K:K,Insumos_Device!B:B,A4,Insumos_Device!C:C,B4) -> 375.333 | E4: =Custo_MI_Device!$C4*Custo_MI_Device!$D4 -> 0
A5: AIT | B5: AIT Hart - 4 Fios - Tanque | C5: =SUMIFS(Insumos_Device!K:K,Insumos_Device!B:B,A5,Insumos_Device!C:C,B5) -> 284.933 | E5: =Custo_MI_Device!$C5*Custo_MI_Device!$D5 -> 0
A6: AIT | B6: AIT Hart - 4 Fios - Tubul. | C6: =SUMIFS(Insumos_Device!K:K,Insumos_Device!B:B,A6,Insumos_Device!C:C,B6) -> 770.3 | D6: 11 | E6: =Custo_MI_Device!$C6*Custo_MI_Device!$D6 -> 8473.3
A7: AIT | B7: AIT PA - 4 Fios - Tanque | C7: =SUMIFS(Insumos_Device!K:K,Insumos_Device!B:B,A7,Insumos_Device!C:C,B7) -> 521.433 | E7: =Custo_MI_Device!$C7*Custo_MI_Device!$D7 -> 0
A8: AIT | B8: AIT PA - 4 Fios - Tubul. | C8: =SUMIFS(Insumos_Device!K:K,Insumos_Device!B:B,A8,Insumos_Device!C:C,B8) -> 611.833 | E8: =Custo_MI_Device!$C8*Custo_MI_Device!$D8 -> 0
A9: XV | B9: Atuador Damper Hart | C9: =SUMIFS(Insumos_Device!K:K,Insumos_Device!B:B,A9,Insumos_Device!C:C,B9) -> 447.533 | E9: =Custo_MI_Device!$C9*Custo_MI_Device!$D9 -> 0
A10: XV | B10: Atuador Damper PA | C10: =SUMIFS(Insumos_Device!K:K,Insumos_Device!B:B,A10,Insumos_Device!C:C,B10) -> 475.033 | E10: =Custo_MI_Device!$C10*Custo_MI_Device!$D10 -> 0
A11: LSLL | B11: Chave Nivel - Caldeira | C11: =SUMIFS(Insumos_Device!K:K,Insumos_Device!B:B,A11,Insumos_Device!C:C,B11) -> 358.333 | E11: =Custo_MI_Device!$C11*Custo_MI_Device!$D11 -> 0
A12: FIT | B12: FIT Diferencial Água - Hart | C12: =SUMIFS(Insumos_Device!K:K,Insumos_Device!B:B,A12,Insumos_Device!C:C,B12) -> 1488.483 | E12: =Custo_MI_Device!$C12*Custo_MI_Device!$D12 -> 0
A13: FIT | B13: FIT Diferencial Água - PA | C13: =SUMIFS(Insumos_Device!K:K,Insumos_Device!B:B,A13,Insumos_Device!C:C,B13) -> 1515.983 | E13: =Custo_MI_Device!$C13*Custo_MI_Device!$D13 -> 0
A14: FIT | B14: FIT Diferencial Água Exd - Hart | C14: =SUMIFS(Insumos_Device!K:K,Insumos_Device!B:B,A14,Insumos_Device!C:C,B14) -> 1627.848 | E14: =Custo_MI_Device!$C14*Custo_MI_Device!$D14 -> 0
A15: FIT | B15: FIT Diferencial Água Exd - PA | C15: =SUMIFS(Insumos_Device!K:K,Insumos_Device!B:B,A15,Insumos_Device!C:C,B15) -> 1740.348 | E15: =Custo_MI_Device!$C15*Custo_MI_Device!$D15 -> 0
A16: FIT | B16: FIT Magnético Integral - Hart | C16: =SUMIFS(Insumos_Device!K:K,Insumos_Device!B:B,A16,Insumos_Device!C:C,B16) -> 129.083 | E16: =Custo_MI_Device!$C16*Custo_MI_Device!$D16 -> 0
A17: FIT | B17: FIT Magnético Integral - PA | C17: =SUMIFS(Insumos_Device!K:K,Insumos_Device!B:B,A17,Insumos_Device!C:C,B17) -> 241.583 | E17: =Custo_MI_Device!$C17*Custo_MI_Device!$D17 -> 0
A18: FIT | B18: FIT Magnético Integral Exd- Hart | C18: =SUMIFS(Insumos_Device!K:K,Insumos_Device!B:B,A18,Insumos_Device!C:C,B18) -> 376.448 | E18: =Custo_MI_Device!$C18*Custo_MI_Device!$D18 -> 0
A19: FIT | B19: FIT Magnético Integral Exd- PA | C19: =SUMIFS(Insumos_Device!K:K,Insumos_Device!B:B,A19,Insumos_Device!C:C,B19) -> 488.948 | E19: =Custo_MI_Device!$C19*Custo_MI_Device!$D19 -> 0
A20: FIT | B20: FIT Magnético Remoto - Hart | C20: =SUMIFS(Insumos_Device!K:K,Insumos_Device!B:B,A20,Insumos_Device!C:C,B20) -> 206.39 | D20: 41 | E20: =Custo_MI_Device!$C20*Custo_MI_Device!$D20 -> 8461.99
A21: FIT | B21: FIT Magnético Remoto - PA | C21: =SUMIFS(Insumos_Device!K:K,Insumos_Device!B:B,A21,Insumos_Device!C:C,B21) -> 365.583 | E21: =Custo_MI_Device!$C21*Custo_MI_Device!$D21 -> 0
A22: FIT | B22: FIT Magnético Remoto Exd- Hart | C22: =SUMIFS(Insumos_Device!K:K,Insumos_Device!B:B,A22,Insumos_Device!C:C,B22) -> 500.448 | E22: =Custo_MI_Device!$C22*Custo_MI_Device!$D22 -> 0
A23: FIT | B23: FIT Magnético Remoto Exd- PA | C23: =SUMIFS(Insumos_Device!K:K,Insumos_Device!B:B,A23,Insumos_Device!C:C,B23) -> 612.948 | E23: =Custo_MI_Device!$C23*Custo_MI_Device!$D23 -> 0
A24: FIT | B24: FIT Vapor F11 - Hart | C24: =SUMIFS(Insumos_Device!K:K,Insumos_Device!B:B,A24,Insumos_Device!C:C,B24) -> 2219.59 | D24: 3 | E24: =Custo_MI_Device!$C24*Custo_MI_Device!$D24 -> 6658.77
A25: FIT | B25: FIT Vapor F11 - PA | C25: =SUMIFS(Insumos_Device!K:K,Insumos_Device!B:B,A25,Insumos_Device!C:C,B25) -> 1361.783 | E25: =Custo_MI_Device!$C25*Custo_MI_Device!$D25 -> 0
A26: FIT | B26: FIT Vapor P22 - Hart | C26: =SUMIFS(Insumos_Device!K:K,Insumos_Device!B:B,A26,Insumos_Device!C:C,B26) -> 1334.283 | E26: =Custo_MI_Device!$C26*Custo_MI_Device!$D26 -> 0
A27: FIT | B27: FIT Vapor P22 - PA | C27: =SUMIFS(Insumos_Device!K:K,Insumos_Device!B:B,A27,Insumos_Device!C:C,B27) -> 1361.783 | E27: =Custo_MI_Device!$C27*Custo_MI_Device!$D27 -> 0
A28: GTW | B28: Gateway DP/AS-i | C28: =SUMIFS(Insumos_Device!K:K,Insumos_Device!B:B,A28,Insumos_Device!C:C,B28) -> 2158.313 | E28: =Custo_MI_Device!$C28*Custo_MI_Device!$D28 -> 0
A29: GTW | B29: Gateway DP/PA | C29: =SUMIFS(Insumos_Device!K:K,Insumos_Device!B:B,A29,Insumos_Device!C:C,B29) -> 2158.313 | E29: =Custo_MI_Device!$C29*Custo_MI_Device!$D29 -> 0
A30: JB | B30: Juncion Box - I/O Fisico | C30: =SUMIFS(Insumos_Device!K:K,Insumos_Device!B:B,A30,Insumos_Device!C:C,B30) -> 1349.138 | E30: =Custo_MI_Device!$C30*Custo_MI_Device!$D30 -> 0
A31: JB | B31: Juncion Box - PA | C31: =SUMIFS(Insumos_Device!K:K,Insumos_Device!B:B,A31,Insumos_Device!C:C,B31) -> 656.638 | E31: =Custo_MI_Device!$C31*Custo_MI_Device!$D31 -> 0
A32: LIT | B32: LIT Desaerador - Hart | C32: =SUMIFS(Insumos_Device!K:K,Insumos_Device!B:B,A32,Insumos_Device!C:C,B32) -> 1268.583 | E32: =Custo_MI_Device!$C32*Custo_MI_Device!$D32 -> 0
A33: LIT | B33: LIT Desaerador - PA | C33: =SUMIFS(Insumos_Device!K:K,Insumos_Device!B:B,A33,Insumos_Device!C:C,B33) -> 1296.083 | E33: =Custo_MI_Device!$C33*Custo_MI_Device!$D33 -> 0
A34: LIT | B34: LIT Diferencial - Hart | C34: =SUMIFS(Insumos_Device!K:K,Insumos_Device!B:B,A34,Insumos_Device!C:C,B34) -> 1647.283 | E34: =Custo_MI_Device!$C34*Custo_MI_Device!$D34 -> 0
A35: LIT | B35: LIT Diferencial - PA | C35: =SUMIFS(Insumos_Device!K:K,Insumos_Device!B:B,A35,Insumos_Device!C:C,B35) -> 1674.783 | E35: =Custo_MI_Device!$C35*Custo_MI_Device!$D35 -> 0
A36: LIT | B36: LIT Diferencial Exd - Hart | C36: =SUMIFS(Insumos_Device!K:K,Insumos_Device!B:B,A36,Insumos_Device!C:C,B36) -> 1871.648 | E36: =Custo_MI_Device!$C36*Custo_MI_Device!$D36 -> 0
... A41: LIT | B41: LIT Flang. Tq. Aberto - PA | C41: =SUMIFS(Insumos_Device!K:K,Insumos_Device!B:B,A41,Insumos_Device!C:C,B41) -> 244.883 | E41: =Custo_MI_Device!$C41*Custo_MI_Device!$D41 -> 0
A42: LIT | B42: LIT Flang. Tq. Fechado - Hart | C42: =SUMIFS(Insumos_Device!K:K,Insumos_Device!B:B,A42,Insumos_Device!C:C,B42) -> 2507.64 | D42: 41 | E42: =Custo_MI_Device!$C42*Custo_MI_Device!$D42 -> 102813.24
A43: LIT | B43: LIT Flang. Tq. Fechado - PA | C43: =SUMIFS(Insumos_Device!K:K,Insumos_Device!B:B,A43,Insumos_Device!C:C,B43) -> 1381.383 | E43: =Custo_MI_Device!$C43*Custo_MI_Device!$D43 -> 0
A44: LIT | B44: LIT Flang. Tq. Fechado Exd - Hart | C44: =SUMIFS(Insumos_Device!K:K,Insumos_Device!B:B,A44,Insumos_Device!C:C,B44) -> 1493.248 | E44: =Custo_MI_Device!$C44*Custo_MI_Device!$D44 -> 0
...

Sheet Insumos_Device
J1: VL PROTHEUS | O1: =SUM(O3:O1854) -> 248547.71
A2: CÓDIGO AUT | B2: ISA | C2: TIPO | D2: NCM | E2: DESCRIÇÃO DOS MATERIAIS | F2: MODELO | G2: QTDE | H2: UNID | I2: FABRICANTE | J2: VALOR UNITARIO R$ | K2: VALOR TOTAL R$ | L2: CÓDIGO NOTA | M2: QTD DEVICE | N2: QTDE | O2: CUSTO TOTAL
A3: 2566 | B3: AIT | C3: AIT Hart - 2 Fios - Tanque | D3: 73072900 | E3: ABRACADEIRA VERGALHAO GRAMPO U ZC 2 X 1/4 DP 634-6 DISPAN | F3: DP 634-6 | G3: 2 | H3: PC | I3: DISPAN | J3: 2.8 | K3: =G3*J3 -> 5.6 | L3: DP 634-6 | M3: =IFERROR(VLOOKUP(C3,Custo_MI_Device!$B$2:$E$102,3,FALSE),0) -> 0 | N3: =ROUNDUP(M3*G3,0) -> 0 | O3: =N3*J3 -> 0
A4: 2534 | B4: AIT | C4: AIT Hart - 2 Fios - Tanque | D4: 73072900 | E4: ABRACADEIRA VERGALHAO GRAMPO U ZC 3/4 X 1/4 DP 634-2 DISPAN | F4: DP 634-2 | G4: 12 | H4: PC | I4: DISPAN | J4: 1.2 | K4: =G4*J4 -> 14.4 | L4: DP 634-2 | M4: =IFERROR(VLOOKUP(C4,Custo_MI_Device!$B$2:$E$102,3,FALSE),0) -> 0 | N4: =ROUNDUP(M4*G4,0) -> 0 | O4: =N4*J4 -> 0
A5: 1669 | B5: AIT | C5: AIT Hart - 2 Fios - Tanque | D5: 39269090 | E5: ABRACADEIRA, NYLON PRETA, 2,5 X 101MM, T-18 R, HELLERMANN | F5: T-18 R | G5: 3 | H5: PC | I5: HELLERMANN | J5: 0.04 | K5: =G5*J5 -> 0.12 | L5: T-18 R | M5: =IFERROR(VLOOKUP(C5,Custo_MI_Device!$B$2:$E$102,3,FALSE),0) -> 0 | N5: =ROUNDUP(M5*G5,0) -> 0 | O5: =N5*J5 -> 0
A6: 5091 | B6: AIT | C6: AIT Hart - 2 Fios - Tanque | D6: 73181500 | E6: ARRUELA LISA ZC 1/4" | F6: DP 619 | G6: 28 | H6: PC | I6: DISPAN | J6: 0.04 | K6: =G6*J6 -> 1.12 | L6: DP 619 | M6: =IFERROR(VLOOKUP(C6,Custo_MI_Device!$B$2:$E$102,3,FALSE),0) -> 0 | N6: =ROUNDUP(M6*G6,0) -> 0 | O6: =N6*J6 -> 0
A7: 1117 | B7: AIT | C7: AIT Hart - 2 Fios - Tanque | E7: BUCHA REDUCAO, ALUMINIO, 3/4 X 1/2 BSP | F7: BRR 034 X 012 | G7: 1 | H7: PC | I7: DAISA | J7: 1.95 | K7: =G7*J7 -> 1.95 | L7: BRR 034 X 012 | M7: =IFERROR(VLOOKUP(C7,Custo_MI_Device!$B$2:$E$102,3,FALSE),0) -> 0 | N7: =ROUNDUP(M7*G7,0) -> 0 | O7: =N7*J7 -> 0
A8: 3585 | B8: AIT | C8: AIT Hart - 2 Fios - Tanque | D8: 85444900 | E8: CABO INSTRUMENTACAO BF, ISOL PVC/E 105øC, NBR 10300, C/ BLIND.ELETROST.COLETIVA FIO DRENO 1X2X0,75MMý 900400 ENERGIFLEX | F8: 900400 | G8: 0 | H8: M | I8: ENERGIFLEX | J8: 1.7 | K8: =G8*J8 -> 0 | L8: 900400 | M8: =IFERROR(VLOOKUP(C8,Custo_MI_Device!$B$2:$E$102,3,FALSE),0) -> 0 | N8: =ROUNDUP(M8*G8,0) -> 0 | O8: =N8*J8 -> 0
A9: 2805 | B9: AIT | C9: AIT Hart - 2 Fios - Tanque | D9: 72162100 | E9: CANTONEIRA, ACO A36, ABAS IGUAIS, 1.1/2 X 1/4 X 6.000MM, GERDAU | F9: 0 | G9: 2.9 | H9: KG | I9: GERDAU | J9: 4.22 | K9: =G9*J9 -> 12.238 | L9: AUT-2805 | M9: =IFERROR(VLOOKUP(C9,Custo_MI_Device!$B$2:$E$102,3,FALSE),0) -> 0 | N9: =ROUNDUP(M9*G9,0) -> 0 | O9: =N9*J9 -> 0
A10: 4823 | B10: AIT | C10: AIT Hart - 2 Fios - Tanque | D10: 76090000 | E10: CONDULETE ROSCÁVEL EM ALUMÍNIO C/ TAMPA 3/4"BSP TIPO "LR" | F10: DVRT 034-BSP-LR | G10: 0.75 | H10: PC | I10: DAISA | J10: 6.7 | K10: =G10*J10 -> 5.025 | L10: DVRT 034-BSP-LR | M10: =IFERROR(VLOOKUP(C10,Custo_MI_Device!$B$2:$E$102,3,FALSE),0) -> 0 | N10: =ROUNDUP(M10*G10,0) -> 0 | O10: =N10*J10 -> 0
A11: 2912 | B11: AIT | C11: AIT Hart - 2 Fios - Tanque | D11: 76090000 | E11: CONDULETE ROSCÁVEL EM ALUMÍNIO C/ TAMPA 3/4"BSP TIPO "T" | F11: DIIRT 034-BSP-T | G11: 1 | H11: PC | I11: DAISA | J11: 7.5 | K11: =G11*J11 -> 7.5 | L11: DIIRT 034-BSP-T | M11: =IFERROR(VLOOKUP(C11,Custo_MI_Device!$B$2:$E$102,3,FALSE),0) -> 0 | N11: =ROUNDUP(M11*G11,0) -> 0 | O11: =N11*J11 -> 0
A12: 3436 | B12: AIT | C12: AIT Hart - 2 Fios - Tanque | D12: 76090000 | E12: CONDULETE ROSCAVEL EM ALUMINIO C/ TAMPA 3/4BSP TIPO C DVRT 034-BSP-C DAISA | F12: DIIRT 034-BSP-C | G12: 1 | H12: PC | I12: DAISA | J12: 6.7 | K12: =G12*J12 -> 6.7 | L12: DIIRT 034-BSP-C | M12: =IFERROR(VLOOKUP(C12,Custo_MI_Device!$B$2:$E$102,3,FALSE),0) -> 0 | N12: =ROUNDUP(M12*G12,0) -> 0 | O12: =N12*J12 -> 0
A13: 4307 | B13: AIT | C13: AIT Hart - 2 Fios - Tanque | D13: 73063000 | E13: ELETRODUTO PESADO C/ LUVA AÇO CARBONO GF NBR 5598 2" X 3000MM BSP | F13: 0 | G13: 0 | H13: BR | I13: CARBINOX | J13: 86 | K13: =G13*J13 -> 0 | L13: AUT-4307 | M13: =IFERROR(VLOOKUP(C13,Custo_MI_Device!$B$2:$E$102,3,FALSE),0) -> 0 | N13: =ROUNDUP(M13*G13,0) -> 0 | O13: =N13*J13 -> 0
A14: 4306 | B14: AIT | C14: AIT Hart - 2 Fios - Tanque | D14: 73063000 | E14: ELETRODUTO PESADO C/ LUVA AÇO CARBONO GF NBR 5598 3/4" X 3000MM BSP | F14: 0 | G14: 2 | H14: BR | I14: CARBINOX | J14: 32 | K14: =G14*J14 -> 64 | L14: AUT-4306 | M14: =IFERROR(VLOOKUP(C14,Custo_MI_Device!$B$2:$E$102,3,FALSE),0) -> 0 | N14: =ROUNDUP(M14*G14,0) -> 0 | O14: =N14*J14 -> 0
A15: 2564 | B15: AIT | C15: AIT Hart - 2 Fios - Tanque | D15: 73145000 | E15: PERFILADO PERFURADO GF 16AWG 19 X 38 X 6000MM | F15: DP 504 | G15: 6 | H15: M | I15: DISPAN | J15: 21 | K15: =G15*J15 -> 126 | L15: DP 504 | M15: =IFERROR(VLOOKUP(C15,Custo_MI_Device!$B$2:$E$102,3,FALSE),0) -> 0 | N15: =ROUNDUP(M15*G15,0) -> 0 | O15: =N15*J15 -> 0
A16: 3274 | B16: AIT | C16: AIT Hart - 2 Fios - Tanque | D16: 73181500 | E16: PORCA SEXTAVADA ZC 1/4" | F16: DP 618 | G16: 28 | H16: PC | I16: DISPAN | J16: 0.06 | K16: =G16*J16 -> 1.68 | L16: DP 618 | M16: =IFERROR(VLOOKUP(C16,Custo_MI_Device!$B$2:$E$102,3,FALSE),0) -> 0 | N16: =ROUNDUP(M16*G16,0) -> 0 | O16: =N16*J16 -> 0
A17: 1611 | B17: AIT | C17: AIT Hart - 2 Fios - Tanque | D17: 39174090 | E17: PRENSA CABO HSK-K CZ RAL 7035 POLIAMIDA S/ CONTRA PORCA 1/2"NPT | F17: 1.209.1200.71 | G17: 2 | H17: PC | I17: HUMMEL | J17: 7.8 | K17: =G17*J17 -> 15.6 | L17: 1.209.1200.71 | M17: =IFERROR(VLOOKUP(C17,Custo_MI_Device!$B$2:$E$102,3,FALSE),0) -> 0 | N17: =ROUNDUP(M17*G17,0) -> 0 | O17: =N17*J17 -> 0
A18: 5081 | B18: AIT | C18: AIT Hart - 2 Fios - Tanque | D18: 73145000 | E18: SUPORTE P/ INSTRUMENTOS EM AÇO A-36 2" AZUL RAL 5002 TIPO "L" | F18: 0 | G18: 1 | H18: PC | I18: BRUMEC | J18: 23 | K18: =G18*J18 -> 23 | L18: AUT-5081 | M18: =IFERROR(VLOOKUP(C18,Custo_MI_Device!$B$2:$E$102,3,FALSE),0) -> 0 | N18: =ROUNDUP(M18*G18,0) -> 0 | O18: =N18*J18 -> 0
A19: 2534 | B19: AIT | C19: AIT Hart - 2 Fios - Tubul. | D19: 73072900 | E19: ABRACADEIRA VERGALHAO GRAMPO U ZC 3/4 X 1/4 DP 634-2 DISPAN | F19: DP 634-2 | G19: 12 | H19: PC | I19: DISPAN | J19: 1.2 | K19: =G19*J19 -> 14.4 | L19: DP 634-2 | M19: =IFERROR(VLOOKUP(C19,Custo_MI_Device!$B$2:$E$102,3,FALSE),0) -> 0 | N19: =ROUNDUP(M19*G19,0) -> 0 | O19: =N19*J19 -> 0
A20: 1669 | B20: AIT | C20: AIT Hart - 2 Fios - Tubul. | D20: 39269090 | E20: ABRACADEIRA, NYLON PRETA, 2,5 X 101MM, T-18 R, HELLERMANN | F20: T-18 R | G20: 3 | H20: PC | I20: HELLERMANN | J20: 0.04 | K20: =G20*J20 -> 0.12 | L20: T-18 R | M20: =IFERROR(VLOOKUP(C20,Custo_MI_Device!$B$2:$E$102,3,FALSE),0) -> 0 | N20: =ROUNDUP(M20*G20,0) -> 0 | O20: =N20*J20 -> 0
A21: 5091 | B21: AIT | C21: AIT Hart - 2 Fios - Tubul. | D21: 73181500 | E21: ARRUELA LISA ZC 1/4" | F21: DP 619 | G21: 24 | H21: PC | I21: DISPAN | J21: 0.04 | K21: =G21*J21 -> 0.96 | L21: DP 619 | M21: =IFERROR(VLOOKUP(C21,Custo_MI_Device!$B$2:$E$102,3,FALSE),0) -> 0 | N21: =ROUNDUP(M21*G21,0) -> 0 | O21: =N21*J21 -> 0
A22: 1117 | B22: AIT | C22: AIT Hart - 2 Fios - Tubul. | E22: BUCHA REDUCAO, ALUMINIO, 3/4 X 1/2 BSP | F22: BRR 034 X 012 | G22: 3 | H22: PC | I22: DAISA | J22: 1.95 | K22: =G22*J22 -> 5.85 | L22: BRR 034 X 012 | M22: =IFERROR(VLOOKUP(C22,Custo_MI_Device!$B$2:$E$102,3,FALSE),0) -> 0 | N22: =ROUNDUP(M22*G22,0) -> 0 | O22: =N22*J22 -> 0
A23: 3585 | B23: AIT | C23: AIT Hart - 2 Fios - Tubul. | D23: 85444900 | E23: CABO INSTRUMENTACAO BF, ISOL PVC/E 105øC, NBR 10300, C/ BLIND.ELETROST.COLETIVA FIO DRENO 1X2X0,75MMý 900400 ENERGIFLEX | F23: 900400 | G23: 0 | H23: M | I23: ENERGIFLEX | J23: 1.7 | K23: =G23*J23 -> 0 | L23: 900400 | M23: =IFERROR(VLOOKUP(C23,Custo_MI_Device!$B$2:$E$102,3,FALSE),0) -> 0 | N23: =ROUNDUP(M23*G23,0) -> 0 | O23: =N23*J23 -> 0
A24: 2805 | B24: AIT | C24: AIT Hart - 2 Fios - Tubul. | D24: 72162100 | E24: CANTONEIRA, ACO A36, ABAS IGUAIS, 1.1/2 X 1/4 X 6.000MM, GERDAU | F24: 0 | G24: 2.9 | H24: KG | I24: GERDAU | J24: 4.22 | K24: =G24*J24 -> 12.238 | L24: AUT-2805 | M24: =IFERROR(VLOOKUP(C24,Custo_MI_Device!$B$2:$E$102,3,FALSE),0) -> 0 | N24: =ROUNDUP(M24*G24,0) -> 0 | O24: =N24*J24 -> 0
A25: 4823 | B25: AIT | C25: AIT Hart - 2 Fios - Tubul. | D25: 76090000 | E25: CONDULETE ROSCÁVEL EM ALUMÍNIO C/ TAMPA 3/4"BSP TIPO "LR" | F25: DVRT 034-BSP-LR | G25: 0.75 | H25: PC | I25: DAISA | J25: 6.7 | K25: =G25*J25 -> 5.025 | L25: DVRT 034-BSP-LR | M25: =IFERROR(VLOOKUP(C25,Custo_MI_Device!$B$2:$E$102,3,FALSE),0) -> 0 | N25: =ROUNDUP(M25*G25,0) -> 0 | O25: =N25*J25 -> 0
A26: 2912 | B26: AIT | C26: AIT Hart - 2 Fios - Tubul. | D26: 76090000 | E26: CONDULETE ROSCÁVEL EM ALUMÍNIO C/ TAMPA 3/4"BSP TIPO "T" | F26: DIIRT 034-BSP-T | G26: 1 | H26: PC | I26: DAISA | J26: 7.5 | K26: =G26*J26 -> 7.5 | L26: DIIRT 034-BSP-T | M26: =IFERROR(VLOOKUP(C26,Custo_MI_Device!$B$2:$E$102,3,FALSE),0) -> 0 | N26: =ROUNDUP(M26*G26,0) -> 0 | O26: =N26*J26 -> 0
A27: 3436 | B27: AIT | C27: AIT Hart - 2 Fios - Tubul. | D27: 76090000 | E27: CONDULETE ROSCAVEL EM ALUMINIO C/ TAMPA 3/4BSP TIPO C DVRT 034-BSP-C DAISA | F27: DIIRT 034-BSP-C | G27: 1 | H27: PC | I27: DAISA | J27: 6.7 | K27: =G27*J27 -> 6.7 | L27: DIIRT 034-BSP-C | M27: =IFERROR(VLOOKUP(C27,Custo_MI_Device!$B$2:$E$102,3,FALSE),0) -> 0 | N27: =ROUNDUP(M27*G27,0) -> 0 | O27: =N27*J27 -> 0
A28: 2909 | B28: AIT | C28: AIT Hart - 2 Fios - Tubul. | D28: 73072200 | E28: CONECTOR RETO MACHO ASTM A276 INOX 316 TP C CL 6500 PSI 1/2"OD X 1/2"NPT | F28: 8-CM-8-316 | G28: 1 | H28: PC | I28: TRIUNION | J28: 27.7 | K28: =G28*J28 -> 27.7 | L28: 8-CM-8-316 | M28: =IFERROR(VLOOKUP(C28,Custo_MI_Device!$B$2:$E$102,3,FALSE),0) -> 0 | N28: =ROUNDUP(M28*G28,0) -> 0 | O28: =N28*J28 -> 0
A29: 4306 | B29: AIT | C29: AIT Hart - 2 Fios - Tubul. | D29: 73063000 | E29: ELETRODUTO PESADO C/ LUVA AÇO CARBONO GF NBR 5598 3/4" X 3000MM BSP | F29: 0 | G29: 2 | H29: BR | I29: CARBINOX | J29: 32 | K29: =G29*J29 -> 64 | L29: AUT-4306 | M29: =IFERROR(VLOOKUP(C29,Custo_MI_Device!$B$2:$E$102,3,FALSE),0) -> 0 | N29: =ROUNDUP(M29*G29,0) -> 0 | O29: =N29*J29 -> 0
A30: 1900 | B30: AIT | C30: AIT Hart - 2 Fios - Tubul. | D30: 73072200 | E30: NIPLE DUPLO SEXTAVADO ASTM A276 INOX 316 TP C CL 6500 PSI 1/2"NPT | F30: 8-NI-316 | G30: 1 | H30: PC | I30: TRIUNION | J30: 27 | K30: =G30*J30 -> 27 | L30: 8-NI-316 | M30: =IFERROR(VLOOKUP(C30,Custo_MI_Device!$B$2:$E$102,3,FALSE),0) -> 0 | N30: =ROUNDUP(M30*G30,0) -> 0 | O30: =N30*J30 -> 0
A31: 3274 | B31: AIT | C31: AIT Hart - 2 Fios - Tubul. | D31: 73181500 | E31: PORCA SEXTAVADA ZC 1/4" | F31: DP 618 | G31: 24 | H31: PC | I31: DISPAN | J31: 0.06 | K31: =G31*J31 -> 1.44 | L31: DP 618 | M31: =IFERROR(VLOOKUP(C31,Custo_MI_Device!$B$2:$E$102,3,FALSE),0) -> 0 | N31: =ROUNDUP(M31*G31,0) -> 0 | O31: =N31*J31 -> 0
A32: 1611 | B32: AIT | C32: AIT Hart - 2 Fios - Tubul. | D32: 39174090 | E32: PRENSA CABO HSK-K CZ RAL 7035 POLIAMIDA S/ CONTRA PORCA 1/2"NPT | F32: 1.209.1200.71 | G32: 3 | H32: PC | I32: HUMMEL | J32: 7.8 | K32: =G32*J32 -> 23.4 | L32: 1.209.1200.71 | M32: =IFERROR(VLOOKUP(C32,Custo_MI_Device!$B$2:$E$102,3,FALSE),0) -> 0 | N32: =ROUNDUP(M32*G32,0) -> 0 | O32: =N32*J32 -> 0
A33: 5081 | B33: AIT | C33: AIT Hart - 2 Fios - Tubul. | D33: 73145000 | E33: SUPORTE P/ INSTRUMENTOS EM AÇO A-36 2" AZUL RAL 5002 TIPO "L" | F33: 0 | G33: 1 | H33: PC | I33: BRUMEC | J33: 23 | K33: =G33*J33 -> 23 | L33: AUT-5081 | M33: =IFERROR(VLOOKUP(C33,Custo_MI_Device!$B$2:$E$102,3,FALSE),0) -> 0 | N33: =ROUNDUP(M33*G33,0) -> 0 | O33: =N33*J33 -> 0
A34: 5194 | B34: AIT | C34: AIT Hart - 2 Fios - Tubul. | D34: 73041010 | E34: TUBO ACO INOX AISI 316L A-269 TREFILADO S/ COSTURA 3063 PSI A 38 øC 12,7 X 1,24MM TI-127124-316 TRIUNION | F34: TI-127124-316 | G34: 1 | H34: BR | I34: TRIUNION | J34: =21.5*6 -> 129 | K34: =G34*J34 -> 129 | L34: TI-127124-316 | M34: =IFERROR(VLOOKUP(C34,Custo_MI_Device!$B$2:$E$102,3,FALSE),0) -> 0 | N34: =ROUNDUP(M34*G34,0) -> 0 | O34: =N34*J34 -> 0
A35: 2567 | B35: AIT | C35: AIT Hart - 2 Fios - Tubul. | D35: 84818095 | E35: VALVULA ESFERA TRIPARTIDA,CL 300 CORPO E TP A 216 WCB, ESFERA ASTM A351 CF8, PASS. REDUZIDA,VED.PTFE ROSCA 1/2 BSP MGA | F35: 0 | G35: 1 | H35: PC | I35: MGA | J35: 27 | K35: =G35*J35 -> 27 | L35: AUT-2567 | M35: =IFERROR(VLOOKUP(C35,Custo_MI_Device!$B$2:$E$102,3,FALSE),0) -> 0 | N35: =ROUNDUP(M35*G35,0) -> 0 | O35: =N35*J35 -> 0
A36: 2566 | B36: AIT | C36: AIT Hart - 4 Fios - Tanque | D36: 73072900 | E36: ABRACADEIRA VERGALHAO GRAMPO U ZC 2 X 1/4 DP 634-6 DISPAN | F36: DP 634-6 | G36: 2 | H36: PC | I36: DISPAN | J36: 2.8 | K36: =G36*J36 -> 5.6 | L36: DP 634-6 | M36: =IFERROR(VLOOKUP(C36,Custo_MI_Device!$B$2:$E$102,3,FALSE),0) -> 0 | N36: =ROUNDUP(M36*G36,0) -> 0 | O36: =N36*J36 -> 0
A37: 2534 | B37: AIT | C37: AIT Hart - 4 Fios - Tanque | D37: 73072900 | E37: ABRACADEIRA VERGALHAO GRAMPO U ZC 3/4 X 1/4 DP 634-2 DISPAN | F37: DP 634-2 | G37: 12 | H37: PC | I37: DISPAN | J37: 1.2 | K37: =G37*J37 -> 14.4 | L37: DP 634-2 | M37: =IFERROR(VLOOKUP(C37,Custo_MI_Device!$B$2:$E$102,3,FALSE),0) -> 0 | N37: =ROUNDUP(M37*G37,0) -> 0 | O37: =N37*J37 -> 0
A38: 1669 | B38: AIT | C38: AIT Hart - 4 Fios - Tanque | D38: 39269090 | E38: ABRACADEIRA, NYLON PRETA, 2,5 X 101MM, T-18 R, HELLERMANN | F38: T-18 R | G38: 3 | H38: PC | I38: HELLERMANN | J38: 0.04 | K38: =G38*J38 -> 0.12 | L38: T-18 R | M38: =IFERROR(VLOOKUP(C38,Custo_MI_Device!$B$2:$E$102,3,FALSE),0) -> 0 | N38: =ROUNDUP(M38*G38,0) -> 0 | O38: =N38*J38 -> 0
A39: 5091 | B39: AIT | C39: AIT Hart - 4 Fios - Tanque | D39: 73181500 | E39: ARRUELA LISA ZC 1/4" | F39: DP 619 | G39: 28 | H39: PC | I39: DISPAN | J39: 0.04 | K39: =G39*J39 -> 1.12 | L39: DP 619 | M39: =IFERROR(VLOOKUP(C39,Custo_MI_Device!$B$2:$E$102,3,FALSE),0) -> 0 | N39: =ROUNDUP(M39*G39,0) -> 0 | O39: =N39*J39 -> 0
A40: 1117 | B40: AIT | C40: AIT Hart - 4 Fios - Tanque | E40: BUCHA REDUCAO, ALUMINIO, 3/4 X 1/2 BSP | F40: BRR 034 X 012 | G40: 1 | H40: PC | I40: DAISA | J40: 1.95 | K40: =G40*J40 -> 1.95 | L40: BRR 034 X 012 | M40: =IFERROR(VLOOKUP(C40,Custo_MI_Device!$B$2:$E$102,3,FALSE),0) -> 0 | N40: =ROUNDUP(M40*G40,0) -> 0 | O40: =N40*J40 -> 0
...

Sheet Custo_MI_Infra
A1: ISA | B1: TIPO | C1: CUSTO UNITARIO Metro | D1: QUANT | E1: CUSTO TOTAL | L1: =SUM(E:E) -> 0
A2: Infra | B2: Infra Eletrica de 1" | C2: =SUMIF(Insumos_Infra!$B:$B,Custo_MI_Infra!$B2,Insumos_Infra!$M:$M) -> 22.962533 | E2: =C2*D2 -> 0
A3: Infra | B3: Infra Eletrica de 1" Exd | C3: =SUMIF(Insumos_Infra!$B:$B,Custo_MI_Infra!$B3,Insumos_Infra!$M:$M) -> 32.236978 | E3: =C3*D3 -> 0
A4: Infra | B4: Infra Eletrica de 1.1/2" | C4: =SUMIF(Insumos_Infra!$B:$B,Custo_MI_Infra!$B4,Insumos_Infra!$M:$M) -> 39.480311 | E4: =C4*D4 -> 0
A5: Infra | B5: Infra Eletrica de 1.1/2" Exd | C5: =SUMIF(Insumos_Infra!$B:$B,Custo_MI_Infra!$B5,Insumos_Infra!$M:$M) -> 59.762533 | E5: =C5*D5 -> 0
A6: Infra | B6: Infra Eletrica de 2" | C6: =SUMIF(Insumos_Infra!$B:$B,Custo_MI_Infra!$B6,Insumos_Infra!$M:$M) -> 47.790311 | E6: =C6*D6 -> 0
A7: Infra | B7: Infra Eletrica de 2" Exd | C7: =SUMIF(Insumos_Infra!$B:$B,Custo_MI_Infra!$B7,Insumos_Infra!$M:$M) -> 73.621422 | E7: =C7*D7 -> 0
A8: Infra | B8: Infra Eletrica de 3/4" | C8: =SUMIF(Insumos_Infra!$B:$B,Custo_MI_Infra!$B8,Insumos_Infra!$M:$M) -> 18.026422 | E8: =C8*D8 -> 0
A9: Infra | B9: Infra Eletrica de 3/4" Exd | C9: =SUMIF(Insumos_Infra!$B:$B,Custo_MI_Infra!$B9,Insumos_Infra!$M:$M) -> 26.058089 | E9: =C9*D9 -> 0
A10: Infra | B10: Infra Eletrica de Eletrocalha de 100 mm | C10: =SUMIF(Insumos_Infra!$B:$B,Custo_MI_Infra!$B10,Insumos_Infra!$M:$M) -> 61.884756 | E10: =C10*D10 -> 0
A11: Infra | B11: Infra Eletrica de Eletrocalha de 200 mm | C11: =SUMIF(Insumos_Infra!$B:$B,Custo_MI_Infra!$B11,Insumos_Infra!$M:$M) -> 81.6934 | E11: =C11*D11 -> 0
A12: Infra | B12: Infra Eletrica de Eletrocalha de 300 mm | C12: =SUMIF(Insumos_Infra!$B:$B,Custo_MI_Infra!$B12,Insumos_Infra!$M:$M) -> 98.9034 | E12: =C12*D12 -> 0
A13: Infra | B13: Infra Pneumática de 1" | C13: =SUMIF(Insumos_Infra!$B:$B,Custo_MI_Infra!$B13,Insumos_Infra!$M:$M) -> 32.567533 | E13: =C13*D13 -> 0
... A17: Infra | B17: Infra Enterrada Canaflex 2" | C17: =SUMIF(Insumos_Infra!$B:$B,Custo_MI_Infra!$B17,Insumos_Infra!$M:$M) -> 0 | E17: =C17*D17 -> 0

Sheet Insumos_Infra
P1: =SUM(P3:P262) -> 0
A2: Código | B2: Tipo | C2: NCM | D2: Descrição dos Materiais | E2: Modelo | F2: QTDE | G2: UNID | H2: Fabricante | I2: Valor Unit | J2: Valor Total | K2: Código Nota | L2: Quantidade por Metro | M2: Custo Por Metro | N2: Quant Metro | O2: Quantidade | P2: Valor Total
A3: 118 | B3: Infra Eletrica de 1" | C3: 73072900 | D3: ABRAÇADEIRA VERGALHÃO GRAMPO "U" ZC 1" X 1/4" | E3: DP 634-3 | F3: 9 | G3: PC | H3: DISPAN | I3: 1.85 | J3: =F3*I3 -> 16.65 | K3: DP 634-3 | L3: =F3/($F$13*3) -> 0.5 | M3: =L3*I3 -> 0.925 | N3: =IFERROR(VLOOKUP(B3,Custo_MI_Infra!B:E,3,FALSE),0) -> 0 | O3: =N3*L3 -> 0 | P3: =O3*I3 -> 0
A4: 95 | B4: Infra Eletrica de 1" | C4: 73072900 | D4: ARRUELA ACABAMENTO ALUMÍNIO 1"BSP | E4: AU 100 - BSP | F4: 1 | G4: PC | H4: DAISA | I4: 0.65 | J4: =F4*I4 -> 0.65 | K4: AU 100 - BSP | L4: =F4/($F$13*3) -> 0.055555556 | M4: =L4*I4 -> 0.036111111 | N4: =IFERROR(VLOOKUP(B4,Custo_MI_Infra!B:E,3,FALSE),0) -> 0 | O4: =N4*L4 -> 0 | P4: =O4*I4 -> 0
A5: 300 | B5: Infra Eletrica de 1" | C5: 73071100 | D5: BUCHA ACABAMENTO ALUMÍNIO 1"BSP | E5: BU-100-B | F5: 1 | G5: PC | H5: DAISA | I5: 0.95 | J5: =F5*I5 -> 0.95 | K5: BU-100-B | L5: =F5/($F$13*3) -> 0.055555556 | M5: =L5*I5 -> 0.052777778 | N5: =IFERROR(VLOOKUP(B5,Custo_MI_Infra!B:E,3,FALSE),0) -> 0 | O5: =N5*L5 -> 0 | P5: =O5*I5 -> 0
A6: 2805 | B6: Infra Eletrica de 1" | C6: 72162100 | D6: CANTONEIRA AÇO ABAS IGUAIS 1.1/2" X 1/4" X 6.000MM | E6: L | F6: =0.86*F13*3 -> 15.48 | G6: KG | H6: GERDAU | I6: 4.22 | J6: =F6*I6 -> 65.3256 | K6: AUT-2805 | L6: =F6/($F$13*3) -> 0.86 | M6: =L6*I6 -> 3.6292 | N6: =IFERROR(VLOOKUP(B6,Custo_MI_Infra!B:E,3,FALSE),0) -> 0 | O6: =N6*L6 -> 0 | P6: =O6*I6 -> 0
A7: 3500 | B7: Infra Eletrica de 1" | C7: 76090000 | D7: CONDULETE ROSCÁVEL EM ALUMÍNIO C/ TAMPA 1"BSP TIPO "C" | E7: DVRT 100-BSP-C | F7: 1 | G7: PC | H7: DAISA | I7: 8.1 | J7: =F7*I7 -> 8.1 | K7: DVRT 100-BSP-C | L7: =F7/($F$13*3) -> 0.055555556 | M7: =L7*I7 -> 0.45 | N7: =IFERROR(VLOOKUP(B7,Custo_MI_Infra!B:E,3,FALSE),0) -> 0 | O7: =N7*L7 -> 0 | P7: =O7*I7 -> 0
A8: 4869 | B8: Infra Eletrica de 1" | C8: 76090000 | D8: CONDULETE ROSCÁVEL EM ALUMÍNIO C/ TAMPA 1"BSP TIPO "LB" | E8: DVRT 100-BSP-LB | F8: 1 | G8: PC | H8: DAISA | I8: 8.1 | J8: =F8*I8 -> 8.1 | K8: DVRT 100-BSP-LB | L8: =F8/($F$13*3) -> 0.055555556 | M8: =L8*I8 -> 0.45 | N8: =IFERROR(VLOOKUP(B8,Custo_MI_Infra!B:E,3,FALSE),0) -> 0 | O8: =N8*L8 -> 0 | P8: =O8*I8 -> 0
A9: 203 | B9: Infra Eletrica de 1" | C9: 76090000 | D9: CONDULETE ROSCÁVEL EM ALUMÍNIO C/ TAMPA 1"BSP TIPO "LL" | E9: DVRT 100-BSP-LL | F9: 1 | G9: PC | H9: DAISA | I9: 8.1 | J9: =F9*I9 -> 8.1 | K9: DVRT 100-BSP-LL | L9: =F9/($F$13*3) -> 0.055555556 | M9: =L9*I9 -> 0.45 | N9: =IFERROR(VLOOKUP(B9,Custo_MI_Infra!B:E,3,FALSE),0) -> 0 | O9: =N9*L9 -> 0 | P9: =O9*I9 -> 0
A10: 2547 | B10: Infra Eletrica de 1" | C10: 76090000 | D10: CONDULETE ROSCÁVEL EM ALUMÍNIO C/ TAMPA 1"BSP TIPO "LR" | E10: DVRT 100-BSP-LR | F10: 1 | G10: PC | H10: DAISA | I10: 8.1 | J10: =F10*I10 -> 8.1 | K10: DVRT 100-BSP-LR | L10: =F10/($F$13*3) -> 0.055555556 | M10: =L10*I10 -> 0.45 | N10: =IFERROR(VLOOKUP(B10,Custo_MI_Infra!B:E,3,FALSE),0) -> 0 | O10: =N10*L10 -> 0 | P10: =O10*I10 -> 0
A11: 4625 | B11: Infra Eletrica de 1" | C11: 76090000 | D11: CONDULETE ROSCÁVEL EM ALUMÍNIO C/ TAMPA 1"BSP TIPO "T" | E11: DVRT 100-BSP-T | F11: 1 | G11: PC | H11: DAISA | I11: 8.45 | J11: =F11*I11 -> 8.45 | K11: DVRT 100-BSP-T | L11: =F11/($F$13*3) -> 0.055555556 | M11: =L11*I11 -> 0.46944444 | N11: =IFERROR(VLOOKUP(B11,Custo_MI_Infra!B:E,3,FALSE),0) -> 0 | O11: =N11*L11 -> 0 | P11: =O11*I11 -> 0
A12: 2894 | B12: Infra Eletrica de 1" | C12: 73063000 | D12: CURVA P/ ELETRODUTO PESADO AÇO CARBONO GF NBR 5598 1" | E12: 0 | F12: 1 | G12: PC | H12: CARBINOX | I12: 9.3 | J12: =F12*I12 -> 9.3 | K12: AUT-2894 | L12: =F12/($F$13*3) -> 0.055555556 | M12: =L12*I12 -> 0.51666667 | N12: =IFERROR(VLOOKUP(B12,Custo_MI_Infra!B:E,3,FALSE),0) -> 0 | O12: =N12*L12 -> 0 | P12: =O12*I12 -> 0
A13: 2894 | B13: Infra Eletrica de 1" | C13: 73063000 | D13: ELETRODUTO PESADO C/ LUVA AÇO CARBONO GF NBR 5598 1" X 3000MM BSP | E13: 0 | F13: 6 | G13: BR | H13: CARBINOX | I13: 46.6 | J13: =F13*I13 -> 279.6 | K13: AUT-2894 | L13: =F13/($F$13*3) -> 0.33333333 | M13: =L13*I13 -> 15.533333 | N13: =IFERROR(VLOOKUP(B13,Custo_MI_Infra!B:E,3,FALSE),0) -> 0 | O13: =N13*L13 -> 0 | P13: =O13*I13 -> 0
A14: 118 | B14: Infra Eletrica de 1" Exd | C14: 73072900 | D14: ABRAÇADEIRA VERGALHÃO GRAMPO "U" ZC 1" X 1/4" | E14: DP 634-3 | F14: 9 | G14: PC | H14: DISPAN | I14: 1.85 | J14: =F14*I14 -> 16.65 | K14: DP 634-3 | L14: =F14/($F$25*3) -> 0.5 | M14: =L14*I14 -> 0.925 | N14: =IFERROR(VLOOKUP(B14,Custo_MI_Infra!B:E,3,FALSE),0) -> 0 | O14: =N14*L14 -> 0 | P14: =O14*I14 -> 0
A15: 4928 | B15: Infra Eletrica de 1" Exd | C15: 73072900 | D15: ARRUELA ACABAMENTO EX-D FERRO NODULAR GF 1" NPT | E15: CX / AR-3 FG | F15: 1 | G15: PC | H15: CONEX | I15: 4.4 | J15: =F15*I15 -> 4.4 | K15: CX / AR-3 FG | L15: =F15/($F$25*3) -> 0.055555556 | M15: =L15*I15 -> 0.24444444 | N15: =IFERROR(VLOOKUP(B15,Custo_MI_Infra!B:E,3,FALSE),0) -> 0 | O15: =N15*L15 -> 0 | P15: =O15*I15 -> 0
A16: 96 | B16: Infra Eletrica de 1" Exd | C16: 73071100 | D16: BUCHA ACABAMENTO EX-D FERRO NODULAR GF 1" NPT | E16: CX / BF-3 FG | F16: 1 | G16: PC | H16: CONEX | I16: 5.3 | J16: =F16*I16 -> 5.3 | K16: CX / BF-3 FG | L16: =F16/($F$25*3) -> 0.055555556 | M16: =L16*I16 -> 0.29444444 | N16: =IFERROR(VLOOKUP(B16,Custo_MI_Infra!B:E,3,FALSE),0) -> 0 | O16: =N16*L16 -> 0 | P16: =O16*I16 -> 0
A17: 74 | B17: Infra Eletrica de 1" Exd | C17: 73071100 | D17: BUCHA REDUÇÃO EX-D FERRO NODULAR GF 1" X 1/2" NPT | E17: CX / BRD-31 FG | F17: 1 | G17: PC | H17: CONEX | I17: 6.95 | J17: =F17*I17 -> 6.95 | K17: CX / BRD-31 FG | L17: =F17/($F$25*3) -> 0.055555556 | M17: =L17*I17 -> 0.38611111 | N17: =IFERROR(VLOOKUP(B17,Custo_MI_Infra!B:E,3,FALSE),0) -> 0 | O17: =N17*L17 -> 0 | P17: =O17*I17 -> 0
A18: 320 | B18: Infra Eletrica de 1" Exd | C18: 73071100 | D18: BUCHA REDUÇÃO EX-D FERRO NODULAR GF 1" X 3/4" NPT | E18: CX / BRD-32 FG | F18: 1 | G18: PC | H18: CONEX | I18: 5.44 | J18: =F18*I18 -> 5.44 | K18: CX / BRD-32 FG | L18: =F18/($F$25*3) -> 0.055555556 | M18: =L18*I18 -> 0.30222222 | N18: =IFERROR(VLOOKUP(B18,Custo_MI_Infra!B:E,3,FALSE),0) -> 0 | O18: =N18*L18 -> 0 | P18: =O18*I18 -> 0
A19: 2805 | B19: Infra Eletrica de 1" Exd | C19: 72162100 | D19: CANTONEIRA AÇO ABAS IGUAIS 1.1/2" X 1/4" X 6.000MM | E19: 0 | F19: =0.86*F25*3 -> 15.48 | G19: KG | H19: GERDAU | I19: 4.22 | J19: =F19*I19 -> 65.3256 | K19: AUT-2805 | L19: =F19/($F$25*3) -> 0.86 | M19: =L19*I19 -> 3.6292 | N19: =IFERROR(VLOOKUP(B19,Custo_MI_Infra!B:E,3,FALSE),0) -> 0 | O19: =N19*L19 -> 0 | P19: =O19*I19 -> 0
A20: 122 | B20: Infra Eletrica de 1" Exd | C20: 73071100 | D20: CONDULETE ROSCÁVEL EM ALUMÍNIO FUNDIDO EX-D C/ TAMPA 1"NPT TIPO "C" | E20: TCLEX/3-C | F20: 1 | G20: PC | H20: TELBRA | I20: 38 | J20: =F20*I20 -> 38 | K20: TCLEX/3-C | L20: =F20/($F$25*3) -> 0.055555556 | M20: =L20*I20 -> 2.1111111 | N20: =IFERROR(VLOOKUP(B20,Custo_MI_Infra!B:E,3,FALSE),0) -> 0 | O20: =N20*L20 -> 0 | P20: =O20*I20 -> 0
A21: 124 | B21: Infra Eletrica de 1" Exd | C21: 73071100 | D21: CONDULETE ROSCÁVEL EM ALUMÍNIO FUNDIDO EX-D C/ TAMPA 1"NPT TIPO "LB" | E21: TCLEX/3-LB | F21: 1 | G21: PC | H21: TELBRA | I21: 38 | J21: =F21*I21 -> 38 | K21: TCLEX/3-LB | L21: =F21/($F$25*3) -> 0.055555556 | M21: =L21*I21 -> 2.1111111 | N21: =IFERROR(VLOOKUP(B21,Custo_MI_Infra!B:E,3,FALSE),0) -> 0 | O21: =N21*L21 -> 0 | P21: =O21*I21 -> 0
A22: 125 | B22: Infra Eletrica de 1" Exd | C22: 73071100 | D22: CONDULETE ROSCÁVEL EM ALUMÍNIO FUNDIDO EX-D C/ TAMPA 1"NPT TIPO "LL" | E22: TCLEX/3-LL | F22: 1 | G22: PC | H22: TELBRA | I22: 38 | J22: =F22*I22 -> 38 | K22: TCLEX/3-LL | L22: =F22/($F$25*3) -> 0.055555556 | M22: =L22*I22 -> 2.1111111 | N22: =IFERROR(VLOOKUP(B22,Custo_MI_Infra!B:E,3,FALSE),0) -> 0 | O22: =N22*L22 -> 0 | P22: =O22*I22 -> 0
A23: 126 | B23: Infra Eletrica de 1" Exd | C23: 73071100 | D23: CONDULETE ROSCÁVEL EM ALUMÍNIO FUNDIDO EX-D C/ TAMPA 1"NPT TIPO "LR" | E23: TCLEX/3-LR | F23: 1 | G23: PC | H23: TELBRA | I23: 38 | J23: =F23*I23 -> 38 | K23: TCLEX/3-LR | L23: =F23/($F$25*3) -> 0.055555556 | M23: =L23*I23 -> 2.1111111 | N23: =IFERROR(VLOOKUP(B23,Custo_MI_Infra!B:E,3,FALSE),0) -> 0 | O23: =N23*L23 -> 0 | P23: =O23*I23 -> 0
A24: 128 | B24: Infra Eletrica de 1" Exd | C24: 73071100 | D24: CONDULETE ROSCÁVEL EM ALUMÍNIO FUNDIDO EX-D C/ TAMPA 1"NPT TIPO "T" | E24: TCLEX/3-T | F24: 1 | G24: PC | H24: TELBRA | I24: 38 | J24: =F24*I24 -> 38 | K24: TCLEX/3-T | L24: =F24/($F$25*3) -> 0.055555556 | M24: =L24*I24 -> 2.1111111 | N24: =IFERROR(VLOOKUP(B24,Custo_MI_Infra!B:E,3,FALSE),0) -> 0 | O24: =N24*L24 -> 0 | P24: =O24*I24 -> 0
A25: 3609 | B25: Infra Eletrica de 1" Exd | C25: 73063000 | D25: ELETRODUTO PESADO C/ LUVA AÇO CARBONO GF EX-D NBR 5597 1" X 3000MM NPT | E25: 0 | F25: 6 | G25: BR | H25: CARBINOX | I25: 47.7 | J25: =F25*I25 -> 286.2 | K25: AUT-3609 | L25: =F25/($F$25*3) -> 0.33333333 | M25: =L25*I25 -> 15.9 | N25: =IFERROR(VLOOKUP(B25,Custo_MI_Infra!B:E,3,FALSE),0) -> 0 | O25: =N25*L25 -> 0 | P25: =O25*I25 -> 0
A26: 3182 | B26: Infra Eletrica de 1.1/2" | C26: 73072900 | D26: ABRAÇADEIRA VERGALHÃO GRAMPO "U" ZC 1.1/2" X 1/4" | E26: DP 634-5 | F26: 12 | G26: PC | H26: DISPAN | I26: 2.1 | J26: =F26*I26 -> 25.2 | K26: DP 634-5 | L26: =F26/($F$39*3) -> 0.66666667 | M26: =L26*I26 -> 1.4 | N26: =IFERROR(VLOOKUP(B26,Custo_MI_Infra!B:E,3,FALSE),0) -> 0 | O26: =N26*L26 -> 0 | P26: =O26*I26 -> 0
A27: 2608 | B27: Infra Eletrica de 1.1/2" | C27: 73072900 | D27: ARRUELA ACABAMENTO ALUMÍNIO 1.1/2"BSP | E27: AU 112 - BSP | F27: 1 | G27: PC | H27: DAISA | I27: 1.15 | J27: =F27*I27 -> 1.15 | K27: AU 112 - BSP | L27: =F27/($F$39*3) -> 0.055555556 | M27: =L27*I27 -> 0.063888889 | N27: =IFERROR(VLOOKUP(B27,Custo_MI_Infra!B:E,3,FALSE),0) -> 0 | O27: =N27*L27 -> 0 | P27: =O27*I27 -> 0
A28: 5091 | B28: Infra Eletrica de 1.1/2" | C28: 73181500 | D28: ARRUELA LISA ZC 1/4" | E28: DP 619 | F28: 24 | G28: PC | H28: DISPAN | I28: 0.04 | J28: =F28*I28 -> 0.96 | K28: DP 619 | L28: =F28/($F$39*3) -> 1.3333333 | M28: =L28*I28 -> 0.053333333 | N28: =IFERROR(VLOOKUP(B28,Custo_MI_Infra!B:E,3,FALSE),0) -> 0 | O28: =N28*L28 -> 0 | P28: =O28*I28 -> 0
A29: 2606 | B29: Infra Eletrica de 1.1/2" | C29: 73071100 | D29: BUCHA ACABAMENTO ALUMÍNIO 1.1/2"BSP | E29: BU-112-B | F29: 2 | G29: PC | H29: DAISA | I29: 1.78 | J29: =F29*I29 -> 3.56 | K29: BU-112-B | L29: =F29/($F$39*3) -> 0.11111111 | M29: =L29*I29 -> 0.19777778 | N29: =IFERROR(VLOOKUP(B29,Custo_MI_Infra!B:E,3,FALSE),0) -> 0 | O29: =N29*L29 -> 0 | P29: =O29*I29 -> 0
A30: 1119 | B30: Infra Eletrica de 1.1/2" | C30: 73071910 | D30: BUCHA REDUÇÃO ALUMÍNIO 1.1/2" X 1"BSP | E30: BRR 112 X 100 | F30: 1 | G30: PC | H30: DAISA | I30: 3.95 | J30: =F30*I30 -> 3.95 | K30: BRR 112 X 100 | L30: =F30/($F$39*3) -> 0.055555556 | M30: =L30*I30 -> 0.21944444 | N30: =IFERROR(VLOOKUP(B30,Custo_MI_Infra!B:E,3,FALSE),0) -> 0 | O30: =N30*L30 -> 0 | P30: =O30*I30 -> 0
A31: 4569 | B31: Infra Eletrica de 1.1/2" | C31: 73071910 | D31: BUCHA REDUÇÃO ALUMÍNIO 1.1/2" X 1/2"BSP | E31: BRR 112 X 012 | F31: 1 | G31: PC | H31: DAISA | I31: 4.2 | J31: =F31*I31 -> 4.2 | K31: BRR 112 X 012 | L31: =F31/($F$39*3) -> 0.055555556 | M31: =L31*I31 -> 0.23333333 | N31: =IFERROR(VLOOKUP(B31,Custo_MI_Infra!B:E,3,FALSE),0) -> 0 | O31: =N31*L31 -> 0 | P31: =O31*I31 -> 0
A32: 3599 | B32: Infra Eletrica de 1.1/2" | C32: 73071910 | D32: BUCHA REDUÇÃO ALUMÍNIO 1.1/2" X 3/4"BSP | E32: BRR 112 X 034 | F32: 2 | G32: PC | H32: DAISA | I32: 4.9 | J32: =F32*I32 -> 9.8 | K32: BRR 112 X 034 | L32: =F32/($F$39*3) -> 0.11111111 | M32: =L32*I32 -> 0.54444444 | N32: =IFERROR(VLOOKUP(B32,Custo_MI_Infra!B:E,3,FALSE),0) -> 0 | O32: =N32*L32 -> 0 | P32: =O32*I32 -> 0
A33: 2805 | B33: Infra Eletrica de 1.1/2" | C33: 72162100 | D33: CANTONEIRA AÇO ABAS IGUAIS 1.1/2" X 1/4" X 6.000MM | E33: 0 | F33: =0.86*F39*3 -> 15.48 | G33: KG | H33: GERDAU | I33: 4.22 | J33: =F33*I33 -> 65.3256 | K33: AUT-2805 | L33: =F33/($F$39*3) -> 0.86 | M33: =L33*I33 -> 3.6292 | N33: =IFERROR(VLOOKUP(B33,Custo_MI_Infra!B:E,3,FALSE),0) -> 0 | O33: =N33*L33 -> 0 | P33: =O33*I33 -> 0
A34: 4597 | B34: Infra Eletrica de 1.1/2" | C34: 76090000 | D34: CONDULETE ROSCÁVEL EM ALUMÍNIO C/ TAMPA 1.1/2"BSP TIPO "C" | E34: DVRT 112-BSP-C | F34: 2 | G34: PC | H34: DAISA | I34: 18.3 | J34: =F34*I34 -> 36.6 | K34: DVRT 112-BSP-C | L34: =F34/($F$39*3) -> 0.11111111 | M34: =L34*I34 -> 2.0333333 | N34: =IFERROR(VLOOKUP(B34,Custo_MI_Infra!B:E,3,FALSE),0) -> 0 | O34: =N34*L34 -> 0 | P34: =O34*I34 -> 0
A35: 4648 | B35: Infra Eletrica de 1.1/2" | C35: 76090000 | D35: CONDULETE ROSCÁVEL EM ALUMÍNIO C/ TAMPA 1.1/2"BSP TIPO "LB" | E35: DVRT 112-BSP-LB | F35: 1 | G35: PC | H35: DAISA | I35: 18.3 | J35: =F35*I35 -> 18.3 | K35: DVRT 112-BSP-LB | L35: =F35/($F$39*3) -> 0.055555556 | M35: =L35*I35 -> 1.0166667 | N35: =IFERROR(VLOOKUP(B35,Custo_MI_Infra!B:E,3,FALSE),0) -> 0 | O35: =N35*L35 -> 0 | P35: =O35*I35 -> 0
A36: 202 | B36: Infra Eletrica de 1.1/2" | C36: 76090000 | D36: CONDULETE ROSCÁVEL EM ALUMÍNIO C/ TAMPA 1.1/2"BSP TIPO "LL" | E36: DVRT 112-BSP-LL | F36: 1 | G36: PC | H36: DAISA | I36: 18.3 | J36: =F36*I36 -> 18.3 | K36: DVRT 112-BSP-LL | L36: =F36/($F$39*3) -> 0.055555556 | M36: =L36*I36 -> 1.0166667 | N36: =IFERROR(VLOOKUP(B36,Custo_MI_Infra!B:E,3,FALSE),0) -> 0 | O36: =N36*L36 -> 0 | P36: =O36*I36 -> 0
A37: 4584 | B37: Infra Eletrica de 1.1/2" | C37: 76090000 | D37: CONDULETE ROSCÁVEL EM ALUMÍNIO C/ TAMPA 1.1/2"BSP TIPO "LR" | E37: DVRT 112-BSP-LR | F37: 1 | G37: PC | H37: DAISA | I37: 18.3 | J37: =F37*I37 -> 18.3 | K37: DVRT 112-BSP-LR | L37: =F37/($F$39*3) -> 0.055555556 | M37: =L37*I37 -> 1.0166667 | N37: =IFERROR(VLOOKUP(B37,Custo_MI_Infra!B:E,3,FALSE),0) -> 0 | O37: =N37*L37 -> 0 | P37: =O37*I37 -> 0
A38: 444 | B38: Infra Eletrica de 1.1/2" | C38: 76090000 | D38: CONDULETE ROSCÁVEL EM ALUMÍNIO C/ TAMPA 1.1/2"BSP TIPO "T" | E38: DVRT 112-BSP-T | F38: 1 | G38: PC | H38: DAISA | I38: 19.2 | J38: =F38*I38 -> 19.2 | K38: DVRT 112-BSP-T | L38: =F38/($F$39*3) -> 0.055555556 | M38: =L38*I38 -> 1.0666667 | N38: =IFERROR(VLOOKUP(B38,Custo_MI_Infra!B:E,3,FALSE),0) -> 0 | O38: =N38*L38 -> 0 | P38: =O38*I38 -> 0
A39: 2833 | B39: Infra Eletrica de 1.1/2" | C39: 73063000 | D39: ELETRODUTO PESADO C/ LUVA AÇO CARBONO GF NBR 5598 1.1/2" X 3000MM BSP | E39: 0 | F39: 6 | G39: BR | H39: CARBINOX | I39: 79 | J39: =F39*I39 -> 474 | K39: AUT-2833 | L39: =F39/($F$39*3) -> 0.33333333 | M39: =L39*I39 -> 26.333333 | N39: =IFERROR(VLOOKUP(B39,Custo_MI_Infra!B:E,3,FALSE),0) -> 0 | O39: =N39*L39 -> 0 | P39: =O39*I39 -> 0
A40: 3014 | B40: Infra Eletrica de 1.1/2" | C40: 73072900 | D40: LUVA GF P/ ELETRODUTO 1.1/2"BSP | E40: 0 | F40: 2 | G40: PC | H40: CARBINOX | I40: 3.4 | J40: =F40*I40 -> 6.8 | K40: AUT-3014 | L40: =F40/($F$39*3) -> 0.11111111 | M40: =L40*I40 -> 0.37777778 | N40: =IFERROR(VLOOKUP(B40,Custo_MI_Infra!B:E,3,FALSE),0) -> 0 | O40: =N40*L40 -> 0 | P40: =O40*I40 -> 0
...

Sheet Lista explodida
A1: Descrição dos Materiais | B1: Unidade | C1: Quantidade
A2: BUCHA REDUCAO, ALUMINIO, 3/4 X 1/2 BSP | B2: PC | C2: 67
A3: BUCHA REDUCAO, ALUMINIO, 3/4 X 1/2 BSP | B3: PC | C3: 4
A4: BUCHA REDUCAO, ALUMINIO, 3/4 X 1/2 BSP | B4: PC | C4: 4
A5: BUCHA REDUCAO, ALUMINIO, 3/4 X 1/2 BSP | B5: PC | C5: 3
A6: BUCHA REDUCAO, ALUMINIO, 3/4 X 1/2 BSP | B6: PC | C6: 2
A7: BUCHA REDUCAO, ALUMINIO, 3/4 X 1/2 BSP | B7: PC | C7: 4
A8: BUCHA REDUCAO, ALUMINIO, 3/4 X 1/2 BSP | B8: PC | C8: 4
A9: BUJÃO C/ REBAIXO SEXTAVADO LATÃO 1/2"BSP | B9: PC | C9: 3
A10: BUJÃO C/ REBAIXO SEXTAVADO LATÃO 1/2"BSP | B10: PC | C10: 2
A11: BUJÃO C/ REBAIXO SEXTAVADO LATÃO 1/2"BSP | B11: PC | C11: 4
A12: CANTONEIRA, ACO A36, ABAS IGUAIS, 1.1/2 X 1/4 X 6.000MM, GERDAU | B12: KG | C12: 195
A13: CANTONEIRA, ACO A36, ABAS IGUAIS, 1.1/2 X 1/4 X 6.000MM, GERDAU | B13: KG | C13: 12
... A115: ARRUELA LISA ZC 1/4" | B115: PC | C115: 96
A116: ABRAÇADEIRA VERGALHÃO GRAMPO "U" ZC 1" X 1/4" | B116: PC | C116: 25 | E116: =ROUNDUP((C116/18)*50,0) -> 70
A117: BUCHA REDUÇÃO GF CL 150 1" X 1/2"BSP | B117: PC | C117: 3 | E117: =ROUNDUP((C117/18)*50,0) -> 9
A118: BUCHA REDUÇÃO GF CL 150 1" X 3/4"BSP | B118: PC | C118: 3 | E118: =ROUNDUP((C118/18)*50,0) -> 9
A119: BUCHA REDUÇÃO GF CL 150 1" X 3/8"BSP | B119: PC | C119: 3 | E119: =ROUNDUP((C119/18)*50,0) -> 9
A120: BUJÃO C/ REBORDO GF CL 150 1"BSP | B120: PC | C120: 3 | E120: =ROUNDUP((C120/18)*50,0) -> 9
A121: BUJÃO GF CL 150 1"BSP | B121: PC | C121: 3 | E121: =ROUNDUP((C121/18)*50,0) -> 9
A122: CANTONEIRA AÇO ABAS IGUAIS 1.1/2" X 1/4" X 6.000MM | B122: KG | C122: 10 | E122: =ROUNDUP((C122/18)*50,0) -> 28
A123: COTOVELO GF CL 150 1" BSP 45° | B123: PC | C123: 3 | E123: =ROUNDUP((C123/18)*50,0) -> 9
A124: COTOVELO GF CL 150 1" BSP 90° | B124: PC | C124: 3 | E124: =ROUNDUP((C124/18)*50,0) -> 9
A125: CRUZETA GF CL 150 1"BSP | B125: PC | C125: 3 | E125: =ROUNDUP((C125/18)*50,0) -> 9
A126: LUVA GF CL 150 1"BSP | B126: PC | C126: 3 | E126: =ROUNDUP((C126/18)*50,0) -> 9
A127: LUVA REDUÇÃO GF CL 150 1" X 1/2"BSP | B127: PC | C127: 3 | E127: =ROUNDUP((C127/18)*50,0) -> 9
... A161: VÁLVULA ESFERA TRIPARTIDA,CL 300 CORPO E TP A 216 WCB, ESFERA ASTM A351 CF8, PASS. REDUZIDA, VED. PTFE ROSCA 1/2" BSP | B161: PC | C161: 3 | E161: =ROUNDUP((C161/18)*50,0) -> 9
A162: ABRAÇADEIRA VERGALHÃO GRAMPO "U" ZC 2" X 1/4" | B162: PC | C162: 50 | E162: =ROUNDUP((C162/18)*150,0) -> 417
A163: ARRUELA LISA ZC 1/4" | B163: PC | C163: 100 | E163: =ROUNDUP((C163/18)*150,0) -> 834
A164: BUCHA REDUÇÃO GF CL 150 2" X 1"BSP | B164: PC | C164: 9 | E164: =ROUNDUP((C164/18)*150,0) -> 75
A165: BUCHA REDUÇÃO GF CL 150 2" X 1.1/2"BSP | B165: PC | C165: 9 | E165: =ROUNDUP((C165/18)*150,0) -> 75
A166: BUCHA REDUÇÃO GF CL 150 2" X 1/2" BSP | B166: PC | C166: 9 | E166: =ROUNDUP((C166/18)*150,0) -> 75
A167: BUJÃO C/ REBORDO GF CL 150 2"BSP | B167: PC | C167: 9 | E167: =ROUNDUP((C167/18)*150,0) -> 75
A168: BUJÃO GF CL 150 2"BSP | B168: PC | C168: 9 | E168: =ROUNDUP((C168/18)*150,0) -> 75
A169: CANTONEIRA AÇO ABAS IGUAIS 1.1/2" X 1/4" X 6.000MM | B169: KG | C169: 29 | E169: =ROUNDUP((C169/18)*150,0) -> 242
A170: COTOVELO GF CL 150 2" BSP 45° | B170: PC | C170: 9 | E170: =ROUNDUP((C170/18)*150,0) -> 75
A171: COTOVELO GF CL 150 2" BSP 90° | B171: PC | C171: 9 | E171: =ROUNDUP((C171/18)*150,0) -> 75
A172: CRUZETA GF CL 150 2"BSP | B172: PC | C172: 9 | E172: =ROUNDUP((C172/18)*150,0) -> 75
A173: LUVA GF CL 150 2"BSP | B173: PC | C173: 9 | E173: =ROUNDUP((C173/18)*150,0) -> 75
... A188: VALVULA ESFERA TRIPARTIDA,CL 300 CORPO E TP A 216 WCB, ESFERA ASTM A351 CF8, HASTE AISI 304, VED. PTFE ROSCA 2" BSP | B188: PC | C188: 9 | E188: =ROUNDUP((C188/18)*150,0) -> 75
...

Sheet Tab Din Device
A1: Rótulos de Linha
A2: ABRACADEIRA VERGALHAO GRAMPO U ZC 1/2 X 1/4 DP 634-1 DISPAN
A3: ABRACADEIRA VERGALHAO GRAMPO U ZC 1/4 X 1/4 DP 634-0 DISPAN
A4: ABRACADEIRA VERGALHAO GRAMPO U ZC 2 X 1/4 DP 634-6 DISPAN
A5: ABRACADEIRA VERGALHAO GRAMPO U ZC 3/4 X 1/4 DP 634-2 DISPAN
A6: ABRACADEIRA, NYLON PRETA, 2,5 X 101MM, T-18 R, HELLERMANN
A7: ARRUELA ACABAMENTO, ALUMINIO, 1 BSP
A8: ARRUELA ACABAMENTO, ALUMINIO, 2 BSP
A9: ARRUELA LISA ZC 1/4"
A10: ARRUELA LISA ZC 3/16"
A11: BUCHA ACABAMENTO ALUMINIO 2BSP BU-200-B DAISA
A12: BUCHA ACABAMENTO ALUMÍNIO 3/4"BSP
... A96: Total Geral

Sheet Tab Din Infra
A1: Rótulos de Linha
A2: ABRAÇADEIRA VERGALHÃO GRAMPO "U" ZC 1" X 1/4"
A3: ABRAÇADEIRA VERGALHÃO GRAMPO "U" ZC 1.1/2" X 1/4"
A4: ABRAÇADEIRA VERGALHÃO GRAMPO "U" ZC 1/2" X 1/4"
A5: ABRAÇADEIRA VERGALHÃO GRAMPO "U" ZC 2" X 1/4"
A6: ABRAÇADEIRA VERGALHÃO GRAMPO "U" ZC 3/4" X 1/4"
A7: ARRUELA ACABAMENTO ALUMÍNIO 1"BSP
A8: ARRUELA ACABAMENTO ALUMÍNIO 1.1/2"BSP
A9: ARRUELA ACABAMENTO ALUMÍNIO 2"BSP
A10: ARRUELA ACABAMENTO ALUMÍNIO 3/4"BSP
A11: ARRUELA ACABAMENTO EX-D FERRO NODULAR GF 1" NPT
A12: ARRUELA ACABAMENTO EX-D FERRO NODULAR GF 1.1/2" NPT
... A207: Total Geral

Sheet Geral
A1: Rótulos de Linha
A2: ABRACADEIRA VERGALHAO GRAMPO U ZC 1/2 X 1/4 DP 634-1 DISPAN
A3: ABRACADEIRA VERGALHAO GRAMPO U ZC 1/4 X 1/4 DP 634-0 DISPAN
A4: ABRACADEIRA VERGALHAO GRAMPO U ZC 2 X 1/4 DP 634-6 DISPAN
A5: ABRACADEIRA VERGALHAO GRAMPO U ZC 3/4 X 1/4 DP 634-2 DISPAN
A6: ABRACADEIRA, NYLON PRETA, 2,5 X 101MM, T-18 R, HELLERMANN
A7: ARRUELA ACABAMENTO, ALUMINIO, 1 BSP
A8: ARRUELA ACABAMENTO, ALUMINIO, 2 BSP
A9: ARRUELA LISA ZC 1/4"
A10: ARRUELA LISA ZC 3/16"
A11: BUCHA ACABAMENTO ALUMINIO 2BSP BU-200-B DAISA
A12: BUCHA ACABAMENTO ALUMÍNIO 3/4"BSP
... A300: VERGALHÃO ROSCA TOTAL ZC 5/16" X 3000MM

Sheet Tab Din Geral
A1: Rótulos de Linha
A2: ABRAÇADEIRA VERGALHÃO GRAMPO "U" ZC 1" X 1/4"
A3: ABRAÇADEIRA VERGALHÃO GRAMPO "U" ZC 1.1/2" X 1/4"
A4: ABRAÇADEIRA VERGALHÃO GRAMPO "U" ZC 1/2" X 1/4"
A5: ABRAÇADEIRA VERGALHÃO GRAMPO "U" ZC 2" X 1/4"
A6: ABRAÇADEIRA VERGALHÃO GRAMPO "U" ZC 3/4" X 1/4"
A7: ABRACADEIRA VERGALHAO GRAMPO U ZC 1/2 X 1/4 DP 634-1 DISPAN
A8: ABRACADEIRA VERGALHAO GRAMPO U ZC 1/4 X 1/4 DP 634-0 DISPAN
A9: ABRACADEIRA VERGALHAO GRAMPO U ZC 2 X 1/4 DP 634-6 DISPAN
A10: ABRACADEIRA VERGALHAO GRAMPO U ZC 3/4 X 1/4 DP 634-2 DISPAN
A11: ABRACADEIRA, NYLON PRETA, 2,5 X 101MM, T-18 R, HELLERMANN
A12: ARRUELA ACABAMENTO ALUMÍNIO 1"BSP
... A267: Total Geral

Sheet Cotação
A1: Rótulos de Linha
A2: ABRACADEIRA VERGALHAO GRAMPO U ZC 1/4 X 1/4 DP 634-0 DISPAN
A3: ABRACADEIRA VERGALHAO GRAMPO U ZC 1/2 X 1/4 DP 634-1 DISPAN
A4: ABRACADEIRA VERGALHAO GRAMPO U ZC 3/4 X 1/4 DP 634-2 DISPAN
A5: ABRAÇADEIRA VERGALHÃO GRAMPO "U" ZC 1" X 1/4"
A6: ABRAÇADEIRA VERGALHÃO GRAMPO "U" ZC 1.1/2" X 1/4"
A7: ABRACADEIRA VERGALHAO GRAMPO U ZC 2 X 1/4 DP 634-6 DISPAN
A8: ABRACADEIRA, NYLON PRETA, 2,5 X 101MM, T-18 R, HELLERMANN
A9: ARRUELA ACABAMENTO ALUMÍNIO 3/4"BSP
A10: ARRUELA ACABAMENTO ALUMÍNIO 1"BSP
A11: ARRUELA ACABAMENTO ALUMÍNIO 1.1/2"BSP
A12: ARRUELA ACABAMENTO ALUMÍNIO 2"BSP
... A247: VERGALHÃO ROSCA TOTAL ZC 5/16" X 3000MM
