Workbook
Name Administrativo_Custo_Fx: '[1]Cockpit Retorno'!$D$41
Name Atendentes_Instr_Campo_QT: '[1]Calc Eng'!$B$53
Name Atendentes_Senior_QT: '[1]Calc Eng'!$B$51
Name Atendentes_Sistema_Processo_QT: '[1]Calc Eng'!$B$52
Name Atendentes_Total: '[1]Calc Eng'!$B$28
Name ATK_INTEG: SUM('[1]Resumo_HIA_HIC_HOC '!$Q$6:$Q$8)
Name ATK_LOG: '[1]Resumo_HIA_HIC_HOC '!$E$13
Name ATK_LOG_INT: '[1]Resumo_HIA_HIC_HOC '!$F$13
Name ATK_LOG_MOB: '[1]Resumo_HIA_HIC_HOC '!$G$13
Name ATK_MOA: '[1]Resumo_HIA_HIC_HOC '!$E$6
Name ATK_MOA_INT: '[1]Resumo_HIA_HIC_HOC '!$F$6
Name ATK_MOA_MOB: '[1]Resumo_HIA_HIC_HOC '!$G$6
Name ATK_MOB: '[1]Resumo_HIA_HIC_HOC '!$L$12
Name ATK_MOD: '[1]Resumo_HIA_HIC_HOC '!$E$8
Name ATK_MOD_INT: '[1]Resumo_HIA_HIC_HOC '!$F$8
Name ATK_MOD_MOB: '[1]Resumo_HIA_HIC_HOC '!$G$8
Name ATK_MOI: '[1]Resumo_HIA_HIC_HOC '!$E$7
Name ATK_MOI_INT: '[1]Resumo_HIA_HIC_HOC '!$F$7
Name ATK_MOI_MOB: '[1]Resumo_HIA_HIC_HOC '!$G$7
Name ATK_periculosidade: '[1]Resumo_HIA_HIC_HOC '!$E$10
Name ATK_Serviços: '[1]Cockpit Retorno'!$L$2
Name ATK_SSMA: '[1]Resumo_HIA_HIC_HOC '!$L$11
Name ATK_Turnover: '[1]Resumo_HIA_HIC_HOC '!$E$9
Name Base_REAJUSTE_MOD_E_MOI: '[1]Custo MO Impostos Obras'!$F$6
Name BDI: [1]BDI!$G$24
Name C_ADM_Geral: 0.1
Name Capital_Giro_ATM: '[1]Cockpit Retorno'!$C$42
Name Capital_Giro_Passivo_BNC_Passivo_Tributario_Tarifas_Advogados: '[1]Cockpit Retorno'!$AFR$174
Name Capital_Giro_Passivo_Custo_Fx: '[1]Cockpit Retorno'!$D$42
Name Casa_Total_Ocupantes: [1]TESTE_LOG_OBRA!$J$38
Name Cesta_Básica_Total: '[1]Resumo_HIA_HIC_HOC '!$G$23
Name Cofins__ATK: [1]Impostos_Taxas_ICMs!$I$31
Name Cofins__Sistema: [1]Impostos_Taxas_ICMs!$H$31
Name COFINS_lOG_MOB: [1]Impostos_Taxas_ICMs!$K$25
Name COFINS_M_S: [1]Impostos_Taxas_ICMs!$H$6
Name Comercial_Custo_Fx: '[1]Cockpit Retorno'!$AFB$174
Name Conteiner_Aluguel_Mes: '[1]Calc Eng'!$B$44
Name Contratação_LOG_Integração_Cliente: [1]HIC_Histograma_Integra_Cliente!$I$51
Name Contratação_Total__Logística: [1]HIA_Histograma_Integração_ATM!$J$51
Name CSLL: [1]Impostos_Taxas_ICMs!$H$28
Name Custo_Comercial__Plus: '[1]Cockpit Retorno'!$C$38
Name Custo_comercial_1: '[1]Cockpit Retorno'!$C$37
Name Custo_Contingência: '[1]Cockpit Retorno'!$C$45
Name Custo_Financeiro_Exclusivo_do_Contrato: '[1]Cockpit Retorno'!$C$43
Name Custo_fixo___Administrativo__Cartões__Carros__Manutenção__Custo_Consumo_interno__SSMA_interno__Alugueis__Luz__Água__Internet_Telefone__Material_escritório__Aquisições_Extra_OS__Totvs__Softwares: '[1]Cockpit Retorno'!$AFK$174
Name Custo_fixo_Adminstrativo: '[1]Cockpit Retorno'!$C$41
Name Custo_Impostos_Credito__Débito: '[1]Cockpit Retorno'!$K$32
Name Custo_Total: '[1]Cockpit Retorno'!$C$47
Name Custos_Viagens__Feiras__Marketing__Filiais: '[1]Cockpit Retorno'!$AFB$171
Name Debito_Impostos: '[1]Cockpit Retorno'!$K$32
Name Diária_Casa_Custo_Atendente: '[1]Calc Eng'!$B$3
Name Diária_Casa_Geral: '[1]Calc Eng'!$B$4
Name Diária_Completa_Sem_Transporte: '[1]Calc Eng'!$B$42
Name Diárias_Hotel_Avulsas_Custo: '[1]Calc Eng'!$B$5
Name Diárias_Hotel_Negociada_Custo: '[1]Calc Eng'!$B$6
Name Dias_Campo: '[1]Calc Eng'!$B$33
Name Dificuldade_Projeto: '[1]Calc Eng'!$K$68
Name Distância_Base_PLANTA: '[1]Calc Eng'!$B$38
Name Distância_STZ_BASE: '[1]Calc Eng'!$B$37
Name Dolar_Referencia: '[1]Cockpit Retorno'!$C$48

Sheet THEO
X5: Dias
X6: Dispositivo
X7: Driver
X8: Instrumento
X9: JB
X10: kg
X11: L
X12: m²
X13: m³
X14: Malhas contr.
X15: ml
X16: Motores
... X25: um
AC41: Profissionais
AC42: 1
AC43: 1.5
AC44: 2
AC45: 2.5
AC46: 3
AC47: 4
AC48: 5
AC49: 6
AC50: 7
AC51: 8
AC52: 9
AC53: 10
... AC63: 20
AL64: 0
AL65: 0.05
AI66: Alta | AJ66: 0.005 | AL66: 0.1
AI67: Extremamente Alta | AJ67: 0.02 | AL67: 0.15
AI68: Muito Alta | AJ68: 0.01 | AL68: 0.2
AI69: Esperado | AJ69: 0 | AL69: 0.25
AL70: 0.3
AL71: 0.35
AL72: 0.4
AJ73: Alta complexidade | AK73: 0.05 | AL73: 0.45
AJ74: Critica_Complicada | AK74: 0.03 | AL74: 0.5
AJ75: Critica_Rapida | AK75: 0.02 | AL75: 0.55
AJ76: Normal | AK76: 0 | AL76: 0.6
...
