Workbook
Name AREA: #REF!
Name CLIENTE: #REF!
Name CODIFICAÇÃO: #REF!
Name DOCUMENTO: #REF!
Name os: #REF!
Name PROJETO: #REF!
Name REVISAO: #REF!
Name TITULO: #REF!

Sheet LISTA
B1: Código | C1: Descricao NF | D1: Unidade | E1: ESTOQUE | F1: Tipo
A2: =VALUE(B2) -> 1 | B2: 000001 | C2: DESPESAS C/ PASSAGENS AEREAS | D2: UN | F2: MC
A3: =VALUE(B3) -> 2 | B3: 000002 | C3: PLATAFORMA AREA DE TRABALHO | D3: UN | F3: AI
A4: =VALUE(B4) -> 3 | B4: 000003 | C4: ISOLADOR DE SINAIS ANALOGICOS IS-5000 SERVICES | D4: PC | F4: EE
A5: =VALUE(B5) -> 4 | B5: 000004 | C5: SENSOR PT-100, 03 FIOS, BAINHA 6MM A304, CABECOTE TEMPO, CONEXAO ELETR. E PROC.1/2NPT, U=150, T=100, N=100MM CONSISTEC | D5: PC | E5: 0 | F5: IS
A6: =VALUE(B6) -> 5 | B6: 000005 | C6: CHAVE SECCIONADORA, BASE FUSIVEL, TAM. 00, 160A ERGONFUSE 160 SIEMENS | D6: PC | F6: MI
A7: =VALUE(B7) -> 6 | B7: 000006 | C7: RETALHOS DE CHAPAS DE ACO | D7: KG | F7: MC
A8: =VALUE(B8) -> 7 | B8: 000007 | C8: RETALHOS DE FERRO | D8: KG | F8: MC
A9: =VALUE(B9) -> 8 | B9: 000008 | C9: MODULO CONTAINER HABITAVEL, VAO LIVRE, REVESTIDO, MED. 6 X 2,30 MT | D9: UN | F9: MF
A10: =VALUE(B10) -> 9 | B10: 000009 | C10: CURVA VERTICAL EXTERNA P/ LEITO, MEDIO, VIROLA EXTERNA 19MM, GF, CHAPA #16/18, R320, 90 G, 300 X 100MM | D10: PC | F10: MI
A11: =VALUE(B11) -> 10 | B11: 000010 | C11: PLACA DE MONTAGEM P/ ESTRUTURA, LJ. 2,5YR6/14, CHAPA #12, MED. 1820 X 1140 MM | D11: PC | F11: OI
A12: =VALUE(B12) -> 11 | B12: 000011 | C12: CONECTOR RETO UNIAO ASTM A276 INOX 316 TP C CL 6500 PSI 1/2OD X 1/2OD F. MASTER | D12: PC | F12: MI
A13: =VALUE(B13) -> 12 | B13: 000012 | C13: MINI-VALVULA AGULHA, INT. ASTM A276 INOX 316, EXT. INOX 316 MICROF. CF8M, 6500 PSI, VED.TEFLON,3/8OD 206-T-316 TRIUNION | D13: PC | F13: IS
A14: =VALUE(B14) -> 13 | B14: 000013 | C14: IMPRESSORA, MULTIFUNCIONAL, MONOCROMATICA, LASER, DCP-1512, BROTHER | D14: PC | F14: AI
A15: =VALUE(B15) -> 14 | B15: 000014 | C15: CARTUCHO DE TONER PRETO, 1000 IMPRESSOES, TN-1060, BROTHER | D15: PC | F15: TI
A16: =VALUE(B16) -> 15 | B16: 000015 | C16: PLACA DE POLICARBONATO, MED. 1,00 MT X 1,50 MT X 2,00 MM | D16: PC | F16: OI
A17: =VALUE(B17) -> 16 | B17: 000016 | C17: CARRETINHA C/ ENGATE, ABERTA, LATERAL MADEIRA, CAP. 750 KG, PRETO, MED. 2 X 1,20 MT, C/ 02 PNEUS ARO 13, POLI | D17: UN | F17: AI
... A11844: =VALUE(B11844) -> 11843 | B11844: 011843 | C11844: DESPESAS C/ AGUA E ESGOTO | D11844: M3 | F11844: MC
A11845: =VALUE(B11845) -> 11844 | B11845: 011844 | C11845: DESPESAS C/ ENERGIA ELETRICA | D11845: W
A11846: =VALUE(B11846) -> 11845 | B11846: 011845 | C11846: SACO P/ LIXO 40 LT, PLASZOM | D11846: UN | F11846: MC
A11847: =VALUE(B11847) -> 11846 | B11847: 011846 | C11847: PA P/ LIXO | D11847: UN | F11847: MC
A11848: =VALUE(B11848) -> 11847 | B11848: 011847 | C11848: RETENTOR P/ VEICULOS | D11848: PC | F11848: MC
A11849: =VALUE(B11849) -> 11848 | B11849: 011848 | C11849: PROTETOR DA CORREIA DO ALTERNADOR | D11849: PC | F11849: MC
A11850: =VALUE(B11850) -> 11849 | B11850: 011849 | C11850: FILTRO DE COMBUSTIVEL P/ VEICULO | D11850: PC | F11850: MC
A11851: =VALUE(B11851) -> 11850 | B11851: 011850 | C11851: SILENCIOSO P/ VEICULO | D11851: PC | F11851: MC
A11852: =VALUE(B11852) -> 11851 | B11852: 011851 | C11852: VELA DE IGNICAO, P/ VEICULO | D11852: PC | F11852: MC
A11853: =VALUE(B11853) -> 11852 | B11853: 011852 | C11853: FILTRO DE AR P/ VEICULO | D11853: PC | F11853: MC
A11854: =VALUE(B11854) -> 11853 | B11854: 011853 | C11854: FILTRO DE OLEO P/ VEICULO | D11854: PC | F11854: MC
A11855: =VALUE(B11855) -> 11854 | B11855: 011854 | C11855: LIMPADOR PARABRISA P/ VEICULO | D11855: PC | F11855: MC
A11856: =VALUE(B11856) -> 11855 | B11856: 011855 | C11856: SENSOR KIT ESTACIONAMENTO, RE P/ VEICULO | D11856: PC | F11856: MC
A11857: =VALUE(B11857) -> 11856 | B11857: 011856 | C11857: RODA DE FERRO ARO14 | D11857: PC | F11857: MC
... A13406: =VALUE(B13406) -> 23922 | B13406: 023922 | C13406: PARAFUSO CABECA SEXTAVADA, ROSCA PARCIAL, ACO G5, EN, 7/8 X 6 POL. | D13406: PC | F13406: MI
A13407: =VALUE(B13407) -> 0
A13408: =VALUE(B13408) -> 0
A13409: =VALUE(B13409) -> 0
A13410: =VALUE(B13410) -> 0
A13411: =VALUE(B13411) -> 0
A13412: =VALUE(B13412) -> 0
A13413: =VALUE(B13413) -> 0
A13414: =VALUE(B13414) -> 0
...

Sheet Encaminhamento
A1: Código | B1: Descricao NF | C1: Unidade | D1: Quant | E1: Categoria | F1: Est. Mínimo | G1: Fabricante | H1: NCM | I1: CEST | J1: Ind. Origem | K1: Tipo Custódia | L1: Preço Custo | M1: Lote | N1: Classif. Fiscal | O1: Cód. Barras
A2: =IFERROR(_xlfn.XLOOKUP(B2,LISTA!C:C,LISTA!B:B,""),"") -> 000009 | B2: CURVA VERTICAL EXTERNA P/ LEITO, MEDIO, VIROLA EXTERNA 19MM, GF, CHAPA #16/18, R320, 90 G, 300 X 100MM | C2: PC | D2: 6 | E2: =IFERROR(_xlfn.XLOOKUP(B2,LISTA!C:C,LISTA!F:F,""),"") -> MI | F2: 66 | G2: DISPAN | H2: 73089010 | I2: 1004100 | J2: 0 - Nacional | K2: Próprio | L2: 207.97 | M2: L20251218 | N2: II - 73089010 | O2: 7897813895198
A3: =IFERROR(_xlfn.XLOOKUP(B3,LISTA!C:C,LISTA!B:B,""),"") -> 000062 | B3: ABRACADEIRA TIPO OMEGA GF 1.1/2 DP 632-5 DISPAN | C3: PC | D3: 469 | E3: =IFERROR(_xlfn.XLOOKUP(B3,LISTA!C:C,LISTA!F:F,""),"") -> MI | F3: 60 | G3: DISPAN | H3: 73269090 | I3: 1005000 | J3: 0 - Nacional | K3: Próprio | L3: 4.7 | M3: L20250815 | N3: II - 73269090 | O3: 7896690099645
A4: =IFERROR(_xlfn.XLOOKUP(B4,LISTA!C:C,LISTA!B:B,""),"") -> 000069 | B4: CONDULETE, ROSCAVEL, ALUMINIO, C/ TAMPA, JUNTA VEDACAO, 2 BSP, TIPO C | C4: PC | D4: 250 | E4: =IFERROR(_xlfn.XLOOKUP(B4,LISTA!C:C,LISTA!F:F,""),"") -> MI | F4: 12 | H4: 76090000 | I4: 1004100 | J4: 0 - Nacional | K4: Próprio | L4: 42.1 | M4: L20250511 | N4: II - 76090000 | O4: 7899863300688
A5: =IFERROR(_xlfn.XLOOKUP(B5,LISTA!C:C,LISTA!B:B,""),"") -> 000071 | B5: UNIDUT CONICO, ROSCA LONGA, ALUMINIO, C/ PARAFUSO, 1 POL. | C5: PC | D5: 304 | E5: =IFERROR(_xlfn.XLOOKUP(B5,LISTA!C:C,LISTA!F:F,""),"") -> MI | F5: 66 | H5: 76090000 | I5: 1004800 | J5: 0 - Nacional | K5: Próprio | L5: 8.93 | M5: L20250416 | N5: II - 76090000 | O5: 7897464892369
A6: =IFERROR(_xlfn.XLOOKUP(B6,LISTA!C:C,LISTA!B:B,""),"") -> 000074 | B6: BUCHA REDUCAO, EX-D, FERRO NODULAR, GF, GR. IIA/IIB OU IIC ZN. 1 OU 2, 1 X 1/2 NPT | C6: PC | D6: 97 | E6: =IFERROR(_xlfn.XLOOKUP(B6,LISTA!C:C,LISTA!F:F,""),"") -> MI | F6: 5 | H6: 73071920 | I6: 1004800 | J6: 0 - Nacional | K6: Controlado | L6: 60.43 | M6: L20250911 | N6: II - 73071920 | O6: 7897487071858
A7: =IFERROR(_xlfn.XLOOKUP(B7,LISTA!C:C,LISTA!B:B,""),"") -> 000075 | B7: ELETRODUTO SEMIPESADO, C/ COSTURA, ACO CARBONO, G.F, NBR 5624, C/ LUVA, 1 X 3000MM BSP | C7: PC | D7: 476 | E7: =IFERROR(_xlfn.XLOOKUP(B7,LISTA!C:C,LISTA!F:F,""),"") -> MI | F7: 26 | H7: 73063000 | I7: 1004100 | J7: 0 - Nacional | K7: Próprio | L7: 121.68 | M7: L20250821 | N7: II - 73063000 | O7: 7894278691813
A8: =IFERROR(_xlfn.XLOOKUP(B8,LISTA!C:C,LISTA!B:B,""),"") -> 000076 | B8: BUCHA TERMINAL S/ ROSCA ZC P/ ELETRODUTO DIN 3/4 BT 034-D DAISA | C8: PC | D8: 92 | E8: =IFERROR(_xlfn.XLOOKUP(B8,LISTA!C:C,LISTA!F:F,""),"") -> MI | F8: 33 | G8: DAISA | H8: 73269090 | I8: 1004100 | J8: 0 - Nacional | K8: Próprio | L8: 3.38 | M8: L20251028 | N8: II - 73269090 | O8: 7899640294620
A9: =IFERROR(_xlfn.XLOOKUP(B9,LISTA!C:C,LISTA!B:B,""),"") -> 000078 | B9: CONECTOR FIXO, REUSAVEL, ALUMINIO, MACHO, P/ ELETRODUTO FLEXIVEL DE ACO REVEST. PVC, ROSCA 3 BSP | C9: PC | D9: 304 | E9: =IFERROR(_xlfn.XLOOKUP(B9,LISTA!C:C,LISTA!F:F,""),"") -> MI | F9: 15 | H9: 39173900 | I9: 1004100 | J9: 0 - Nacional | K9: Próprio | L9: 6.32 | M9: L20250303 | N9: II - 39173900 | O9: 7893727069371
A10: =IFERROR(_xlfn.XLOOKUP(B10,LISTA!C:C,LISTA!B:B,""),"") -> 000084 | B10: CONDULETE ROSCAVEL EM ALUMINIO C/ TAMPA 1BSP TIPO E DIIRT 100-BSP-E DAISA | C10: PC | D10: 411 | E10: =IFERROR(_xlfn.XLOOKUP(B10,LISTA!C:C,LISTA!F:F,""),"") -> MI | F10: 16 | G10: DAISA | H10: 76090000 | I10: 1004100 | J10: 0 - Nacional | K10: Próprio | L10: 55.04 | M10: L20250821 | N10: II - 76090000 | O10: 7892996147553
A11: =IFERROR(_xlfn.XLOOKUP(B11,LISTA!C:C,LISTA!B:B,""),"") -> 000085 | B11: CONDULETE ROSCAVEL EM ALUMINIO FUNDIDO EX-D C/ TAMPA 2NPT TIPO LB TCLX/6-LB TELBRA | C11: PC | D11: 195 | E11: =IFERROR(_xlfn.XLOOKUP(B11,LISTA!C:C,LISTA!F:F,""),"") -> MI | F11: 55 | G11: TELBRA | H11: 76090000 | I11: 1004100 | J11: 0 - Nacional | K11: Controlado | L11: 166.74 | M11: L20251110 | N11: II - 76090000 | O11: 7898859844908
A12: =IFERROR(_xlfn.XLOOKUP(B12,LISTA!C:C,LISTA!B:B,""),"") -> 000088 | B12: BUCHA REDUCAO, GF, CL 150, 1 X 1/2BSP | C12: PC | D12: 251 | E12: =IFERROR(_xlfn.XLOOKUP(B12,LISTA!C:C,LISTA!F:F,""),"") -> MI | F12: 46 | H12: 73071100 | I12: 1004800 | J12: 0 - Nacional | K12: Próprio | L12: 10.92 | M12: L20251016 | N12: II - 73071100 | O12: 7899698210949
A13: =IFERROR(_xlfn.XLOOKUP(B13,LISTA!C:C,LISTA!B:B,""),"") -> 000089 | B13: BUCHA REDUCAO, GF CL 150, 2 X 1BSP | C13: PC | D13: 86 | E13: =IFERROR(_xlfn.XLOOKUP(B13,LISTA!C:C,LISTA!F:F,""),"") -> MI | F13: 30 | H13: 73071100 | I13: 1004800 | J13: 0 - Nacional | K13: Próprio | L13: 5.05 | M13: L20250907 | N13: II - 73071100 | O13: 7891228082962
A14: =IFERROR(_xlfn.XLOOKUP(B14,LISTA!C:C,LISTA!B:B,""),"") -> 000091 | B14: CONDULETE ROSCAVEL EM ALUMINIO C/ TAMPA 2.1/2BSP TIPO LB DIIRT 212-BSP-LB DAISA | C14: PC | D14: 347 | E14: =IFERROR(_xlfn.XLOOKUP(B14,LISTA!C:C,LISTA!F:F,""),"") -> MI | F14: 8 | G14: DAISA | H14: 76090000 | I14: 1004100 | J14: 0 - Nacional | K14: Próprio | L14: 77.43 | M14: L20250410 | N14: II - 76090000 | O14: 7899663496369
A15: =IFERROR(_xlfn.XLOOKUP(B15,LISTA!C:C,LISTA!B:B,""),"") -> 000093 | B15: CAIXA DE INSPECAO SUSPENSA, POLIAMIDA, 123 X 158 MM, 1 BSP, TEL-541, TERMOTECNICA | C15: PC | D15: 91 | E15: =IFERROR(_xlfn.XLOOKUP(B15,LISTA!C:C,LISTA!F:F,""),"") -> MI | F15: 78 | G15: TERMOTECNICA | H15: 39259090 | I15: 1004100 | J15: 0 - Nacional | K15: Próprio | L15: 32.47 | M15: L20250414 | N15: II - 39259090 | O15: 7891894778612
A16: =IFERROR(_xlfn.XLOOKUP(B16,LISTA!C:C,LISTA!B:B,""),"") -> 000094 | B16: BUCHA ACABAMENTO, FERRO NODULAR, GE, 2 NPT | C16: PC | D16: 96 | E16: =IFERROR(_xlfn.XLOOKUP(B16,LISTA!C:C,LISTA!F:F,""),"") -> MI | F16: 61 | H16: 73089010 | I16: 1004800 | J16: 0 - Nacional | K16: Próprio | L16: 14.84 | M16: L20251103 | N16: II - 73089010 | O16: 7893668589711
A17: =IFERROR(_xlfn.XLOOKUP(B17,LISTA!C:C,LISTA!B:B,""),"") -> 000096 | B17: BUCHA ACABAMENTO EX-D FERRO NODULAR GF 1 NPT CX / BF-3 FG CONEX | C17: PC | D17: 465 | E17: =IFERROR(_xlfn.XLOOKUP(B17,LISTA!C:C,LISTA!F:F,""),"") -> MI | F17: 79 | G17: CONEX | H17: 73071920 | I17: 1004800 | J17: 0 - Nacional | K17: Controlado | L17: 38.27 | M17: L20250507 | N17: II - 73071920 | O17: 7897698136660
A18: =IFERROR(_xlfn.XLOOKUP(B18,LISTA!C:C,LISTA!B:B,""),"") -> 000098 | B18: BUCHA ACABAMENTO EX-D FERRO NODULAR GF 2.1/4 NPT CX / BF-7 FG CONEX | C18: PC | D18: 140 | E18: =IFERROR(_xlfn.XLOOKUP(B18,LISTA!C:C,LISTA!F:F,""),"") -> MI | F18: 8 | G18: CONEX | H18: 73071920 | I18: 1004800 | J18: 0 - Nacional | K18: Controlado | L18: 73.56 | M18: L20250619 | N18: II - 73071920 | O18: 7896327459724
A19: =IFERROR(_xlfn.XLOOKUP(B19,LISTA!C:C,LISTA!B:B,""),"") -> 000100 | B19: ARRUELA ACABAMENTO, ALUMINIO, 3 BSP | C19: PC | D19: 94 | E19: =IFERROR(_xlfn.XLOOKUP(B19,LISTA!C:C,LISTA!F:F,""),"") -> MI | F19: 54 | H19: 76090000 | I19: 1004800 | J19: 0 - Nacional | K19: Próprio | L19: 4.33 | M19: L20250521 | N19: II - 76090000 | O19: 7893098240635
A20: =IFERROR(_xlfn.XLOOKUP(B20,LISTA!C:C,LISTA!B:B,""),"") -> 000101 | B20: PORCA ACABAMENTO ALUMINIO 2.1/2BSP PU-212-BSP DAISA | C20: PC | D20: 59 | E20: =IFERROR(_xlfn.XLOOKUP(B20,LISTA!C:C,LISTA!F:F,""),"") -> MI | F20: 34 | G20: DAISA | H20: 76090000 | I20: 1004800 | J20: 0 - Nacional | K20: Próprio | L20: 8.86 | M20: L20250410 | N20: II - 76090000 | O20: 7896743921166
A21: =IFERROR(_xlfn.XLOOKUP(B21,LISTA!C:C,LISTA!B:B,""),"") -> 000102 | B21: ARRUELA ACABAMENTO EX-D FERRO NODULAR GF 2 NPT CX / AR-6 FG CONEX | C21: PC | D21: 438 | E21: =IFERROR(_xlfn.XLOOKUP(B21,LISTA!C:C,LISTA!F:F,""),"") -> MI | F21: 48 | G21: CONEX | H21: 73071920 | I21: 1004800 | J21: 0 - Nacional | K21: Controlado | L21: 8.78 | M21: L20251127 | N21: II - 73071920 | O21: 7891560673864
A22: =IFERROR(_xlfn.XLOOKUP(B22,LISTA!C:C,LISTA!B:B,""),"") -> 000107 | B22: ELETROCALHA FUNDO PERFURADO C/ VIROLA LATERAL 18AWG GF, TAMPA PRESSAO 2 AGUAS 300X100X3000MM DP 703 DISPAN | C22: BR | D22: 54 | E22: =IFERROR(_xlfn.XLOOKUP(B22,LISTA!C:C,LISTA!F:F,""),"") -> MI | F22: 42 | G22: DISPAN | H22: 73089010 | I22: 1004100 | J22: 0 - Nacional | K22: Próprio | L22: 154.85 | M22: L20250803 | N22: II - 73089010 | O22: 7896927469183
A23: =IFERROR(_xlfn.XLOOKUP(B23,LISTA!C:C,LISTA!B:B,""),"") -> 000111 | B23: ABRACADEIRA VERGALHAO, GRAMPO U, GE, C/ PORCAS E ARRUELAS, 3 X 5/16 POL. | C23: PC | D23: 494 | E23: =IFERROR(_xlfn.XLOOKUP(B23,LISTA!C:C,LISTA!F:F,""),"") -> MI | F23: 68 | H23: 73269090 | I23: 1005000 | J23: 0 - Nacional | K23: Próprio | L23: 6.69 | M23: L20250902 | N23: II - 73269090 | O23: 7899185943741
A24: =IFERROR(_xlfn.XLOOKUP(B24,LISTA!C:C,LISTA!B:B,""),"") -> 000112 | B24: ABRACADEIRA VERGALHAO GRAMPO U GF 2 X 3/8 DP 634-6 DISPAN | C24: PC | D24: 305 | E24: =IFERROR(_xlfn.XLOOKUP(B24,LISTA!C:C,LISTA!F:F,""),"") -> MI | F24: 15 | G24: DISPAN | H24: 73269090 | I24: 1005000 | J24: 0 - Nacional | K24: Próprio | L24: 5.23 | M24: L20250222 | N24: II - 73269090 | O24: 7899838670566
A25: =IFERROR(_xlfn.XLOOKUP(B25,LISTA!C:C,LISTA!B:B,""),"") -> 000113 | B25: ABRACADEIRA VERGALHAO GRAMPO U GF 1.1/2 X 5/16 DP 634-5 DISPAN | C25: PC | D25: 181 | E25: =IFERROR(_xlfn.XLOOKUP(B25,LISTA!C:C,LISTA!F:F,""),"") -> MI | F25: 80 | G25: DISPAN | H25: 73269090 | I25: 1005000 | J25: 0 - Nacional | K25: Próprio | L25: 13.83 | M25: L20250925 | N25: II - 73269090 | O25: 7898158672226
A26: =IFERROR(_xlfn.XLOOKUP(B26,LISTA!C:C,LISTA!B:B,""),"") -> 000114 | B26: ABRACADEIRA VERGALHAO GRAMPO U GF 2 X 5/16 DP 634-6 DISPAN | C26: PC | D26: 31 | E26: =IFERROR(_xlfn.XLOOKUP(B26,LISTA!C:C,LISTA!F:F,""),"") -> MI | F26: 38 | G26: DISPAN | H26: 73269090 | I26: 1005000 | J26: 0 - Nacional | K26: Próprio | L26: 4.99 | M26: L20250706 | N26: II - 73269090 | O26: 7896583833463
A27: =IFERROR(_xlfn.XLOOKUP(B27,LISTA!C:C,LISTA!B:B,""),"") -> 000115 | B27: ABRACADEIRA VERGALHAO, GRAMPO U, GE, C/ PORCAS E ARRUELAS, 4 X 5/16 POL. | C27: PC | D27: 53 | E27: =IFERROR(_xlfn.XLOOKUP(B27,LISTA!C:C,LISTA!F:F,""),"") -> MI | F27: 17 | H27: 73269090 | I27: 1005000 | J27: 0 - Nacional | K27: Próprio | L27: 10.71 | M27: L20251106 | N27: II - 73269090 | O27: 7895846516606
A28: =IFERROR(_xlfn.XLOOKUP(B28,LISTA!C:C,LISTA!B:B,""),"") -> 000116 | B28: ABRACADEIRA VERGALHAO GRAMPO U GF 1 X 5/16 DP 634-3 DISPAN | C28: PC | D28: 188 | E28: =IFERROR(_xlfn.XLOOKUP(B28,LISTA!C:C,LISTA!F:F,""),"") -> MI | F28: 80 | G28: DISPAN | H28: 73269090 | I28: 1005000 | J28: 0 - Nacional | K28: Próprio | L28: 5.27 | M28: L20250409 | N28: II - 73269090 | O28: 7899609888725
A29: =IFERROR(_xlfn.XLOOKUP(B29,LISTA!C:C,LISTA!B:B,""),"") -> 000117 | B29: ABRACADEIRA VERGALHAO, GRAMPO U, GE, C/ PORCAS E ARRUELAS, 1/2 X 1/4 POL. | C29: PC | D29: 438 | E29: =IFERROR(_xlfn.XLOOKUP(B29,LISTA!C:C,LISTA!F:F,""),"") -> MI | F29: 26 | H29: 73269090 | I29: 1005000 | J29: 0 - Nacional | K29: Próprio | L29: 8.19 | M29: L20251010 | N29: II - 73269090 | O29: 7895172959432
A30: =IFERROR(_xlfn.XLOOKUP(B30,LISTA!C:C,LISTA!B:B,""),"") -> 000118 | B30: ABRACADEIRA VERGALHAO, GRAMPO U, GE, C/ PORCAS E ARRUELAS, 1 X 1/4 POL. | C30: PC | D30: 137 | E30: =IFERROR(_xlfn.XLOOKUP(B30,LISTA!C:C,LISTA!F:F,""),"") -> MI | F30: 69 | H30: 73269090 | I30: 1005000 | J30: 0 - Nacional | K30: Próprio | L30: 12.19 | M30: L20250709 | N30: II - 73269090 | O30: 7896932226577
A31: =IFERROR(_xlfn.XLOOKUP(B31,LISTA!C:C,LISTA!B:B,""),"") -> 000120 | B31: BUCHA REDUCAO, ALUMINIO, 2 X 3/4BSP | C31: PC | D31: 479 | E31: =IFERROR(_xlfn.XLOOKUP(B31,LISTA!C:C,LISTA!F:F,""),"") -> MI | F31: 79 | H31: 76090000 | I31: 1004800 | J31: 0 - Nacional | K31: Próprio | L31: 13.28 | M31: L20250410 | N31: II - 76090000 | O31: 7899834922535
A32: =IFERROR(_xlfn.XLOOKUP(B32,LISTA!C:C,LISTA!B:B,""),"") -> 000124 | B32: CONDULETE, ROSCAVEL, ALUMINIO FUNDIDO, EX-D, C/ TAMPA, IIA/IIB/IEC 60079-0/60079-1/60529, 1NPT, LB | C32: PC | D32: 19 | E32: =IFERROR(_xlfn.XLOOKUP(B32,LISTA!C:C,LISTA!F:F,""),"") -> MI | F32: 7 | H32: 76090000 | I32: 1004100 | J32: 0 - Nacional | K32: Controlado | L32: 168.51 | M32: L20250827 | N32: II - 76090000 | O32: 7891376155411
A33: =IFERROR(_xlfn.XLOOKUP(B33,LISTA!C:C,LISTA!B:B,""),"") -> 000125 | B33: CONDULETE, ROSCAVEL, ALUMINIO FUNDIDO, EX-D, C/ TAMPA, IIA/IIB/IEC 60079-0/60079-1/60529, 1NPT, LL | C33: PC | D33: 65 | E33: =IFERROR(_xlfn.XLOOKUP(B33,LISTA!C:C,LISTA!F:F,""),"") -> MI | F33: 13 | H33: 76090000 | I33: 1004100 | J33: 0 - Nacional | K33: Controlado | L33: 197.54 | M33: L20250725 | N33: II - 76090000 | O33: 7899255933332
A34: =IFERROR(_xlfn.XLOOKUP(B34,LISTA!C:C,LISTA!B:B,""),"") -> 000126 | B34: CONDULETE, ROSCAVEL, ALUMINIO FUNDIDO, EX-D, C/ TAMPA, IIA/IIB/IEC 60079-0/60079-1/60529, 1NPT, LR | C34: PC | D34: 416 | E34: =IFERROR(_xlfn.XLOOKUP(B34,LISTA!C:C,LISTA!F:F,""),"") -> MI | F34: 70 | H34: 76090000 | I34: 1004100 | J34: 0 - Nacional | K34: Controlado | L34: 236.95 | M34: L20250222 | N34: II - 76090000 | O34: 7896212254814
A35: =IFERROR(_xlfn.XLOOKUP(B35,LISTA!C:C,LISTA!B:B,""),"") -> 000128 | B35: CONDULETE, ROSCAVEL, ALUMINIO FUNDIDO, EX-D, C/ TAMPA, IIA/IIB/IEC 60079-0/60079-1/60529, 1NPT, T | C35: PC | D35: 298 | E35: =IFERROR(_xlfn.XLOOKUP(B35,LISTA!C:C,LISTA!F:F,""),"") -> MI | F35: 80 | H35: 76090000 | I35: 1004100 | J35: 0 - Nacional | K35: Controlado | L35: 230.8 | M35: L20250206 | N35: II - 76090000 | O35: 7891924484508
A36: =IFERROR(_xlfn.XLOOKUP(B36,LISTA!C:C,LISTA!B:B,""),"") -> 000130 | B36: CONDULETE, ROSCAVEL, ALUMINIO FUNDIDO, EX-D, C/ TAMPA, IIA/IIB/IEC 60079-0/60079-1/60529, 1NPT, X | C36: PC | D36: 407 | E36: =IFERROR(_xlfn.XLOOKUP(B36,LISTA!C:C,LISTA!F:F,""),"") -> MI | F36: 80 | H36: 76090000 | I36: 1004100 | J36: 0 - Nacional | K36: Controlado | L36: 206.23 | M36: L20250126 | N36: II - 76090000 | O36: 7896059639049
A37: =IFERROR(_xlfn.XLOOKUP(B37,LISTA!C:C,LISTA!B:B,""),"") -> 000131 | B37: CONDULETE, ROSCAVEL, ALUMINIO FUNDIDO, EX-D, C/ TAMPA, IIA/IIB/IEC 60079-0/60079-1/60529, 1.1/2NPT, C | C37: PC | D37: 475 | E37: =IFERROR(_xlfn.XLOOKUP(B37,LISTA!C:C,LISTA!F:F,""),"") -> MI | F37: 77 | H37: 76090000 | I37: 1004100 | J37: 0 - Nacional | K37: Controlado | L37: 223.18 | M37: L20250513 | N37: II - 76090000 | O37: 7898582479680
A38: =IFERROR(_xlfn.XLOOKUP(B38,LISTA!C:C,LISTA!B:B,""),"") -> 000134 | B38: CONDULETE, ROSCAVEL, ALUMINIO FUNDIDO, EX-D, C/ TAMPA, IIA/IIB/IEC 60079-0/60079-1/60529, 1.1/2NPT, LB | C38: PC | D38: 56 | E38: =IFERROR(_xlfn.XLOOKUP(B38,LISTA!C:C,LISTA!F:F,""),"") -> MI | F38: 75 | H38: 76090000 | I38: 1004100 | J38: 0 - Nacional | K38: Controlado | L38: 160.09 | M38: L20250416 | N38: II - 76090000 | O38: 7891162007628
A39: =IFERROR(_xlfn.XLOOKUP(B39,LISTA!C:C,LISTA!B:B,""),"") -> 000135 | B39: TAMPAO FENDA PVC 1/2 MT 012 DAISA | C39: PC | D39: 290 | E39: =IFERROR(_xlfn.XLOOKUP(B39,LISTA!C:C,LISTA!F:F,""),"") -> MI | F39: 71 | G39: DAISA | H39: 39174090 | I39: 1004100 | J39: 0 - Nacional | K39: Próprio | L39: 4.79 | M39: L20250704 | N39: II - 39174090 | O39: 7896645114419
A40: =IFERROR(_xlfn.XLOOKUP(B40,LISTA!C:C,LISTA!B:B,""),"") -> 000146 | B40: CONDULETE, ROSCAVEL, ALUMINIO FUNDIDO, EX-D, C/ TAMPA, IIA/IIB/IEC 60079-0/60079-1/60529, 1.1/2NPT, LL | C40: PC | D40: 463 | E40: =IFERROR(_xlfn.XLOOKUP(B40,LISTA!C:C,LISTA!F:F,""),"") -> MI | F40: 62 | H40: 76090000 | I40: 1004100 | J40: 0 - Nacional | K40: Controlado | L40: 111.76 | M40: L20250603 | N40: II - 76090000 | O40: 7893805020045
...

Sheet Instrucoes
B4: Preenchimento da lista para solicitação de materiais
B6: Importante: O documento deve ser preenchido conforme instrução abaixo. Não serão aceitos documentos não preenchidos ou parcialmente preenchidos.
B8: 1. Atualização dos dados da Planilha F-T-001 - Solicitação de Compra de Matéria-Prima:
B9: A planilha será atualizada mensalmente e disponibilizada pelo controle de documentos.
B11: 2. Cabeçalho (conf. imagem 2):
B12: a. Cliente: Informar o nome do cliente e a unidade de atendimento em caso de duas ou mais;
B13: b. Projeto: Nome do projeto. Ex.: Caldeira II;
B14: c. OS: Preencher com o número da ordem de serviços: OCS_xxx_xx ou ATK_xxx_xx;
B15: d. Data: Data da solicitação;
B16: e. Elaborado por: Nome do solicitante;
B17: f. N° Contrato: Quando houve, citar o contrato;
B18: g. Doc. Ref.: Se houve uma lista do cliente como base, cite o número;
... B21: j. ID: Preencher a identificação da solicitação (conf. imagem 1);
B23: #VALUE!
B24: Imagem 1
B25: #VALUE!
B26: Imagem 2
B28: 3. Seleção de produtos
B29: a. Utilize o campo de busca para localizar o produto desejado; digite parte do Texto e Tecle "Enter"
B30: b. A busca sera realizada pelo código e/ou produto.
B31: c. O símbolo * é utilizado como um facilitador na busca, exemplo: se estiver buscando por CONDULETE, ROSCAVEL, ALUMINIO FUNDIDO, EX-D, C/ TAMPA, IIA/IIB/IEC 60079-0/60079-1/60529, 1NPT, LR, posso procurar por “CONDULETE*EX”, mas, ainda aparecerão conduletes de diversas formas e bitolas (imagem 3), porém, se pesquisarmos por “CONDULETE*EX*1.1/2” a pesquisa fica mais restrita e rápida (imagem 4);
B32: d. Após localizar o produto desejado clique 2 vezes no código numérico ou no produto, assim o produto será gravado na lista de materiais
B33: e. Em seguida, para Limpar o filtro e localizar outro produto tecle "ESC" ou clique em “Limpa Filtro” e refaça a busca (imagem 5);
B35: #VALUE!
B36: Imagem 3
B37: #VALUE!
B38: Imagem 4
B39: #VALUE!
B40: Imagem 5
B41: f. Na coluna D denominada Estoque, pode-se conferir o estoque mensal para ajudar a tomar a melhor decisão conforme a necessidade.
B42: Conforme abaixo, se a necessidade for para CONDULETE, ROSCAVEL, ALUMINIO FUNDIDO, EX-D, C/ TAMPA, IIA/IIB/IEC 60079-0/60079-1/60529, 1.1/2NPT, LR o solicitante pode alterar a solicitação e adequar o projeto para LL e considerar as 20 peças de estoque (imagem 6).
B43: #VALUE!
B44: Imagem 6
B45: g. Após a inclusão do produto, ele automaticamente será enviado a aba “LM” e será agrupado conforme ordem de inclusão.
B46: Se acaso selecionar um produto incorretamente, basta clicar em cima do código e em seguida DELETE, a planilha entenderá que ele foi excluído e o próximo produto assumirá seu lugar.
B47: 4. Preenchimento da lista de materiais (LM) (imagem 7)
B48: a. Rev: Inicia-se na revisão 0 e deve ser preenchido individualmente. Quando algum item sofrer alteração, deve-se considerar como revisão 1 e assim sucessivamente;
B49: b. Na sequência informe a quantidade de produtos;
B50: c. Adicione alguma observação que considerar relevante;
B51: #VALUE!
...

Sheet Cabeamento
A1: Código | B1: Descricao NF | C1: Unidade | D1: Quant | E1: Categoria | F1: Est. Mínimo | G1: Fabricante | H1: NCM | I1: CEST | J1: Ind. Origem | K1: Tipo Custódia | L1: Preço Custo | M1: Lote | N1: Classif. Fiscal | O1: Cód. Barras
A2: =IFERROR(_xlfn.XLOOKUP(B2,LISTA!C:C,LISTA!B:B,""),"") -> 000136 | B2: CABO INSTRUMENTACAO BC, ISOL PVC 70ØC, NBR 10300, C/ BLIND. ELETROST. COLETIVA E FIO DRENO 2X4,00MMY TELEFIO | C2: =IFERROR(_xlfn.XLOOKUP(B2,LISTA!C:C,LISTA!D:D,""),"") -> MT | D2: =IFERROR(_xlfn.XLOOKUP(B2,LISTA!C:C,LISTA!E:E,""),"") -> 0 | E2: =IFERROR(_xlfn.XLOOKUP(B2,LISTA!C:C,LISTA!F:F,""),"") -> MI | F2: 49 | G2: TELEFIO | H2: 85444900 | I2: 1004800 | J2: 0 - Nacional | K2: Próprio | L2: 86.93 | M2: L20250922 | N2: II - 85444900 | O2: 7897204901102
A3: =IFERROR(_xlfn.XLOOKUP(B3,LISTA!C:C,LISTA!B:B,""),"") -> 000151 | B3: CABO TERMOPAR EXTENSAO K, ISOL. SILICONE AMARELO EXTERNO E INTERNO, SEM BLINDAGEM, 2 X 1,00MM CK100SS-A CONSISTEC | C3: =IFERROR(_xlfn.XLOOKUP(B3,LISTA!C:C,LISTA!D:D,""),"") -> MT | D3: =IFERROR(_xlfn.XLOOKUP(B3,LISTA!C:C,LISTA!E:E,""),"") -> 0 | E3: =IFERROR(_xlfn.XLOOKUP(B3,LISTA!C:C,LISTA!F:F,""),"") -> MI | F3: 44 | G3: CONSISTEC | H3: 85444900 | I3: 1004100 | J3: 0 - Nacional | K3: Próprio | L3: 4.8 | M3: L20250309 | N3: II - 85444900 | O3: 7899973295931
A4: =IFERROR(_xlfn.XLOOKUP(B4,LISTA!C:C,LISTA!B:B,""),"") -> 000156 | B4: CABO INSTRUMENTACAO BF, MA, PVC/E 70ØC, NBR 10300, C/ BLIND. ELETROST. COLETIVA E FIO DRENO 2X1,0MMY 900475 INNOV | C4: =IFERROR(_xlfn.XLOOKUP(B4,LISTA!C:C,LISTA!D:D,""),"") -> MT | D4: =IFERROR(_xlfn.XLOOKUP(B4,LISTA!C:C,LISTA!E:E,""),"") -> 0 | E4: =IFERROR(_xlfn.XLOOKUP(B4,LISTA!C:C,LISTA!F:F,""),"") -> MI | F4: 58 | G4: INNOV | H4: 85444900 | I4: 1005000 | J4: 0 - Nacional | K4: Próprio | L4: 34.47 | M4: L20250403 | N4: II - 85444900 | O4: 7899095128092
A5: =IFERROR(_xlfn.XLOOKUP(B5,LISTA!C:C,LISTA!B:B,""),"") -> 000173 | B5: CABO INSTRUMENTACAO BC, ISOL PVC 70ØC, NBR 10300, C/ BLIND. ELETROST. COLETIVA E FIO DRENO 2X0,75MMY TELEFIO | C5: =IFERROR(_xlfn.XLOOKUP(B5,LISTA!C:C,LISTA!D:D,""),"") -> MT | D5: =IFERROR(_xlfn.XLOOKUP(B5,LISTA!C:C,LISTA!E:E,""),"") -> 0 | E5: =IFERROR(_xlfn.XLOOKUP(B5,LISTA!C:C,LISTA!F:F,""),"") -> MI | F5: 69 | G5: TELEFIO | H5: 85444900 | I5: 1005000 | J5: 0 - Nacional | K5: Próprio | L5: 42.95 | M5: L20250424 | N5: II - 85444900 | O5: 7891409400582
A6: =IFERROR(_xlfn.XLOOKUP(B6,LISTA!C:C,LISTA!B:B,""),"") -> 000241 | B6: CABO INSTRUMENTACAO BC, ISOL PVC 70ØC, NBR 10300, C/ BLIND. ELETROST. COLETIVA E FIO DRENO 2X2,50MMY TELEFIO | C6: =IFERROR(_xlfn.XLOOKUP(B6,LISTA!C:C,LISTA!D:D,""),"") -> MT | D6: =IFERROR(_xlfn.XLOOKUP(B6,LISTA!C:C,LISTA!E:E,""),"") -> 0 | E6: =IFERROR(_xlfn.XLOOKUP(B6,LISTA!C:C,LISTA!F:F,""),"") -> MI | F6: 63 | G6: TELEFIO | H6: 85444900 | I6: 1005000 | J6: 0 - Nacional | K6: Próprio | L6: 76.51 | M6: L20250210 | N6: II - 85444900 | O6: 7896846017244
A7: =IFERROR(_xlfn.XLOOKUP(B7,LISTA!C:C,LISTA!B:B,""),"") -> 000249 | B7: TERMINAL OLHAL, PRE-ISOLADO, VERMELHO, P/ CABOS 0,50·1,50MM, FURO 5MM | C7: =IFERROR(_xlfn.XLOOKUP(B7,LISTA!C:C,LISTA!D:D,""),"") -> PC | D7: =IFERROR(_xlfn.XLOOKUP(B7,LISTA!C:C,LISTA!E:E,""),"") -> 0 | E7: =IFERROR(_xlfn.XLOOKUP(B7,LISTA!C:C,LISTA!F:F,""),"") -> MC | F7: 9 | H7: 85369090 | I7: 1004100 | J7: 0 - Nacional | K7: Próprio | L7: 48.05 | M7: L20251008 | N7: II - 85369090 | O7: 7895649570705
A8: =IFERROR(_xlfn.XLOOKUP(B8,LISTA!C:C,LISTA!B:B,""),"") -> 000252 | B8: TERMINAL OLHAL, PRE-ISOLADO, VERMELHO, P/ CABOS 0,50·1,50MM, FURO 6,00MM | C8: =IFERROR(_xlfn.XLOOKUP(B8,LISTA!C:C,LISTA!D:D,""),"") -> PC | D8: =IFERROR(_xlfn.XLOOKUP(B8,LISTA!C:C,LISTA!E:E,""),"") -> 0 | E8: =IFERROR(_xlfn.XLOOKUP(B8,LISTA!C:C,LISTA!F:F,""),"") -> MC | F8: 5 | H8: 85369090 | I8: 1004800 | J8: 0 - Nacional | K8: Próprio | L8: 52.81 | M8: L20250820 | N8: II - 85369090 | O8: 7898682550433
A9: =IFERROR(_xlfn.XLOOKUP(B9,LISTA!C:C,LISTA!B:B,""),"") -> 000253 | B9: TERMINAL OLHAL, PRE-ISOLADO, AZUL, P/ CABOS 1,50·2,50MM, FURO 8,00MM | C9: =IFERROR(_xlfn.XLOOKUP(B9,LISTA!C:C,LISTA!D:D,""),"") -> PC | D9: =IFERROR(_xlfn.XLOOKUP(B9,LISTA!C:C,LISTA!E:E,""),"") -> 0 | E9: =IFERROR(_xlfn.XLOOKUP(B9,LISTA!C:C,LISTA!F:F,""),"") -> MC | F9: 66 | H9: 85369090 | I9: 1004100 | J9: 0 - Nacional | K9: Próprio | L9: 79.44 | M9: L20250626 | N9: II - 85369090 | O9: 7892255259872
A10: =IFERROR(_xlfn.XLOOKUP(B10,LISTA!C:C,LISTA!B:B,""),"") -> 000255 | B10: TERMINAL GARFO, PRE-ISOLADO, P/ CABOS 0,50 A 1,50MM, FURO 5,00 MM | C10: =IFERROR(_xlfn.XLOOKUP(B10,LISTA!C:C,LISTA!D:D,""),"") -> PC | D10: =IFERROR(_xlfn.XLOOKUP(B10,LISTA!C:C,LISTA!E:E,""),"") -> 0 | E10: =IFERROR(_xlfn.XLOOKUP(B10,LISTA!C:C,LISTA!F:F,""),"") -> MC | F10: 69 | H10: 85369090 | I10: 1004100 | J10: 0 - Nacional | K10: Próprio | L10: 1.82 | M10: L20250601 | N10: II - 85369090 | O10: 7892386850353
A11: =IFERROR(_xlfn.XLOOKUP(B11,LISTA!C:C,LISTA!B:B,""),"") -> 000258 | B11: TERMINAL OLHAL, PRE-ISOLADO, AZUL, P/ CABOS 1,50 A 2,50MM, FURO 3,00 MM | C11: =IFERROR(_xlfn.XLOOKUP(B11,LISTA!C:C,LISTA!D:D,""),"") -> PC | D11: =IFERROR(_xlfn.XLOOKUP(B11,LISTA!C:C,LISTA!E:E,""),"") -> 0 | E11: =IFERROR(_xlfn.XLOOKUP(B11,LISTA!C:C,LISTA!F:F,""),"") -> MI | F11: 76 | H11: 85369090 | I11: 1004100 | J11: 0 - Nacional | K11: Próprio | L11: 31.02 | M11: L20250821 | N11: II - 85369090 | O11: 7896262014510
A12: =IFERROR(_xlfn.XLOOKUP(B12,LISTA!C:C,LISTA!B:B,""),"") -> 000263 | B12: TERMINAL GARFO, PRE-ISOLADO VERMELHO, P/ CABOS 0,50 A 1,50MM, FURO 4,00 MM | C12: =IFERROR(_xlfn.XLOOKUP(B12,LISTA!C:C,LISTA!D:D,""),"") -> PC | D12: =IFERROR(_xlfn.XLOOKUP(B12,LISTA!C:C,LISTA!E:E,""),"") -> 0 | E12: =IFERROR(_xlfn.XLOOKUP(B12,LISTA!C:C,LISTA!F:F,""),"") -> MI | F12: 66 | H12: 85369090 | I12: 1004800 | J12: 0 - Nacional | K12: Próprio | L12: 58.96 | M12: L20250208 | N12: II - 85369090 | O12: 7891718398571
A13: =IFERROR(_xlfn.XLOOKUP(B13,LISTA!C:C,LISTA!B:B,""),"") -> 000269 | B13: TERMINAL OLHAL, PRE-ISOLADO AMARELO, P/ CABOS 4,00 A 6,00MM, FURO 8MM | C13: =IFERROR(_xlfn.XLOOKUP(B13,LISTA!C:C,LISTA!D:D,""),"") -> PC | D13: =IFERROR(_xlfn.XLOOKUP(B13,LISTA!C:C,LISTA!E:E,""),"") -> 0 | E13: =IFERROR(_xlfn.XLOOKUP(B13,LISTA!C:C,LISTA!F:F,""),"") -> MI | F13: 73 | H13: 85369090 | I13: 1005000 | J13: 0 - Nacional | K13: Próprio | L13: 22.83 | M13: L20251007 | N13: II - 85369090 | O13: 7894798414857
A14: =IFERROR(_xlfn.XLOOKUP(B14,LISTA!C:C,LISTA!B:B,""),"") -> 000270 | B14: TERMINAL GARFO, PRE-ISOLADO, AMARELO, P/ CABOS 4,00 A 6,00MM, FURO 5,00 MM | C14: =IFERROR(_xlfn.XLOOKUP(B14,LISTA!C:C,LISTA!D:D,""),"") -> PC | D14: =IFERROR(_xlfn.XLOOKUP(B14,LISTA!C:C,LISTA!E:E,""),"") -> 0 | E14: =IFERROR(_xlfn.XLOOKUP(B14,LISTA!C:C,LISTA!F:F,""),"") -> MC | F14: 10 | H14: 85369090 | I14: 1004100 | J14: 0 - Nacional | K14: Próprio | L14: 14.09 | M14: L20250516 | N14: II - 85369090 | O14: 7899948127154
A15: =IFERROR(_xlfn.XLOOKUP(B15,LISTA!C:C,LISTA!B:B,""),"") -> 000271 | B15: TERMINAL OLHAL, PRE-ISOLADO, P/ CABOS 1,50 A 2,50MM, FURO 6,00 MM | C15: =IFERROR(_xlfn.XLOOKUP(B15,LISTA!C:C,LISTA!D:D,""),"") -> PC | D15: =IFERROR(_xlfn.XLOOKUP(B15,LISTA!C:C,LISTA!E:E,""),"") -> 0 | E15: =IFERROR(_xlfn.XLOOKUP(B15,LISTA!C:C,LISTA!F:F,""),"") -> MI | F15: 37 | H15: 85369090 | I15: 1004800 | J15: 0 - Nacional | K15: Próprio | L15: 33.82 | M15: L20250812 | N15: II - 85369090 | O15: 7891203015327
A16: =IFERROR(_xlfn.XLOOKUP(B16,LISTA!C:C,LISTA!B:B,""),"") -> 000275 | B16: TERMINAL OLHAL, PRE-ISOLADO VERMELHO, P/ CABOS 1,50 · 2,50MM, FURO 8MM TP-2,5-8 INTELLI | C16: =IFERROR(_xlfn.XLOOKUP(B16,LISTA!C:C,LISTA!D:D,""),"") -> PC | D16: =IFERROR(_xlfn.XLOOKUP(B16,LISTA!C:C,LISTA!E:E,""),"") -> 0 | E16: =IFERROR(_xlfn.XLOOKUP(B16,LISTA!C:C,LISTA!F:F,""),"") -> MI | F16: 62 | G16: INTELLI | H16: 85369090 | I16: 1004800 | J16: 0 - Nacional | K16: Próprio | L16: 78.84 | M16: L20250320 | N16: II - 85369090 | O16: 7895768627526
A17: =IFERROR(_xlfn.XLOOKUP(B17,LISTA!C:C,LISTA!B:B,""),"") -> 000286 | B17: TERMINAL GARFO, PRE-ISOLADO AZUL, P/ CABOS 1,50 · 2,5MM, FURO 4MM TPF-2,5-4 INTELLI | C17: =IFERROR(_xlfn.XLOOKUP(B17,LISTA!C:C,LISTA!D:D,""),"") -> PC | D17: =IFERROR(_xlfn.XLOOKUP(B17,LISTA!C:C,LISTA!E:E,""),"") -> 0 | E17: =IFERROR(_xlfn.XLOOKUP(B17,LISTA!C:C,LISTA!F:F,""),"") -> MI | F17: 63 | G17: INTELLI | H17: 85369090 | I17: 1004800 | J17: 0 - Nacional | K17: Próprio | L17: 46.27 | M17: L20250607 | N17: II - 85369090 | O17: 7891101781517
A18: =IFERROR(_xlfn.XLOOKUP(B18,LISTA!C:C,LISTA!B:B,""),"") -> 000352 | B18: CABO FLEXIVEL FOREPLAST, ISOL. PVC BWF, 450 / 750V BRANCO 0,50MM 25404001371 PHELPS DODGE | C18: =IFERROR(_xlfn.XLOOKUP(B18,LISTA!C:C,LISTA!D:D,""),"") -> MT | D18: =IFERROR(_xlfn.XLOOKUP(B18,LISTA!C:C,LISTA!E:E,""),"") -> 0 | E18: =IFERROR(_xlfn.XLOOKUP(B18,LISTA!C:C,LISTA!F:F,""),"") -> MI | F18: 30 | G18: PHELPS DODGE | H18: 85444900 | I18: 1004800 | J18: 0 - Nacional | K18: Próprio | L18: 27.59 | M18: L20251224 | N18: II - 85444900 | O18: 7896361963274
A19: =IFERROR(_xlfn.XLOOKUP(B19,LISTA!C:C,LISTA!B:B,""),"") -> 000378 | B19: TERMINAL OLHAL, PRE-ISOLADO, P/ CABOS 4,00 A 6,00MM, FURO 6,00 MM | C19: =IFERROR(_xlfn.XLOOKUP(B19,LISTA!C:C,LISTA!D:D,""),"") -> PC | D19: =IFERROR(_xlfn.XLOOKUP(B19,LISTA!C:C,LISTA!E:E,""),"") -> 0 | E19: =IFERROR(_xlfn.XLOOKUP(B19,LISTA!C:C,LISTA!F:F,""),"") -> MI | F19: 12 | H19: 85369090 | I19: 1005000 | J19: 0 - Nacional | K19: Próprio | L19: 55.63 | M19: L20250804 | N19: II - 85369090 | O19: 7891863876492
A20: =IFERROR(_xlfn.XLOOKUP(B20,LISTA!C:C,LISTA!B:B,""),"") -> 000456 | B20: CABO INSTRUMENTACAO BIC, ISOL PVC 70ØC, NBR 10300, C/ BLIND. ELETROST. COLETIVA E IND. FIO DRENO 4X2X0,75MMY TELEFIO | C20: =IFERROR(_xlfn.XLOOKUP(B20,LISTA!C:C,LISTA!D:D,""),"") -> MT | D20: =IFERROR(_xlfn.XLOOKUP(B20,LISTA!C:C,LISTA!E:E,""),"") -> 0 | E20: =IFERROR(_xlfn.XLOOKUP(B20,LISTA!C:C,LISTA!F:F,""),"") -> MI | F20: 68 | G20: TELEFIO | H20: 85444900 | I20: 1005000 | J20: 0 - Nacional | K20: Próprio | L20: 44.27 | M20: L20251019 | N20: II - 85444900 | O20: 7898802614692
A21: =IFERROR(_xlfn.XLOOKUP(B21,LISTA!C:C,LISTA!B:B,""),"") -> 000503 | B21: CABO FLEXIVEL , ISOL. PVC/F, CAPA PVC/ST1, TEMP. 70C, 500/750V PRETO 2 X 1,00MM | C21: =IFERROR(_xlfn.XLOOKUP(B21,LISTA!C:C,LISTA!D:D,""),"") -> MT | D21: -150 | E21: =IFERROR(_xlfn.XLOOKUP(B21,LISTA!C:C,LISTA!F:F,""),"") -> MI | F21: 30 | H21: 85444900 | I21: 1004100 | J21: 0 - Nacional | K21: Próprio | L21: 43.51 | M21: L20250126 | N21: II - 85444900 | O21: 7894083280803
A22: =IFERROR(_xlfn.XLOOKUP(B22,LISTA!C:C,LISTA!B:B,""),"") -> 000507 | B22: CABO COAXIAL P/ REDE CONTROLNET RG6/U, 18AWG, CAPA EM PVC PRETA 3092A# BELDEN | C22: =IFERROR(_xlfn.XLOOKUP(B22,LISTA!C:C,LISTA!D:D,""),"") -> MT | D22: =IFERROR(_xlfn.XLOOKUP(B22,LISTA!C:C,LISTA!E:E,""),"") -> 0 | E22: =IFERROR(_xlfn.XLOOKUP(B22,LISTA!C:C,LISTA!F:F,""),"") -> MI | F22: 58 | G22: BELDEN | H22: 85441900 | I22: 1004800 | J22: 0 - Nacional | K22: Próprio | L22: 6.58 | M22: L20250216 | N22: II - 85441900 | O22: 7895033604623
A23: =IFERROR(_xlfn.XLOOKUP(B23,LISTA!C:C,LISTA!B:B,""),"") -> 000645 | B23: TERMINAL DE COMPRESSAO, COBRE ESTANHADO, SERIE METRICA, P/ CABOS 4 A 6MM C/ FURO 5,00 MM | C23: =IFERROR(_xlfn.XLOOKUP(B23,LISTA!C:C,LISTA!D:D,""),"") -> PC | D23: =IFERROR(_xlfn.XLOOKUP(B23,LISTA!C:C,LISTA!E:E,""),"") -> 0 | E23: =IFERROR(_xlfn.XLOOKUP(B23,LISTA!C:C,LISTA!F:F,""),"") -> MI | F23: 77 | H23: 85369090 | I23: 1004100 | J23: 0 - Nacional | K23: Próprio | L23: 90.13 | M23: L20251218 | N23: II - 85369090 | O23: 7896590101244
A24: =IFERROR(_xlfn.XLOOKUP(B24,LISTA!C:C,LISTA!B:B,""),"") -> 000647 | B24: TERMINAL DE COMPRESSAO, COBRE ESTANHADO, P/ CABOS 240,00MM, C/ FURO 13,00MM | C24: =IFERROR(_xlfn.XLOOKUP(B24,LISTA!C:C,LISTA!D:D,""),"") -> PC | D24: =IFERROR(_xlfn.XLOOKUP(B24,LISTA!C:C,LISTA!E:E,""),"") -> 0 | E24: =IFERROR(_xlfn.XLOOKUP(B24,LISTA!C:C,LISTA!F:F,""),"") -> MI | F24: 44 | H24: 85369090 | I24: 1004800 | J24: 0 - Nacional | K24: Próprio | L24: 49.11 | M24: L20250307 | N24: II - 85369090 | O24: 7891840981424
A25: =IFERROR(_xlfn.XLOOKUP(B25,LISTA!C:C,LISTA!B:B,""),"") -> 000648 | B25: TERMINAL DE COMPRESSAO, COBRE ESTANHADO, SERIE METRICA, P/ CABOS 185MM C/ FURO 13,8MM TM-185 INTELLI | C25: =IFERROR(_xlfn.XLOOKUP(B25,LISTA!C:C,LISTA!D:D,""),"") -> PC | D25: =IFERROR(_xlfn.XLOOKUP(B25,LISTA!C:C,LISTA!E:E,""),"") -> 0 | E25: =IFERROR(_xlfn.XLOOKUP(B25,LISTA!C:C,LISTA!F:F,""),"") -> MI | F25: 30 | G25: INTELLI | H25: 85369090 | I25: 1005000 | J25: 0 - Nacional | K25: Próprio | L25: 60.32 | M25: L20250320 | N25: II - 85369090 | O25: 7893594304443
A26: =IFERROR(_xlfn.XLOOKUP(B26,LISTA!C:C,LISTA!B:B,""),"") -> 000649 | B26: TERMINAL DE COMPRESSAO, COBRE ESTANHADO, SERIE METRICA, P/ CABOS 150MM C/ FURO 13,8MM TM-150 INTELLI | C26: =IFERROR(_xlfn.XLOOKUP(B26,LISTA!C:C,LISTA!D:D,""),"") -> PC | D26: =IFERROR(_xlfn.XLOOKUP(B26,LISTA!C:C,LISTA!E:E,""),"") -> 0 | E26: =IFERROR(_xlfn.XLOOKUP(B26,LISTA!C:C,LISTA!F:F,""),"") -> MI | F26: 58 | G26: INTELLI | H26: 85369090 | I26: 1005000 | J26: 0 - Nacional | K26: Próprio | L26: 24.55 | M26: L20250116 | N26: II - 85369090 | O26: 7897907505753
A27: =IFERROR(_xlfn.XLOOKUP(B27,LISTA!C:C,LISTA!B:B,""),"") -> 000650 | B27: TERMINAL DE COMPRESSAO, COBRE ESTANHADO, P/ CABOS 120,00 MM C/ FURO 10,00 MM | C27: =IFERROR(_xlfn.XLOOKUP(B27,LISTA!C:C,LISTA!D:D,""),"") -> PC | D27: =IFERROR(_xlfn.XLOOKUP(B27,LISTA!C:C,LISTA!E:E,""),"") -> 0 | E27: =IFERROR(_xlfn.XLOOKUP(B27,LISTA!C:C,LISTA!F:F,""),"") -> MI | F27: 53 | H27: 85369090 | I27: 1004100 | J27: 0 - Nacional | K27: Próprio | L27: 72.6 | M27: L20251205 | N27: II - 85369090 | O27: 7891286529928
A28: =IFERROR(_xlfn.XLOOKUP(B28,LISTA!C:C,LISTA!B:B,""),"") -> 000651 | B28: TERMINAL DE COMPRESSAO, COBRE ESTANHADO, P/ CABOS 95,00 MM C/ FURO 10,00 MM | C28: =IFERROR(_xlfn.XLOOKUP(B28,LISTA!C:C,LISTA!D:D,""),"") -> PC | D28: =IFERROR(_xlfn.XLOOKUP(B28,LISTA!C:C,LISTA!E:E,""),"") -> 0 | E28: =IFERROR(_xlfn.XLOOKUP(B28,LISTA!C:C,LISTA!F:F,""),"") -> MI | F28: 23 | H28: 85369090 | I28: 1004100 | J28: 0 - Nacional | K28: Próprio | L28: 42.96 | M28: L20250322 | N28: II - 85369090 | O28: 7893356819511
A29: =IFERROR(_xlfn.XLOOKUP(B29,LISTA!C:C,LISTA!B:B,""),"") -> 000652 | B29: TERMINAL DE COMPRESSAO, COBRE ESTANHADO, SERIE METRICA, P/ CABOS 70MM C/ FURO 10,5MM TM-70 INTELLI | C29: =IFERROR(_xlfn.XLOOKUP(B29,LISTA!C:C,LISTA!D:D,""),"") -> PC | D29: =IFERROR(_xlfn.XLOOKUP(B29,LISTA!C:C,LISTA!E:E,""),"") -> 0 | E29: =IFERROR(_xlfn.XLOOKUP(B29,LISTA!C:C,LISTA!F:F,""),"") -> MI | F29: 9 | G29: INTELLI | H29: 85369090 | I29: 1004100 | J29: 0 - Nacional | K29: Próprio | L29: 32.6 | M29: L20250123 | N29: II - 85369090 | O29: 7891083770751
A30: =IFERROR(_xlfn.XLOOKUP(B30,LISTA!C:C,LISTA!B:B,""),"") -> 000680 | B30: TERMINAL GARFO, PRE-ISOLADO, AMARELO, P/ CABOS 4,00 A 6,00 MM, FURO 6,00 MM | C30: =IFERROR(_xlfn.XLOOKUP(B30,LISTA!C:C,LISTA!D:D,""),"") -> PC | D30: =IFERROR(_xlfn.XLOOKUP(B30,LISTA!C:C,LISTA!E:E,""),"") -> 0 | E30: =IFERROR(_xlfn.XLOOKUP(B30,LISTA!C:C,LISTA!F:F,""),"") -> MC | F30: 71 | H30: 85369090 | I30: 1004100 | J30: 0 - Nacional | K30: Próprio | L30: 66.74 | M30: L20250322 | N30: II - 85369090 | O30: 7893863507033
A31: =IFERROR(_xlfn.XLOOKUP(B31,LISTA!C:C,LISTA!B:B,""),"") -> 000681 | B31: TERMINAL OLHAL, TUBULAR, PRE-ISOLADO, VERMELHO, P/ CABOS 10,00 MM, FURO 8,00 MM | C31: =IFERROR(_xlfn.XLOOKUP(B31,LISTA!C:C,LISTA!D:D,""),"") -> PC | D31: =IFERROR(_xlfn.XLOOKUP(B31,LISTA!C:C,LISTA!E:E,""),"") -> 0 | E31: =IFERROR(_xlfn.XLOOKUP(B31,LISTA!C:C,LISTA!F:F,""),"") -> MC | F31: 33 | H31: 85369090 | I31: 1004800 | J31: 0 - Nacional | K31: Próprio | L31: 40.62 | M31: L20250921 | N31: II - 85369090 | O31: 7897039431336
A32: =IFERROR(_xlfn.XLOOKUP(B32,LISTA!C:C,LISTA!B:B,""),"") -> 000690 | B32: TERMINAL OLHAL, PRE-ISOLADO, P/ CABOS 4,00 A 6,00MM, FURO 4,00 MM | C32: =IFERROR(_xlfn.XLOOKUP(B32,LISTA!C:C,LISTA!D:D,""),"") -> PC | D32: =IFERROR(_xlfn.XLOOKUP(B32,LISTA!C:C,LISTA!E:E,""),"") -> 0 | E32: =IFERROR(_xlfn.XLOOKUP(B32,LISTA!C:C,LISTA!F:F,""),"") -> MI | F32: 36 | H32: 85369090 | I32: 1004100 | J32: 0 - Nacional | K32: Próprio | L32: 57.51 | M32: L20251026 | N32: II - 85369090 | O32: 7894530617477
A33: =IFERROR(_xlfn.XLOOKUP(B33,LISTA!C:C,LISTA!B:B,""),"") -> 000716 | B33: CABO FLEXIVEL, ISOL. PVC/A, TEMP. 70 C, 750V, PRETO, 1 X 6,00 MM | C33: =IFERROR(_xlfn.XLOOKUP(B33,LISTA!C:C,LISTA!D:D,""),"") -> MT | D33: =IFERROR(_xlfn.XLOOKUP(B33,LISTA!C:C,LISTA!E:E,""),"") -> 0 | E33: =IFERROR(_xlfn.XLOOKUP(B33,LISTA!C:C,LISTA!F:F,""),"") -> MI | F33: 9 | H33: 85444900 | I33: 1004100 | J33: 0 - Nacional | K33: Próprio | L33: 84.61 | M33: L20250717 | N33: II - 85444900 | O33: 7899074655059
A34: =IFERROR(_xlfn.XLOOKUP(B34,LISTA!C:C,LISTA!B:B,""),"") -> 000720 | B34: CABO FLEXIVEL, ISOL. PVC/A, TEMP. 70 C, 750V, PRETO, 1 X 4,00 MM | C34: =IFERROR(_xlfn.XLOOKUP(B34,LISTA!C:C,LISTA!D:D,""),"") -> MT | D34: =IFERROR(_xlfn.XLOOKUP(B34,LISTA!C:C,LISTA!E:E,""),"") -> 0 | E34: =IFERROR(_xlfn.XLOOKUP(B34,LISTA!C:C,LISTA!F:F,""),"") -> MI | F34: 67 | H34: 85444900 | I34: 1005000 | J34: 0 - Nacional | K34: Próprio | L34: 82.35 | M34: L20250112 | N34: II - 85444900 | O34: 7894602424504
A35: =IFERROR(_xlfn.XLOOKUP(B35,LISTA!C:C,LISTA!B:B,""),"") -> 000760 | B35: CABO FLEXIVEL, ISOL. PVC/A, TEMP. 70 C, 750V, PRETO, 1 X 1,50 MM | C35: =IFERROR(_xlfn.XLOOKUP(B35,LISTA!C:C,LISTA!D:D,""),"") -> RL | D35: =IFERROR(_xlfn.XLOOKUP(B35,LISTA!C:C,LISTA!E:E,""),"") -> 0 | E35: =IFERROR(_xlfn.XLOOKUP(B35,LISTA!C:C,LISTA!F:F,""),"") -> MI | F35: 7 | H35: 85444900 | I35: 1004800 | J35: 0 - Nacional | K35: Próprio | L35: 64.48 | M35: L20250824 | N35: II - 85444900 | O35: 7897072493317
A36: =IFERROR(_xlfn.XLOOKUP(B36,LISTA!C:C,LISTA!B:B,""),"") -> 000766 | B36: CABO FLEXIVEL, ISOL. PVC/A, TEMP. 70 C, 750V, BRANCO, 1 X 1,50 MM | C36: =IFERROR(_xlfn.XLOOKUP(B36,LISTA!C:C,LISTA!D:D,""),"") -> MT | D36: =IFERROR(_xlfn.XLOOKUP(B36,LISTA!C:C,LISTA!E:E,""),"") -> 0 | E36: =IFERROR(_xlfn.XLOOKUP(B36,LISTA!C:C,LISTA!F:F,""),"") -> MI | F36: 55 | H36: 85444900 | I36: 1004100 | J36: 0 - Nacional | K36: Próprio | L36: 77.96 | M36: L20250709 | N36: II - 85444900 | O36: 7892464853049
A37: =IFERROR(_xlfn.XLOOKUP(B37,LISTA!C:C,LISTA!B:B,""),"") -> 000771 | B37: CABO FLEXIVEL, ISOL. PVC/F, CAPA PVC/ST1, TEMP. 70C, 750V, CL. 4, PRETO, 3 X 1,50 MM | C37: =IFERROR(_xlfn.XLOOKUP(B37,LISTA!C:C,LISTA!D:D,""),"") -> MT | D37: =IFERROR(_xlfn.XLOOKUP(B37,LISTA!C:C,LISTA!E:E,""),"") -> 0 | E37: =IFERROR(_xlfn.XLOOKUP(B37,LISTA!C:C,LISTA!F:F,""),"") -> MI | F37: 17 | H37: 85444900 | I37: 1004100 | J37: 0 - Nacional | K37: Próprio | L37: 17.77 | M37: L20250903 | N37: II - 85444900 | O37: 7892469352991
A38: =IFERROR(_xlfn.XLOOKUP(B38,LISTA!C:C,LISTA!B:B,""),"") -> 000808 | B38: CABO INSTRUMENTACAO, 300V, ISOL. PVC, 70 C, BLINDAGEM, MALHA, 4 X 18 AWG | C38: =IFERROR(_xlfn.XLOOKUP(B38,LISTA!C:C,LISTA!D:D,""),"") -> MT | D38: =IFERROR(_xlfn.XLOOKUP(B38,LISTA!C:C,LISTA!E:E,""),"") -> 0 | E38: =IFERROR(_xlfn.XLOOKUP(B38,LISTA!C:C,LISTA!F:F,""),"") -> MI | F38: 57 | H38: 85444900 | I38: 1004100 | J38: 0 - Nacional | K38: Próprio | L38: 16.7 | M38: L20250105 | N38: II - 85444900 | O38: 7898595247749
A39: =IFERROR(_xlfn.XLOOKUP(B39,LISTA!C:C,LISTA!B:B,""),"") -> 000809 | B39: CABO INSTRUMENTACAO, 300V, ISOL. PVC, 70 C, BLINDAGEM, MALHA, 2 X 18 AWG | C39: =IFERROR(_xlfn.XLOOKUP(B39,LISTA!C:C,LISTA!D:D,""),"") -> MT | D39: =IFERROR(_xlfn.XLOOKUP(B39,LISTA!C:C,LISTA!E:E,""),"") -> 0 | E39: =IFERROR(_xlfn.XLOOKUP(B39,LISTA!C:C,LISTA!F:F,""),"") -> MI | F39: 61 | H39: 85444900 | I39: 1004800 | J39: 0 - Nacional | K39: Próprio | L39: 36.24 | M39: L20250911 | N39: II - 85444900 | O39: 7896634531500
A40: =IFERROR(_xlfn.XLOOKUP(B40,LISTA!C:C,LISTA!B:B,""),"") -> 000822 | B40: CABO FLEXIVEL, ISOL. PVC/A, TEMP. 70 C, 750V, VERDE, 1 X 2,50 MM | C40: =IFERROR(_xlfn.XLOOKUP(B40,LISTA!C:C,LISTA!D:D,""),"") -> MT | D40: =IFERROR(_xlfn.XLOOKUP(B40,LISTA!C:C,LISTA!E:E,""),"") -> 0 | E40: =IFERROR(_xlfn.XLOOKUP(B40,LISTA!C:C,LISTA!F:F,""),"") -> MI | F40: 67 | H40: 85444900 | I40: 1004800 | J40: 0 - Nacional | K40: Próprio | L40: 38.97 | M40: L20250102 | N40: II - 85444900 | O40: 7891331542626
...
