Workbook
Name Administrativo_Custo_Fx: '[1]Cockpit Retorno'!$D$41
Name Atendentes_Instr_Campo_QT: '[1]Calc Eng'!$B$53
Name Atendentes_Senior_QT: '[1]Calc Eng'!$B$51
Name Atendentes_Sistema_Processo_QT: '[1]Calc Eng'!$B$52
Name Atendentes_Total: '[1]Calc Eng'!$B$28
Name ATK_INTEG: SUM('[1]Resumo_HIA_HIC_HOC '!$Q$6:$Q$8)
Name ATK_LOG: '[1]Resumo_HIA_HIC_HOC '!$E$13
Name ATK_LOG_INT: '[1]Resumo_HIA_HIC_HOC '!$F$13
Name ATK_LOG_MOB: '[1]Resumo_HIA_HIC_HOC '!$G$13
Name ATK_MOA: '[1]Resumo_HIA_HIC_HOC '!$E$6
Name ATK_MOA_INT: '[1]Resumo_HIA_HIC_HOC '!$F$6
Name ATK_MOA_MOB: '[1]Resumo_HIA_HIC_HOC '!$G$6
Name ATK_MOB: '[1]Resumo_HIA_HIC_HOC '!$L$12
Name ATK_MOD: '[1]Resumo_HIA_HIC_HOC '!$E$8
Name ATK_MOD_INT: '[1]Resumo_HIA_HIC_HOC '!$F$8
Name ATK_MOD_MOB: '[1]Resumo_HIA_HIC_HOC '!$G$8
Name ATK_MOI: '[1]Resumo_HIA_HIC_HOC '!$E$7
Name ATK_MOI_INT: '[1]Resumo_HIA_HIC_HOC '!$F$7
Name ATK_MOI_MOB: '[1]Resumo_HIA_HIC_HOC '!$G$7
Name ATK_periculosidade: '[1]Resumo_HIA_HIC_HOC '!$E$10
Name ATK_Serviços: '[1]Cockpit Retorno'!$L$2
Name ATK_SSMA: '[1]Resumo_HIA_HIC_HOC '!$L$11
Name ATK_Turnover: '[1]Resumo_HIA_HIC_HOC '!$E$9
Name Base_REAJUSTE_MOD_E_MOI: '[1]Custo MO Impostos Obras'!$F$6
Name BDI: [1]BDI!$G$24
Name C_ADM_Geral: 0.1
Name Capital_Giro_ATM: '[1]Cockpit Retorno'!$C$42
Name Capital_Giro_Passivo_BNC_Passivo_Tributario_Tarifas_Advogados: '[1]Cockpit Retorno'!$AFR$174
Name Capital_Giro_Passivo_Custo_Fx: '[1]Cockpit Retorno'!$D$42
Name Casa_Total_Ocupantes: [1]TESTE_LOG_OBRA!$J$38
Name Cesta_Básica_Total: '[1]Resumo_HIA_HIC_HOC '!$G$23
Name Cofins__ATK: [1]Impostos_Taxas_ICMs!$I$31
Name Cofins__Sistema: [1]Impostos_Taxas_ICMs!$H$31
Name COFINS_lOG_MOB: [1]Impostos_Taxas_ICMs!$K$25
Name COFINS_M_S: [1]Impostos_Taxas_ICMs!$H$6
Name Comercial_Custo_Fx: '[1]Cockpit Retorno'!$AFB$174
Name Conteiner_Aluguel_Mes: '[1]Calc Eng'!$B$44
Name Contratação_LOG_Integração_Cliente: [1]HIC_Histograma_Integra_Cliente!$I$51
Name Contratação_Total__Logística: [1]HIA_Histograma_Integração_ATM!$J$51
Name CSLL: [1]Impostos_Taxas_ICMs!$H$28
Name Custo_Comercial__Plus: '[1]Cockpit Retorno'!$C$38
Name Custo_comercial_1: '[1]Cockpit Retorno'!$C$37
Name Custo_Contingência: '[1]Cockpit Retorno'!$C$45
Name Custo_Financeiro_Exclusivo_do_Contrato: '[1]Cockpit Retorno'!$C$43
Name Custo_fixo___Administrativo__Cartões__Carros__Manutenção__Custo_Consumo_interno__SSMA_interno__Alugueis__Luz__Água__Internet_Telefone__Material_escritório__Aquisições_Extra_OS__Totvs__Softwares: '[1]Cockpit Retorno'!$AFK$174
Name Custo_fixo_Adminstrativo: '[1]Cockpit Retorno'!$C$41
Name Custo_Impostos_Credito__Débito: '[1]Cockpit Retorno'!$K$32
Name Custo_Total: '[1]Cockpit Retorno'!$C$47
Name Custos_Viagens__Feiras__Marketing__Filiais: '[1]Cockpit Retorno'!$AFB$171
Name Debito_Impostos: '[1]Cockpit Retorno'!$K$32
Name Diária_Casa_Custo_Atendente: '[1]Calc Eng'!$B$3
Name Diária_Casa_Geral: '[1]Calc Eng'!$B$4
Name Diária_Completa_Sem_Transporte: '[1]Calc Eng'!$B$42
Name Diárias_Hotel_Avulsas_Custo: '[1]Calc Eng'!$B$5
Name Diárias_Hotel_Negociada_Custo: '[1]Calc Eng'!$B$6
Name Dias_Campo: '[1]Calc Eng'!$B$33
Name Dificuldade_Projeto: '[1]Calc Eng'!$K$68
Name Distância_Base_PLANTA: '[1]Calc Eng'!$B$38
Name Distância_STZ_BASE: '[1]Calc Eng'!$B$37
Name Dolar_Referencia: '[1]Cockpit Retorno'!$C$48

Sheet Mestre
D1: eparação Valores
H38: Real
H39: CFTV | U39: =Mestre!AG1312 -> 0
H40: INST
H41: LOG COM
H42: LOG MON
H43: LOG INT
H44: MI
H45: MI - Abraçadeiras
H46: MI - Aço
H47: MI - Aterramento e SPDA | K47: Retorno | L47: ATK | N47: Pis Cofins
H48: MI - Cabos | J48: 48 | K48: CFTV | L48: ATM | M48: 1 | N48: 1 | Z48: 1 ED 1 SD | AA48: 0 | AC48: ⁰C | AE48: Analisadores | AF48: 2 Fios | AI48: 0.15 | AJ48: 0.05 | AK48: 0
H49: MI - Conduletes | J49: 49 | K49: INST | L49: TERCEIROS | M49: 2 | N49: 1 | Z49: 2 ED 1 SD | AA49: 4 | AC49: % | AE49: Analisadores CO2 O2 | AF49: 4 fios | AI49: 0.03 | AJ49: 0.07 | AK49: 0.01
H50: MI - Diversos | J50: 50 | K50: LOG | L50: CLIENTE | M50: 3 | N50: 1 | Z50: ASi | AA50: 8 | AC50: brix | AE50: Bornes geral | AF50: Wireless | AI50: 0.05 | AJ50: 0.12 | AK50: 0.02
H51: MI - Eletrodutos | J51: 51 | K51: LOG_M | M51: 4 | N51: 1 | Z51: CN | AA51: 12 | AC51: g | AE51: Botoeiras | AF51: 3 fios | AI51: 0.1 | AJ51: 0.18 | AK51: 0.03
H52: MI - Iluminação | J52: 52 | K52: MI | M52: 5 | N52: 1 | Z52: DN | AA52: 16 | AC52: Kg | AE52: Chave Nível | AF52: NA | AI52: 0.2 | AJ52: 0.088 | AK52: 0.04
H53: MI - Incêndio | J53: 53 | K53: MOA | M53: 6 | N53: 1 | Z53: DP | AA53: 20 | AC53: kgf/cm² | AE53: Condutivimetro | AI53: 0 | AJ53: 0 | AK53: 0.05
H54: MI - Kanaflex | J54: 54 | K54: MOB | M54: 7 | N54: 1 | Z54: EA | AA54: 24 | AC54: l/h | AE54: Coriolise | AI54: 0.0075 | AK54: 0.06
H55: MI - Leitos | J55: 55 | K55: MOC | M55: 8 | N55: 1 | Z55: ED | AA55: 32 | AC55: m³ | AE55: Diferencial | AK55: 0.07
H56: MI - Manifold | J56: 56 | K56: MOE | M56: 9 | N56: 1 | Z56: IF | AA56: 36 | AC56: m³/h | AE56: Disjuntores Miscelâneas | AK56: 0.08
H57: MI - Manômetros | J57: 57 | K57: MOI | M57: 10 | N57: 1 | Z57: IT | AA57: 40 | AC57: mca | AE57: DT Densidade | AK57: 0.09
H58: MI - Parafusos | J58: 58 | K58: MOD | M58: 11 | N58: 1 | Z58: NA | AA58: 46 | AC58: mm | AE58: Fluxostato | AK58: 0.1
H59: MI - Potes | J59: 59 | K59: MOV | M59: 12 | N59: 1 | Z59: PA | AA59: 50 | AC59: mmH2O | AE59: Fontes | AK59: 0.11
H60: MI - Sealtube | J60: 60 | K60: PLC_DCS | M60: 13 | N60: 1 | Z60: SA | AA60: 62 | AC60: pH | AE60: Magnético | AK60: 0.12
H61: MI - Steck | J61: 61 | K61: PNL | M61: 14 | N61: 1 | Z61: SD | AA61: 14 | AC61: t | AE61: Manométrico | AK61: 0.13
H62: MI - Termômetros | J62: 62 | K62: PROD | M62: 15 | N62: 1 | Z62: 2 ED 2 SD | AC62: t/h | AE62: Manômetros | AK62: 0.14
H63: MI - Ar Comprimido | J63: 63 | K63: PROD REDE | M63: 16 | N63: 1 | Z63: 3 ED 2 SD | AC63: m | AE63: Nível Flangeado | AK63: 0.15
H64: MI - Tubbing | J64: 64 | K64: PROD TI | M64: 17 | N64: 1 | Z64: 1 ED 2 SD | AC64: g/cm³ | AE64: pH TRM | AK64: 0.16
H65: MOA | J65: 65 | K65: SERV | M65: 18 | N65: 1 | Z65: 2 ED 1 SD 1 EA 1 SA | AC65: mmHg | AE65: Pressostados | AK65: 0.17 | AU65: Nacional
H66: MOB | J66: 66 | K66: SOFT | M66: 19 | N66: 1 | AC66: G | AE66: Radar | AK66: 0.18 | AU66: Imp. Diretamente
H67: MOC | J67: 67 | K67: SSMA | M67: 20 | N67: 1 | AC67: mmca | AE67: Reles | AK67: 0.19 | AU67: Imp. Terceiros
H68: MOE | J68: 68 | K68: TRS | M68: 21 | N68: 1 | AC68: inH2O | AE68: Sensor Capacitivo | AK68: 0.2 | AU68: Fab. Própria
H69: MOI | J69: 69 | K69: MOT | AC69: mg/l | AE69: Sensor Indutivo | AK69: 0.21
H70: MOD | J70: 70 | K70: TXATM | AC70: uS | AE70: Sensores | AK70: 0.22
H71: MOV | K71: xxxx | AC71: NA | AE71: Solenóides | AK71: 0.23
H72: PLC | AC72: bar | AE72: Temperatura | AK72: 0.25
H73: PNL | AE73: Termo elemento | AK73: 0.27
H74: PROD | N74: CFTV | O74: Mercadorias | AE74: Termômetros | AK74: 0.29
H75: PROD REDE | N75: INST | O75: Mercadorias | AE75: Ultrassom | AK75: 0.31
H76: PROD TI | N76: LOG | O76: Despesas | AE76: Válvulas Controle | AK76: 0.33
...
